<?xml version="1.0"?>
<robot name="summit_xl" xmlns:xacro="http://wiki.ros.org/xacro"> 

  
  <xacro:include filename="$(find summit_xl_description)/urdf/bases/summit_xl_base.gazebo.xacro" />

  <xacro:macro name="summit_x_base" params="prefix publish_bf hq">

	  <!-- Robot mechanical and motor parameters -->
	  <xacro:property name="PI" value="3.1415926535897931"/>
	  <xacro:property name="wheel_width" value="0.175" />

	  <!-- BASE FOOTPRINT -->
	  <xacro:if value="${publish_bf}">
		<link name="${prefix}base_footprint">
		  <visual>
			  <origin xyz="0 0 0" rpy="0 0 0" />
			  <geometry>
				 <box size="0.001 0.001 0.001" />
			  </geometry>
		  </visual>
		</link>

		<joint name="${prefix}base_footprint_joint" type="fixed">
		  <origin xyz="0 0 ${wheel_radius}" rpy="0 0 0" /> <!-- ${wheel_radius} property must be defined inside wheel description -->
		  <parent link="${prefix}base_footprint"/>
		  <child link="${prefix}base_link" />
		</joint>    
	  </xacro:if>

	  <!-- BASE_LINK -->
	  <link name="${prefix}base_link">
		<inertial>
		  <mass value="25.0" />
		  <origin xyz="0 0 0" />
		  <inertia  ixx="1.391" ixy="0.004"  ixz="0.0"  iyy="6.853"  iyz="0.0"  izz="6.125" />
		</inertial>
		<visual>
		   <origin xyz="0 0 0" rpy="0 0 0" />
		   <xacro:if value="${hq}">
		   <geometry>
			 <mesh filename="package://summit_xl_description/meshes/bases/x/summit_x_chassis_down.dae"/>
		   </geometry>
		   </xacro:if>
		   <xacro:unless value="${hq}">
		   <geometry>
			 <mesh filename="package://summit_xl_description/meshes/bases/x/summit_x_chassis_down.stl"/>
		   </geometry>
		   </xacro:unless>
		   <material name="darkgrey">
			 <color rgba="0.1 0.1 0.1 1"/>
		   </material>
		</visual>  
		<collision>
		   <origin xyz="0 0 0" rpy="0 0 0 " />
		   <geometry>
			 <mesh filename="package://summit_xl_description/meshes/bases/x/summit_x_chassis_down.dae"/>
		   </geometry>
		</collision>     
	  </link>
	  
	  <link name="${prefix}upper_base_link">
		<inertial>
			<mass value="1.0" /> <!-- 20.0 -->
			<origin xyz="0 0 0" />
			<inertia  ixx="0.2185" ixy="0.0"  ixz="-0.001"  iyy="0.33677"  iyz="0.0"  izz="0.20511" />
		</inertial>
		<visual>
			<origin xyz="0 0 0" rpy="0 0 0" />
			<geometry>
				<mesh filename="package://summit_xl_description/meshes/bases/x/summit_x_chassis_up.stl"/>
			</geometry>
			<material name="summit_x_rover_color">
				<color rgba="0.1 0.1 0.1 1"/>
			</material>
		</visual>
		<collision>
			<origin xyz="0 0 0" rpy="0 0 0 " />
			<geometry>
				<mesh filename="package://summit_xl_description/meshes/bases/x/summit_x_chassis_up.stl"/>
			</geometry>
		</collision>     
	</link>

	<joint name="${prefix}upper_base_joint" type="prismatic">
		<parent link="${prefix}base_link"/>
		<child link="${prefix}upper_base_link"/>
		<limit effort="100000.0" velocity="1000.0" lower="0.0" upper="0.5"/> <!-- lower="0.1" upper="0.5" -->
		<origin rpy="0 0 0" xyz="0.261 0 -0.038"/>
		<axis xyz="0 0 1"/>
	</joint>
	
	<!-- auxiliar joint that pushes the 'X' -->
	<link name="${prefix}aux_upper_base_link">   
	</link>
	<joint name="${prefix}aux_upper_base_joint" type="prismatic">
		<parent link="${prefix}base_link"/>
		<child link="${prefix}aux_upper_base_link"/>
		<limit effort="100000.0" velocity="1000.0" lower="0.0" upper="0.5"/> <!-- lower="0.1" upper="0.5" -->
		<origin rpy="0 ${PI/2} 0" xyz="-0.261 -0.15 0.0"/>
		<axis xyz="0 0 1"/>
	</joint>

	<transmission name="${prefix}upper_base_joint_trans">
		<type>transmission_interface/SimpleTransmission</type>
		<joint name="${prefix}upper_base_joint">
		  <hardwareInterface>EffortJointInterface</hardwareInterface>
		</joint>
		<actuator name="${prefix}upper_base_motor">
		  <mechanicalReduction>1</mechanicalReduction>
		 </actuator>
	</transmission>
	<transmission name="${prefix}aux_upper_base_joint_trans">
		<type>transmission_interface/SimpleTransmission</type>
		<joint name="${prefix}aux_upper_base_joint">
		  <hardwareInterface>EffortJointInterface</hardwareInterface>
		</joint>
		<actuator name="${prefix}aux_upper_base_motor">
		  <mechanicalReduction>1</mechanicalReduction>
		 </actuator>
	</transmission>

  </xacro:macro>
</robot>

