<?xml version="1.0"?>
<robot name="sensor_axis_m5013" xmlns:xacro="http://ros.org/wiki/xacro">
	
  <xacro:property name="ptz_joint_effort_limit" value="100.0" /> 
  <xacro:property name="ptz_joint_velocity_limit" value="100.0"/>  
  <xacro:property name="ptz_joint_friction" value="0.1" />
  <xacro:property name="ptz_joint_damping" value="0.1" />
  <xacro:property name="ptz_mechanical_reduction" value="1.0" />	
		
		
  <xacro:macro name="sensor_axis_m5013" params="name parent *origin">
    
 	  <joint name="${name}_joint" type="fixed">
	      <axis xyz="0 1 0" />
<!--
	      <origin xyz="0.180 0.0 0.270"/>
-->
		  <insert_block name="origin"/>
	      <parent link="${parent}"/>
	      <child link="${name}_link"/>
	  </joint>
    
    <link name="${name}_link">
      <inertial>
				<origin xyz="0 0 0" rpy="0 0 0"/>
        <mass value="0.1" />
        <origin xyz="0 0 0" rpy="0 0 0" />
        <inertia ixx="0.1" ixy="0" ixz="0" iyy="0.1" iyz="0" izz="0.1" />
      </inertial>
      <visual>
	      <origin xyz="0 0 0" rpy="0 0 0"/> <!-- to center the axis model -->
	      <material name="axis_color">
           <color rgba="0.1 0.1 0.1 1"/>
        </material>
	      <geometry>
			 <mesh filename= "package://summit_xl_description/meshes/sensors/axis_m5013.dae" scale="1.0 1.0 1.0"/>
	      </geometry>
        
	    </visual>
	    <collision>
	      <origin xyz="0.03 0.0 -0.3" rpy="0 0 0"/>
	      <geometry>
	        <mesh filename= "package://summit_xl_description/meshes/sensors/axis_m5013.stl" scale="1.0 1.0 1.0"/>
	      </geometry>
	    </collision>
    </link>
	  
  
	  <joint name="joint_${name}_pan" type="continuous">
	     <axis xyz="0 0 1" />
	     <origin xyz="0.0 0.0 0.1"/>
	     <parent link="${name}_link"/>
	     <child link="${name}_pan_link"/>
	     <limit effort="${ptz_joint_effort_limit}" velocity="${ptz_joint_velocity_limit}" lower="-3.1416" upper="3.1416"/>
	     <joint_properties damping="${ptz_joint_damping}" friction="{ptz_joint_friction}"/>
	  </joint>  
	  
	  <link name="${name}_pan_link">
	     <inertial>
	       <mass value="0.1" />
	       <origin xyz="0 0 0" rpy="0 0 0" />
	       <inertia ixx="0.1" ixy="0" ixz="0" iyy="0.1" iyz="0" izz="0.1" />
	    </inertial>
	  </link>
	  
	  <transmission name="${name}_pan_trans">
		 <type>transmission_interface/SimpleTransmission</type>
	     <joint name="joint_${name}_pan" />
	     <actuator name="pan_motor">
			   <hardwareInterface>EffortJointInterface</hardwareInterface>
	       <mechanicalReduction>${ptz_mechanical_reduction}</mechanicalReduction>
	     </actuator>
	  </transmission>
	
	
	  <joint name="joint_${name}_tilt" type="continuous">
	     <axis xyz="0 1 0" />
	     <origin xyz="0.0 0.0 0.0"/>
	     <parent link="${name}_pan_link"/>
	     <child link="${name}_tilt_link"/>
	     <limit effort="${ptz_joint_effort_limit}" velocity="${ptz_joint_velocity_limit}" lower="-1.5708" upper="1.5708"/>
	     <joint_properties damping="${ptz_joint_damping}" friction="{ptz_joint_friction}"/>
	  </joint>
	  
	  <link name="${name}_tilt_link">
	     <inertial>
	       <mass value="0.1" />
	       <origin xyz="0 0 0" rpy="0 0 0" />
	       <inertia ixx="0.1" ixy="0" ixz="0" iyy="0.1" iyz="0" izz="0.1" />
	    </inertial>
	  </link>
	  
	  <transmission name="${name}_tilt_trans">
		 <type>transmission_interface/SimpleTransmission</type>
	     <joint name="joint_${name}_tilt" />
	     <actuator name="tilt_motor">
				 <hardwareInterface>EffortJointInterface</hardwareInterface>
				 <mechanicalReduction>${ptz_mechanical_reduction}</mechanicalReduction>
	     </actuator>
	  </transmission>
	
	  <gazebo reference="${name}_link">
      <material>Gazebo/FlatBlack</material>
    </gazebo>

		<!-- Axis sensor for simulation -->
		<sensor_axis_m5013_gazebo/>
		
  </xacro:macro>
  
    
    
    
  <xacro:macro name="sensor_axis_m5013_gazebo">
		
    <gazebo reference="${name}_tilt_link">
	    <sensor type="camera" name="camera1">
	      <update_rate>30.0</update_rate>
	      <camera name="head">
	        <horizontal_fov>1.3962634</horizontal_fov>
	        <image>
	          <width>800</width>
	          <height>800</height>
	          <format>R8G8B8</format>
	        </image>
	        <clip>
	          <near>0.03</near>
	          <far>300</far>
	        </clip>
	        <noise>
	          <type>gaussian</type>
	          <mean>0.0</mean>
	          <stddev>0.007</stddev>
	        </noise>
	      </camera>
	      <plugin name="camera_controller" filename="libgazebo_ros_camera.so">
	        <alwaysOn>true</alwaysOn>
	        <updateRate>0.0</updateRate>
	        <cameraName>${name}</cameraName>
	        <imageTopicName>image_raw</imageTopicName>
	        <cameraInfoTopicName>camera_info</cameraInfoTopicName>
	        <frameName>${name}_tilt_link</frameName>
	        <hackBaseline>0.07</hackBaseline>
	        <distortionK1>0.0</distortionK1>
	        <distortionK2>0.0</distortionK2>
	        <distortionK3>0.0</distortionK3>
	        <distortionT1>0.0</distortionT1>
	        <distortionT2>0.0</distortionT2>
	      </plugin>
	    </sensor>
	  </gazebo>
	  

	  
  </xacro:macro>
  
</robot>
