<?xml version="1.0"?>
<robot name="summit_xl" xmlns:xacro="http://www.ros.org/wiki/xacro"> 

  <!-- BASE FOOTPRINT -->

  <!-- base_footprint is a fictitious link(frame) that is on the ground right below base_link origin,
             navigation stack depends on this frame -->
  <link name="base_footprint">
      <inertial>
          <mass value="0.0001" />
          <origin xyz="0 0 0" />
      <inertia ixx="0.0001" ixy="0.0" ixz="0.0"
                         iyy="0.0001" iyz="0.0" 
                         izz="0.0001" />
      </inertial>

      <visual>
          <origin xyz="0 0 0" rpy="0 0 0" />
          <geometry>
             <box size="0.001 0.001 0.001" />
          </geometry>
      </visual>

      <collision>
          <origin xyz="0 0 0.0" rpy="0 0 0" />
          <geometry>
            <box size="0.001 0.001 0.001" />
         </geometry>
     </collision>
  </link>

  <gazebo reference="base_footprint">
    <material>Gazebo/Green</material>
    <gravity>true</gravity>
  </gazebo>

  <joint name="base_footprint_joint" type="fixed">
     <!--NB: While you would think this would make it go up, it is oddly reversed.
      This moves the joint to 0,0,0 where we want it for rviz, etc. -->
     <!-- origin xyz="0 0 0.130" rpy="0 0 0" / -->
     <origin xyz="0 0 0.050" rpy="0 0 0" />
     <parent link="base_footprint"/>
     <child link="base_link" />
  </joint>


  <!-- BASE_LINK (RED) -->

  <link name="base_link">
    <inertial>
      <mass value="25.0" />
      <origin xyz="0 0 0" />
      <inertia  ixx="1.391" ixy="0.004"  ixz="0.0"  iyy="6.853"  iyz="0.0"  izz="6.125" />
    </inertial>
    <visual>
       <origin xyz="0 0 0" rpy="0 0 0" />
       <geometry>
	 <mesh filename="package://summit_xl_description/meshes/summit_xl_chassis_cam2.mesh"/>
       </geometry>
    </visual>
    <collision>
       <origin xyz="0 0 0.06" rpy="0 0 0 " />
       <geometry>
         <mesh filename="package://summit_xl_description/meshes/summit_xl_chassis_cam2.mesh"/>
	 <box size = "0.750 0.4 0.3"/>
       </geometry>
    </collision>     
  </link>
  <gazebo reference="base_link">
    <material>Gazebo/Red</material>
    <gravity>true</gravity>
  </gazebo>


  <!-- BACK LEFT WHEEL (GREY) -->
  <link name="back_left_wheel">
    <inertial>
      <mass value="1.250" />
      <origin xyz="0 0 0" /> 
      <inertia  ixx="0.0109375" ixy="0.0"  ixz="0.0"  iyy="0.021125"  iyz="0.0"  izz="0.0109375" />
      <!--inertia ixx="1.0" ixy="0.0" ixz="0.0" iyy="1.0" iyz="0.0" izz="1.0"/-->
      <!--inertia  ixx="0.00584" ixy="0.0"  ixz="0.0"  iyy="0.00584"  iyz="0.0"  izz="0.01072"/-->
    </inertial>
    <visual>
       <origin xyz="0 0 0" rpy="0 0 0" /> 
       <geometry>
	 <mesh filename="package://summit_xl_description/meshes/summit_xl_wheel.mesh" scale="1.0 1.0 1.0"/>
       </geometry>
	<material name="grey">
		<color rgba="0.5 0.5 0.5 1"/>
      	</material>
    </visual>
    <collision>
       <origin xyz="0 0 0" rpy="0 0 0" />
       <geometry>
	 <mesh filename="package://summit_xl_description/meshes/summit_xl_wheel.mesh" scale="1.0 1.0 1.0"/>
       </geometry>
    </collision>
  </link>
  <gazebo reference="back_left_wheel">
    <mu1 value="50.0"/> <!-- 2.0 -->
    <mu2 value="0.5"/> <!-- 0.5 -->
    <fdir1 value="1 0 0"/>
    <material>Gazebo/Grey</material>
    <gravity>true</gravity>
  </gazebo>

  <joint name="joint_back_left_wheel" type="continuous">
    <parent link="base_link"/>
    <child link="back_left_wheel"/>
    <origin xyz="-0.223 0.154 0" rpy="0 0 0" /> 
    <axis xyz="0 1 0" rpy="0 0 0" />
    <limit effort="100" velocity="100"/>
    <joint_properties damping="0.0" friction="0.0"/>
  </joint>

  <transmission name="joint_blw_trans" type="pr2_mechanism_model/SimpleTransmission">
     <actuator name="joint_blw_motor" />
     <joint name="joint_back_left_wheel" />
     <mechanicalReduction>1</mechanicalReduction>
     <motorTorqueConstant>1</motorTorqueConstant>
  </transmission>


  <!-- BACK RIGHT WHEEL (GREY) -->
  <link name="back_right_wheel">
    <inertial>
      <mass value="1.250" />
      <origin xyz="0 0 0" />
      <inertia  ixx="0.0109375" ixy="0.0"  ixz="0.0"  iyy="0.021125"  iyz="0.0"  izz="0.0109375" />
    </inertial>
    <visual>
       <origin xyz="0 0 0" rpy="0 0 0" /> 
       <geometry>
	 <mesh filename="package://summit_xl_description/meshes/summit_xl_wheel.mesh" scale="1.0 1.0 1.0"/>
       </geometry>
	<material name="grey">
		<color rgba="0.5 0.5 0.5 1"/>
      	</material>
    </visual>
    <collision>
       <origin xyz="0 0 0" rpy="0 0 0" /> 
       <geometry>
         <!--mesh filename=" ... wheel.dae "/-->
	 <mesh filename="package://summit_xl_description/meshes/summit_xl_wheel.mesh" scale="1.0 1.0 1.0"/>
       </geometry>
    </collision>
  </link>
  <gazebo reference="back_right_wheel">
    <mu1 value="50.0"/> <!-- 2.0 -->
    <mu2 value="0.5"/> <!-- 0.5 -->
    <fdir1 value="1 0 0"/>
    <material>Gazebo/Grey</material>
    <gravity>true</gravity>
  </gazebo>

  <joint name="joint_back_right_wheel" type="continuous">
    <parent link="base_link"/>
    <child link="back_right_wheel"/>
    <origin xyz="-0.223 -0.154 0" rpy="0 0 3.1416" />
    <axis xyz="0 1 0" />
    <limit effort="100" velocity="100"/>
    <joint_properties damping="0.0" friction="0.0"/>
  </joint>

  <transmission name="joint_brw_trans" type="pr2_mechanism_model/SimpleTransmission">
     <actuator name="joint_brw_motor" />
     <joint name="joint_back_right_wheel" />
     <mechanicalReduction>1</mechanicalReduction>
     <motorTorqueConstant>1</motorTorqueConstant>
  </transmission>


  <!-- FRONT LEFT WHEEL (GREY) -->
  <link name="front_left_wheel">
    <inertial>
      <mass value="1.250" />
      <origin xyz="0 0 0" />
      <inertia  ixx="0.0109375" ixy="0.0"  ixz="0.0"  iyy="0.021125"  iyz="0.0"  izz="0.0109375" />
    </inertial>
    <visual>
       <origin xyz="0 0 0" rpy="0 0 0" /> 
       <geometry>
	 <mesh filename="package://summit_xl_description/meshes/summit_xl_wheel.mesh" scale="1.0 1.0 1.0"/>
       </geometry>
	<material name="grey">
		<color rgba="0.5 0.5 0.5 1"/>
      	</material>
    </visual>
    <collision>
       <origin xyz="0 0 0" rpy="0 0 0" /> 
       <geometry>
	 <mesh filename="package://summit_xl_description/meshes/summit_xl_wheel.mesh" scale="1.0 1.0 1.0"/>
       </geometry>
    </collision>
  </link>
  <gazebo reference="front_left_wheel">
    <mu1 value="50.0"/> <!-- 2.0 -->
    <mu2 value="0.5"/> <!-- 0.5 -->
    <fdir1 value="1 0 0"/>
    <material>Gazebo/Grey</material>
    <gravity>true</gravity>
  </gazebo>

  <joint name="joint_front_left_wheel" type="continuous">
    <parent link="base_link"/>
    <child link="front_left_wheel"/>
    <origin xyz="0.223 0.154 0" rpy="0 0 0" />
    <axis xyz="0 1 0" />
    <limit effort="100" velocity="100"/>
    <joint_properties damping="0.0" friction="0.0"/>
  </joint>

  <transmission name="joint_flw_trans" type="pr2_mechanism_model/SimpleTransmission">
     <actuator name="joint_flw_motor" />
     <joint name="joint_front_left_wheel" />
     <mechanicalReduction>1</mechanicalReduction>
     <motorTorqueConstant>1</motorTorqueConstant>
  </transmission>


  <!-- FRONT RIGHT WHEEL (GREY) -->
  <link name="front_right_wheel">
    <inertial>
      <mass value="1.250" />
      <origin xyz="0 0 0" />
      <inertia  ixx="0.0109375" ixy="0.0"  ixz="0.0"  iyy="0.021125"  iyz="0.0"  izz="0.0109375" />
    </inertial>
    <visual>
       <origin xyz="0 0 0" rpy="0 0 0" /> 
       <geometry>
	 <mesh filename="package://summit_xl_description/meshes/summit_xl_wheel.mesh" scale="1.0 1.0 1.0"/>
       </geometry>
	<material name="grey">
		<color rgba="0.5 0.5 0.5 1"/>
      	</material>
    </visual>
    <collision>
       <origin xyz="0 0 0" rpy="0 0 0" /> 
       <geometry>
	 <mesh filename="package://summit_xl_description/meshes/summit_xl_wheel.mesh" scale="1.0 1.0 1.0"/>
       </geometry>
    </collision>
  </link>
  <gazebo reference="front_right_wheel">
    <mu1 value="50.0"/> <!-- 2.0 -->
    <mu2 value="0.5"/> <!-- 0.5 -->
    <fdir1 value="1 0 0"/>
    <material>Gazebo/Grey</material>
    <gravity>true</gravity>
  </gazebo>

  <joint name="joint_front_right_wheel" type="continuous">
    <parent link="base_link"/>
    <child link="front_right_wheel"/>
    <origin xyz="0.223 -0.154 0" rpy="0 0 3.1416" />
    <axis xyz="0 1 0" />
    <limit effort="100" velocity="100"/>
    <joint_properties damping="0.0" friction="0.0"/>
  </joint>

  <transmission name="joint_frw_trans" type="pr2_mechanism_model/SimpleTransmission">
     <actuator name="joint_frw_motor" />
     <joint name="joint_front_right_wheel" />
     <mechanicalReduction>1</mechanicalReduction>
     <motorTorqueConstant>1</motorTorqueConstant>
  </transmission>


  <!-- HOKUYO SENSOR -->

  <joint name="hokuyo_laser_joint" type="fixed">
     <axis xyz="0 1 0" />
     <origin xyz="0.29 0 0.1"/>
     <parent link="base_link"/>
     <child link="hokuyo_laser_link"/>
  </joint>
  <link name="hokuyo_laser_link" type="laser">
     <inertial>
       <mass value="0.001" />
       <origin xyz="0 0 0" rpy="0 0 0" />
       <inertia ixx="0.0001" ixy="0" ixz="0" iyy="0.000001" iyz="0" izz="0.0001" />
    </inertial>
  </link>

  <!-- This adds a visual box to allow us to see the Hokuyo in rviz/gazebo -->
  <joint name="hokuyo_laser_box_joint" type="fixed">
    <origin xyz="0 0 0" rpy="0 0 0" />
    <parent link="hokuyo_laser_link" />
    <child link="hokuyo_laser_box_link"/>
  </joint>
  <link name="hokuyo_laser_box_link">
    <inertial>
      <mass value="0.01" />
      <origin xyz="0 0 0" />
      <inertia ixx="0.001"  ixy="0.0"  ixz="0.0"
               iyy="0.001"  iyz="0.0"
               izz="0.001" />
    </inertial>
    <visual>
      <origin xyz="0 0 0" rpy="0 0 0"/>
      <geometry>
        <!--box size="0.05 0.05 0.1" /-->
	<mesh filename= "package://pr2_description/meshes/tilting_laser_v0/hok_tilt.stl" scale="0.5 0.5 0.5"/>
      </geometry>
    </visual>
    <collision>
      <origin xyz="0 0 0" rpy="0 0 0"/>
      <geometry>
        <box size="0.05 0.05 0.1" />
      </geometry>
    </collision>
  </link>

  <gazebo reference="hokuyo_laser_box_link">
    <material>Gazebo/Grey</material>
    <gravity>true</gravity>
  </gazebo>

  <!-- IMU SENSOR -->

  <joint name="imu_joint" type="fixed">
      <axis xyz="1 0 0"/> <!-- 0 1 0 -->
      <origin xyz="0 0 0.2825"/>
      <parent link="base_link"/>
      <child link="imu_link"/>
  </joint>


  <link name="imu_link">
      <inertial>
        <mass value="0.001"/>
        <origin rpy="0 0 0" xyz="0 0 0"/>
        <inertia ixx="0.0001" ixy="0" ixz="0" iyy="0.000001" iyz="0" izz="0.0001"/>
      </inertial>
      <visual>
        <origin rpy="0 0 0" xyz="0 0 0"/>
        <geometry>
          <box size="0.001 0.001 0.001"/>
        </geometry>
      </visual>
      <collision>
        <origin rpy="0 0 0" xyz="0 0 0"/>
        <geometry>
          <box size=".001 .001 .001"/>
        </geometry>
      </collision>
  </link>

  <!-- Gazebo controllers -->
  <gazebo>
     <controller:gazebo_ros_time name="gazebo_ros_time" plugin="libgazebo_ros_time.so">
       <alwaysOn>true</alwaysOn>
       <updateRate>1000.0</updateRate>
       <interface:audio name="dummy_gazebo_ros_time_iface_should_not_be_here"/>
     </controller:gazebo_ros_time>

      <!-- PR2_ACTARRAY -->
     <controller:gazebo_ros_controller_manager name="gazebo_ros_controller_manager" plugin="libgazebo_ros_controller_manager.so">
       <alwaysOn>true</alwaysOn>
       <updateRate>1000.0</updateRate>
       <interface:audio name="gazebo_ros_controller_manager_dummy_iface" />
     </controller:gazebo_ros_controller_manager>
  </gazebo>

  <!-- Other controllers (HOKUYO SENSOR) -->

  <gazebo reference = "hokuyo_laser_link">
    <sensor:ray name="hokuyo_laser">
       <rayCount>640</rayCount>
       <rangeCount>640</rangeCount>
       <laserCount>1</laserCount>

       <origin>0.0 0.0 0.0</origin>
       <displayRays>fan</displayRays>

       <minAngle>-120.0</minAngle>
       <maxAngle>120.0</maxAngle>
     
       <minRange>0.05</minRange>
       <maxRange>4.0</maxRange>
       <resRange>0.001</resRange>
       <updateRate>10.0</updateRate>
       <controller:gazebo_ros_laser name="gazebo_ros_hokuyo_laser_controller" plugin="libgazebo_ros_laser.so">
         <gaussianNoise>0.005</gaussianNoise>
         <alwaysOn>true</alwaysOn>
         <updateRate>10.0</updateRate>
         <topicName>hokuyo_laser_topic</topicName>
         <frameName>hokuyo_laser_link</frameName>
         <interface:laser name="gazebo_ros_hokuyo_laser_iface" />
       </controller:gazebo_ros_laser>
    </sensor:ray>
   </gazebo>

   <!-- Other controllers (IMU SENSOR) -->

  <!--gazebo reference = "imu_link">
      <material>Gazebo/Green</material>
      <gravity>true</gravity>
      <controller:gazebo_ros_imu name="imu_controller" plugin="libgazebo_ros_imu.so">
         <alwaysOn>true</alwaysOn>
         <updateRate>50.0</updateRate>
         <bodyName>imu_link</bodyName>
         <topicName>imu_data</topicName>
         <xyzOffsets>0 0 0</xyzOffsets--> <!-- option to initialize odometry for fake localization-->
         <!--rpyOffsets>0 0 0</rpyOffsets>
	 <gaussianNoise>0.01</gaussianNoise>
	 <frameName>map</frameName>
         <interface:position name="imu_base_position"/--> <!--imu_position_iface-->
      <!--/controller:gazebo_ros_imu>
  </gazebo-->

  <gazebo>
    <controller:gazebo_ros_imu name="imu_controller" plugin="libgazebo_ros_imu.so">
      <alwaysOn>true</alwaysOn>
      <updateRate>50.0</updateRate> <!-- 100 -->
      <bodyName>imu_link</bodyName>
      <topicName>imu_data</topicName>
      <gaussianNoise>2.89e-08</gaussianNoise>
      <xyzOffsets>0 0 0</xyzOffsets>
      <rpyOffsets>0 0 0</rpyOffsets>
      <interface:position name="imu_position"/>
    </controller:gazebo_ros_imu>
  </gazebo>

</robot>

