<?xml version="1.0"?>
<robot name="summit_xl" xmlns:xacro="http://www.ros.org/wiki/xacro"> 

  <!-- Import all Gazebo-customization elements, including Gazebo colors -->
  <xacro:include filename="$(find summit_xl_description)/urdf/summit_xl_hq.gazebo" />


  <!-- Robot mechanical and motor parameters -->
  <xacro:property name="PI" value="3.1415926535897931"/>
  <xacro:property name="wheel_offset_x" value="0.223" />    <!-- x,y,z in base_footprint CS -->
  <xacro:property name="wheel_offset_y" value="0.154" /> 
  <xacro:property name="wheel_offset_z" value="0.0" /> 
  <xacro:property name="wheel_joint_damping" value="0.0" />
  <xacro:property name="wheel_joint_friction" value="0.0" />
  <xacro:property name="wheel_joint_effort_limit" value="100.0" />
  <xacro:property name="wheel_joint_velocity_limit" value="100.0" />
  <xacro:property name="wheel_mechanical_reduction" value="1.0" />

  <xacro:property name="ptz_joint_effort_limit" value="100.0" /> 
  <xacro:property name="ptz_joint_velocity_limit" value="100.0"/>  
  <xacro:property name="ptz_joint_friction" value="0.1" />
  <xacro:property name="ptz_joint_damping" value="0.1" />
  <xacro:property name="ptz_mechanical_reduction" value="1.0" />

  
  <!-- Used for fixing robot to Gazebo 'base_link' -->
  <!-- link name="world"/>
  <joint name="fwf" type="planar">
    <parent link="world"/>
    <child link="base_footprint"/>
  </joint -->

  <!-- BASE FOOTPRINT -->
  <!-- base_footprint is a fictitious link(frame) that is on the ground right below base_link origin,
             navigation stack depends on this frame -->
  <link name="base_footprint">
      <visual>
          <origin xyz="0 0 0" rpy="0 0 0" />
          <geometry>
             <box size="0.001 0.001 0.001" />
          </geometry>
      </visual>

      <collision>
          <origin xyz="0 0 0" rpy="0 0 0" />
          <geometry>
            <box size="0.001 0.001 0.001" />
         </geometry>
     </collision>
  </link>

  <joint name="base_footprint_joint" type="fixed">
     <!-- NB While you would think this would make it go up, it is oddly reversed.
      This moves the joint to 0,0,0 where we want it for rviz, etc. -->
     <origin xyz="0 0 0.110" rpy="0 0 0" />
     <parent link="base_footprint"/>
     <child link="base_link" />
  </joint>


  <!-- BASE_LINK (RED) -->
  <link name="base_link">
    <inertial>
      <mass value="25.0" />
      <origin xyz="0 0 0" />
      <inertia  ixx="1.391" ixy="0.004"  ixz="0.0"  iyy="6.853"  iyz="0.0"  izz="6.125" />
    </inertial>
    <visual>
       <origin xyz="0 0 0" rpy="0 0 0" />
       <geometry>
	 <mesh filename="package://summit_xl_description/meshes/high_quality/summit_xl_chassis.dae"/>
	   </geometry>
    </visual>
    <collision>
       <origin xyz="0 0 0" rpy="0 0 0 " />
       <geometry>
         <mesh filename="package://summit_xl_description/meshes/high_quality/summit_xl_chassis.dae"/>
	     <!-- box size = "0.750 0.4 0.3"/ -->
       </geometry>
    </collision>     
  </link>

  <!-- BACK LEFT WHEEL (GREY) -->
  <link name="back_left_wheel">
    <inertial>
      <mass value="1.250" />
      <origin xyz="0 0 0"/> 
      <inertia  ixx="0.0109375" ixy="0.0"  ixz="0.0"  iyy="0.021125"  iyz="0.0"  izz="0.0109375" />
    </inertial>
    <visual>
		<origin xyz="0 0 0" rpy="0 0 3.1416" /> 
       <!--origin xyz="0 0.075 0" rpy="0 1.57075 1.57075"/--> 
       <geometry>
	   <mesh filename="package://summit_xl_description/meshes/high_quality/summit_xl_wheel_left.dae" scale="1.0 1.0 1.0"/>
		 <!--cylinder radius="0.125" length="0.15"/-->
       </geometry>
	<material name="grey">
	   <color rgba="0.5 0.5 0.5 1"/>
       </material>
    </visual>
    <collision>
       <geometry>
	    <mesh filename="package://summit_xl_description/meshes/summit_xl_wheel.dae" scale="1.0 1.0 1.0"/>
       </geometry>
    </collision>
  </link>

  <joint name="joint_back_left_wheel" type="continuous">
    <parent link="base_link"/>
    <child link="back_left_wheel"/>
    <origin xyz="-${wheel_offset_x} ${wheel_offset_y} 0" rpy="0 0 0" /> 
    <axis xyz="0 1 0" rpy="0 0 0" />
    <limit effort="${wheel_joint_effort_limit}" velocity="${wheel_joint_velocity_limit}"/>
    <joint_properties damping="${wheel_joint_damping}" friction="{wheel_joint_friction}"/>
  </joint>

  <transmission name="joint_blw_trans">
	 <type>transmission_interface/SimpleTransmission</type>
     <joint name="joint_back_left_wheel" />
     <actuator name="joint_blw_motor">
	    <hardwareInterface>EffortJointInterface</hardwareInterface>
		<!-- hardwareInterface>VelocityJointInterface</hardwareInterface -->
        <mechanicalReduction>${wheel_mechanical_reduction}</mechanicalReduction>
     	<!-- motorTorqueConstant>1</motorTorqueConstant -->
     </actuator>
  </transmission>

  <!-- BACK RIGHT WHEEL (GREY) -->
  <link name="back_right_wheel">
    <inertial>
      <mass value="1.250" />
      <origin xyz="0 0 0" />
      <inertia  ixx="0.0109375" ixy="0.0"  ixz="0.0"  iyy="0.021125"  iyz="0.0"  izz="0.0109375" />
    </inertial>
    <visual>
       <origin xyz="0 0 0" rpy="0 0 3.1416" /> 
       <!--origin xyz="0 0.075 0" rpy="0 1.57075 1.57075"/--> 
       <geometry>
	   <mesh filename="package://summit_xl_description/meshes/high_quality/summit_xl_wheel_right.dae" scale="1.0 1.0 1.0"/>
	   <!--cylinder radius="0.125" length="0.15"/-->
       </geometry>
	   <material name="grey">
	    <color rgba="0.5 0.5 0.5 1"/>
       </material>
    </visual>
    <collision>
       <geometry>
	    <mesh filename="package://summit_xl_description/meshes/summit_xl_wheel.dae" scale="1.0 1.0 1.0"/>
       </geometry>
    </collision>
  </link>

  <joint name="joint_back_right_wheel" type="continuous">
    <parent link="base_link"/>
    <child link="back_right_wheel"/>
    <origin xyz="-${wheel_offset_x} -${wheel_offset_y} 0" rpy="0 0 3.1416" /> 
    <axis xyz="0 1 0" rpy="0 0 3.1416" />
    <limit effort="${wheel_joint_effort_limit}" velocity="${wheel_joint_velocity_limit}"/>
    <joint_properties damping="${wheel_joint_damping}" friction="{wheel_joint_friction}"/>
  </joint>

  <transmission name="joint_brw_trans">
    <type>transmission_interface/SimpleTransmission</type>
    <joint name="joint_back_right_wheel" />
    <actuator name="joint_brw_motor">
	   <hardwareInterface>EffortJointInterface</hardwareInterface>
       <!-- hardwareInterface>VelocityJointInterface</hardwareInterface -->
       <mechanicalReduction>${wheel_mechanical_reduction}</mechanicalReduction>
	   <!-- motorTorqueConstant>1</motorTorqueConstant -->
    </actuator>
  </transmission>


  <!-- FRONT LEFT WHEEL (GREY) -->
  <link name="front_left_wheel">
    <inertial>
      <mass value="1.250" />
      <origin xyz="0 0 0" />
      <inertia  ixx="0.0109375" ixy="0.0"  ixz="0.0"  iyy="0.021125"  iyz="0.0"  izz="0.0109375" />
    </inertial>
    <visual>
      <origin xyz="0 0 0" rpy="0 0 3.1416" />
      <!--origin xyz="0 0.075 0" rpy="0 1.57075 1.57075"/-->  
      <geometry>
	  <mesh filename="package://summit_xl_description/meshes/high_quality/summit_xl_wheel_left.dae" scale="1.0 1.0 1.0"/>
	  <!--cylinder radius="0.125" length="0.15"/-->
      </geometry>
	  <material name="grey">
	    <color rgba="0.5 0.5 0.5 1"/>
      </material>
    </visual>
    <collision>
       <geometry>
	    <mesh filename="package://summit_xl_description/meshes/summit_xl_wheel.dae" scale="1.0 1.0 1.0"/>
       </geometry>
    </collision>
  </link>

  <joint name="joint_front_left_wheel" type="continuous">
    <parent link="base_link"/>
    <child link="front_left_wheel"/>
    <origin xyz="${wheel_offset_x} ${wheel_offset_y} 0" rpy="0 0 0" /> 
    <axis xyz="0 1 0" rpy="0 0 0" />
    <limit effort="${wheel_joint_effort_limit}" velocity="${wheel_joint_velocity_limit}"/>
    <joint_properties damping="${wheel_joint_damping}" friction="{wheel_joint_friction}"/>
  </joint>

  <transmission name="joint_flw_trans">
	 <type>transmission_interface/SimpleTransmission</type>
     <joint name="joint_front_left_wheel" />
     <actuator name="joint_flw_motor">
	   <hardwareInterface>EffortJointInterface</hardwareInterface>
       <!-- hardwareInterface>VelocityJointInterface</hardwareInterface -->
       <mechanicalReduction>${wheel_mechanical_reduction}</mechanicalReduction>
       <!-- motorTorqueConstant>1</motorTorqueConstant -->
     </actuator>     
  </transmission>

  <!-- FRONT RIGHT WHEEL (GREY) -->
  <link name="front_right_wheel">
    <inertial>
      <mass value="1.250" />
      <origin xyz="0 0 0" />
      <inertia  ixx="0.0109375" ixy="0.0"  ixz="0.0"  iyy="0.021125"  iyz="0.0"  izz="0.0109375" />
    </inertial>
    <visual>
       <origin xyz="0 0 0" rpy="0 0 3.1416" /> 
       <!--origin xyz="0 0.075 0" rpy="0 1.57075 1.57075"/--> 
       <geometry>
	   <mesh filename="package://summit_xl_description/meshes/high_quality/summit_xl_wheel_right.dae" scale="1.0 1.0 1.0"/>
       <!--cylinder radius="0.125" length="0.15"/-->
       </geometry>
	   <material name="grey">
		<color rgba="0.5 0.5 0.5 1"/>
       </material>
    </visual>
    <collision>
       <geometry>
	    <mesh filename="package://summit_xl_description/meshes/summit_xl_wheel.dae" scale="1.0 1.0 1.0"/>
       </geometry>
    </collision>
  </link>

  <joint name="joint_front_right_wheel" type="continuous">
    <parent link="base_link"/>
    <child link="front_right_wheel"/>
    <origin xyz="${wheel_offset_x} -${wheel_offset_y} 0" rpy="0 0 3.1416" /> 
    <axis xyz="0 1 0" rpy="0 0 3.1416" />
    <limit effort="${wheel_joint_effort_limit}" velocity="${wheel_joint_velocity_limit}"/>
    <joint_properties damping="${wheel_joint_damping}" friction="{wheel_joint_friction}"/>
  </joint>
  
  <transmission name="joint_frw_trans">
	 <type>transmission_interface/SimpleTransmission</type>
     <joint name="joint_front_right_wheel" />
     <actuator name="joint_frw_motor">
	   <hardwareInterface>EffortJointInterface</hardwareInterface>
	   <!-- hardwareInterface>VelocityJointInterface</hardwareInterface -->    
       <mechanicalReduction>${wheel_mechanical_reduction}</mechanicalReduction>
       <!-- motorTorqueConstant>1</motorTorqueConstant -->
     </actuator>
     <!-- motorTorqueConstant>1</motorTorqueConstant -->
  </transmission>

  <!-- HOKUYO SENSOR -->
  <joint name="hokuyo_laser_joint" type="fixed">
     <axis xyz="0 1 0" />
     <!-- FRONT MOUNT --> 
     <!-- origin xyz="0.29 0 0.1"/ -->
     <!-- FRONT AXIS TOP MOUNT -->
     <!-- origin xyz="0.0 0.0 0.325"/ -->
     <!-- TOP AXIS FRONT MOUNT (WHEN USING ALSO FOTONIC) -->
     <!-- origin xyz="0.120 0.0 0.260"/ -->
     <origin rpy="0 0 0" xyz="0.120 0.0 0.320"/>
     <parent link="base_link"/>
     <child link="hokuyo_laser_link"/>
  </joint>

  <!-- Hokuyo Laser -->
  <link name="hokuyo_laser_link">
    <collision>
      <origin xyz="0 0 -0.06" rpy="0 0 0"/>
      <geometry>
	<box size="0.1 0.1 0.1"/>
      </geometry>
    </collision>

    <visual>
      <origin xyz="0 0 -0.06" rpy="0 0 0"/>
      <geometry>
        <mesh filename="package://summit_xl_description/meshes/hokuyo-utm30-lx-hq.dae"/>
        <!--mesh filename="package://summit_xl_description/meshes/hokuyo-utm30-lx.dae"/-->
      </geometry>
    </visual>

    <inertial>
      <mass value="1e-5" />
      <origin xyz="0 0 0" rpy="0 0 0"/>
      <inertia ixx="1e-6" ixy="0" ixz="0" iyy="1e-6" iyz="0" izz="1e-6" />
    </inertial>
  </link>


  <!-- IMU SENSOR -->
  <joint name="imu_joint" type="fixed">
      <axis xyz="1 0 0"/> <!-- 0 1 0 -->
      <origin xyz="0 0 0.2825"/>
      <parent link="base_link"/>
      <child link="imu_link"/>
  </joint>

  <link name="imu_link">
      <inertial>
        <mass value="0.001"/>
        <origin rpy="0 0 0" xyz="0 0 0"/>
        <inertia ixx="0.0001" ixy="0" ixz="0" iyy="0.000001" iyz="0" izz="0.0001"/>
      </inertial>
      <visual>
        <origin rpy="0 0 0" xyz="0 0 0"/>
        <geometry>
          <box size="0.001 0.001 0.001"/>
        </geometry>
      </visual>
      <collision>
        <origin rpy="0 0 0" xyz="0 0 0"/>
        <geometry>
          <box size=".001 .001 .001"/>
        </geometry>
      </collision>
  </link>




  <!-- AXIS CAMERA VISUAL -->
  <joint name="camera_joint" type="fixed">
     <axis xyz="0 1 0" />
     <origin xyz="0.0 0.0 -0.015"/>      
     <parent link="base_link"/>
     <child link="camera_link"/>
  </joint>
  <link name="camera_link" type="camera">
     <inertial>
       <mass value="0.001" />
       <origin xyz="0 0 0" rpy="0 0 0" />
       <inertia ixx="0.0001" ixy="0" ixz="0" iyy="0.000001" iyz="0" izz="0.0001" />
    </inertial>
    <visual>
      <origin xyz="0 0 0" rpy="0 0 0"/>
      <geometry>
	<mesh filename= "package://summit_xl_description/meshes/xl_fotonic/axis_p5512.dae" scale="1.0 1.0 1.0"/>
      </geometry>
    </visual>
    <collision>
      <origin xyz="0 0 0" rpy="0 0 0"/>
      <geometry>
        <mesh filename= "package://summit_xl_description/meshes/xl_fotonic/axis_p5512.dae" scale="1.0 1.0 1.0"/>
      </geometry>
    </collision>
  </link>

  <!-- AXIS PTZ CAMERA WITH PAN AND TILT -->
  <link name="camera_base_link">
     <inertial>
       <mass value="0.1" />
       <origin xyz="0 0 0" rpy="0 0 0" />
       <inertia ixx="0.1" ixy="0" ixz="0" iyy="0.1" iyz="0" izz="0.1" />
    </inertial>
  </link>
  <joint name="joint_camera" type="fixed">
     <axis xyz="0 1 0" />
     <!--origin xyz="0.180 0.0 0.270"/-->
     <origin xyz="-0.025 0.0 0.440"/>
     <parent link="base_link"/>
     <child link="camera_base_link"/>
  </joint>
  <link name="camera_pan_link">
     <inertial>
       <mass value="0.1" />
       <origin xyz="0 0 0" rpy="0 0 0" />
       <inertia ixx="0.1" ixy="0" ixz="0" iyy="0.1" iyz="0" izz="0.1" />
    </inertial>
  </link>
  <joint name="joint_camera_pan" type="continuous">
     <axis xyz="0 0 1" />
     <origin xyz="0.0 0.0 0.0"/>
     <parent link="camera_base_link"/>
     <child link="camera_pan_link"/>
     <limit effort="${ptz_joint_effort_limit}" velocity="${ptz_joint_velocity_limit}" lower="-3.1416" upper="3.1416"/>
     <joint_properties damping="${ptz_joint_damping}" friction="{ptz_joint_friction}"/>
  </joint>  
  <transmission name="joint_pan_trans">
	 <type>transmission_interface/SimpleTransmission</type>
     <joint name="joint_camera_pan" />
     <actuator name="pan_motor">
	   <hardwareInterface>EffortJointInterface</hardwareInterface>
       <mechanicalReduction>${ptz_mechanical_reduction}</mechanicalReduction>
     </actuator>
  </transmission>

  <link name="camera_tilt_link">
     <inertial>
       <mass value="0.1" />
       <!-- origin xyz="0 0 0" rpy="0 0 0" / -->
       <origin xyz="0 0 0.3" rpy="0 0 0" />
       <inertia ixx="0.1" ixy="0" ixz="0" iyy="0.1" iyz="0" izz="0.1" />
    </inertial>
  </link>
  <joint name="joint_camera_tilt" type="continuous">
     <axis xyz="0 1 0" />
     <origin xyz="0.0 0.0 0.0"/>
     <parent link="camera_pan_link"/>
     <child link="camera_tilt_link"/>
     <limit effort="${ptz_joint_effort_limit}" velocity="${ptz_joint_velocity_limit}" lower="-1.5708" upper="1.5708"/>
     <joint_properties damping="${ptz_joint_damping}" friction="{ptz_joint_friction}"/>
  </joint>
  <transmission name="joint_tilt_trans">
	 <type>transmission_interface/SimpleTransmission</type>
     <joint name="joint_camera_tilt" />
     <actuator name="tilt_motor">
	   <hardwareInterface>EffortJointInterface</hardwareInterface>
       <mechanicalReduction>${ptz_mechanical_reduction}</mechanicalReduction>
     </actuator>
  </transmission>


  <!-- FOTONIC 3D TOF LASER SENSOR -->
  <joint name="fotonic_laser_joint" type="fixed">
     <axis xyz="0 0 1" />
     <!-- origin xyz="0.0 0.0 -0.010"/ -->  <!-- geometric origin of the part -->    
     <origin xyz="0.035 0.0 -0.020"/>
     <parent link="base_link"/>
     <child link="kinect_link"/>
  </joint>

  <link name="kinect_link">
    <inertial>
      <mass value="0.0001" />
      <origin xyz="0 0 0" />
      <inertia ixx="0.0001" ixy="0.0" ixz="0.0"
               iyy="0.0001" iyz="0.0" 
               izz="0.0001" />
    </inertial>
    <visual>
      <origin xyz="0 0 0" rpy="0 0 0"/>
      <geometry>
	<mesh filename= "package://summit_xl_description/meshes/xl_fotonic/fotonic.dae" scale="1.0 1.0 1.0"/>
      </geometry>
    </visual>
    <collision>
      <origin xyz="0 0 0" rpy="0 0 0"/>
      <geometry>
        <mesh filename= "package://summit_xl_description/meshes/xl_fotonic/fotonic.dae" scale="1.0 1.0 1.0"/>
      </geometry>
    </collision>
  </link>

  <joint name="kinect_depth_joint" type="fixed">
    <origin xyz="0.275 0 0.260" rpy="0 0 0" />
    <parent link="kinect_link" />
    <child link="kinect_depth_frame" />
  </joint>

  <link name="kinect_depth_frame">
    <inertial>
      <mass value="0.0001" />
      <origin xyz="0 0 0" />
      <inertia ixx="0.0001" ixy="0.0" ixz="0.0"
               iyy="0.0001" iyz="0.0" 
               izz="0.0001" />
    </inertial>
  </link>

  <joint name="depth_optical_joint" type="fixed">
    <origin xyz="0 0 0" rpy="-1.5708 0 -1.5708" />
    <parent link="kinect_depth_frame" />
    <child link="kinect_depth_optical_frame" />
  </joint>

  <link name="kinect_depth_optical_frame">
    <inertial>
      <mass value="0.0001" />
      <origin xyz="0 0 0" />
      <inertia ixx="0.0001" ixy="0.0" ixz="0.0"
               iyy="0.0001" iyz="0.0" 
               izz="0.0001" />
    </inertial>
  </link>


</robot>

