<?xml version="1.0" ?>
<!-- =================================================================================== -->
<!-- |    This document was autogenerated by xacro from summit_xl_vrep.urdf.xacro      | -->
<!-- |    EDITING THIS FILE BY HAND IS NOT RECOMMENDED                                 | -->
<!-- =================================================================================== -->
<robot name="summit_xl" xmlns:xacro="http://www.ros.org/wiki/xacro">
  <!-- Import all Gazebo-customization elements, including Gazebo colors -->
  <!-- xacro:include filename="$(find summit_xl_description)/urdf/summit_xl_hq.gazebo" / -->
  <!-- Robot mechanical and motor parameters -->
  <!-- x,y,z in base_footprint CS -->
  <!-- BASE_LINK (RED) -->
  <link name="base_link">
    <inertial>
      <mass value="25.0"/>
      <origin xyz="0 0 0"/>
      <inertia ixx="1.391" ixy="0.004" ixz="0.0" iyy="6.853" iyz="0.0" izz="6.125"/>
    </inertial>
    <visual>
      <origin rpy="0 0 0" xyz="0 0 0"/>
      <geometry>
        <mesh filename="package://meshes/hq_suspension/xl_chassis.dae"/>
      </geometry>
    </visual>
    <collision>
      <origin rpy="0 0 0 " xyz="0 0 0"/>
      <geometry>
        <mesh filename="package://meshes/hq_suspension/xl_chassis.dae"/>
      </geometry>
    </collision>
  </link>
  <!-- Robot covers (gray) -->
  <link name="cover_link">
    <inertial>
      <mass value="0.1"/>
      <origin xyz="0 0 0"/>
      <inertia ixx="0.001" ixy="0.0" ixz="0.0" iyy="0.001" iyz="0.0" izz="0.001"/>
    </inertial>
    <visual>
      <origin rpy="0 0 0" xyz="0 0 0"/>
      <geometry>
        <mesh filename="package://meshes/hq_suspension/xl_covers.dae"/>
      </geometry>
    </visual>
    <collision>
      <origin rpy="0 0 0 " xyz="0 0 0"/>
      <geometry>
        <mesh filename="package://meshes/hq_suspension/xl_covers.dae"/>
      </geometry>
    </collision>
  </link>
  <joint name="covers_joint" type="fixed">
    <origin rpy="0 0 0" xyz="0 0 0"/>
    <parent link="base_link"/>
    <child link="cover_link"/>
  </joint>
  <!-- ROBOTNIK LOGOS -->
  <!-- RED -->
  <link name="logo_red">
    <inertial>
      <mass value="1.0"/>
      <origin xyz="0 0 0"/>
      <inertia ixx="0.001" ixy="0.0" ixz="0.0" iyy="0.001" iyz="0.0" izz="0.001"/>
    </inertial>
    <visual>
      <origin rpy="0 0 0" xyz="0 0 0"/>
      <geometry>
        <mesh filename="package://meshes/hq_suspension/xl_logo_red.dae"/>
      </geometry>
    </visual>
    <!-- collision>
       <origin xyz="0 0 0" rpy="0 0 0 " />
       <geometry>
	     <box size = "0.001 0.001 0.001"/>
       </geometry>
    </collision -->
  </link>
  <joint name="logo_red_joint" type="fixed">
    <origin rpy="0 0 0" xyz="0 0 0"/>
    <parent link="base_link"/>
    <child link="logo_red"/>
  </joint>
  <!-- SUSPENSION BAR HOLDER -->
  <link name="bar_holder_left">
    <inertial>
      <mass value="1.0"/>
      <origin xyz="0 0 0"/>
      <inertia ixx="0.001" ixy="0.0" ixz="0.0" iyy="0.001" iyz="0.0" izz="0.001"/>
    </inertial>
    <visual>
      <origin rpy="0 0 0" xyz="0 0 0"/>
      <geometry>
        <mesh filename="package://meshes/hq_suspension/bar_holder.dae"/>
      </geometry>
    </visual>
    <collision>
      <origin rpy="0 0 0 " xyz="0 0 0"/>
      <geometry>
        <mesh filename="package://meshes/hq_suspension/bar_holder.dae"/>
        <!-- box size = "0.750 0.4 0.3"/ -->
      </geometry>
    </collision>
  </link>
  <joint name="bar_holder_left_joint" type="fixed">
    <origin rpy="0 0 0" xyz="0 0.164 0.0"/>
    <parent link="base_link"/>
    <child link="bar_holder_left"/>
  </joint>
  <!-- SUSPENSION BAR HOLDER -->
  <link name="bar_holder_right">
    <inertial>
      <mass value="1.0"/>
      <origin xyz="0 0 0"/>
      <inertia ixx="0.001" ixy="0.0" ixz="0.0" iyy="0.001" iyz="0.0" izz="0.001"/>
    </inertial>
    <visual>
      <origin rpy="0 0 0" xyz="0 0 0"/>
      <geometry>
        <mesh filename="package://meshes/hq_suspension/bar_holder.dae"/>
      </geometry>
    </visual>
    <collision>
      <origin rpy="0 0 0 " xyz="0 0 0"/>
      <geometry>
        <mesh filename="package://meshes/hq_suspension/bar_holder.dae"/>
      </geometry>
    </collision>
  </link>
  <joint name="bar_holder_right_joint" type="fixed">
    <origin rpy="0 0 3.1416" xyz="0 -0.164 0.0"/>
    <parent link="base_link"/>
    <child link="bar_holder_right"/>
  </joint>
  <!-- SUSPENSION BARS -->
  <!-- SUSPENSION BARS -->
  <!-- SUSPENSION BARS -->
  <!-- SUSPENSION BARS -->
  <!-- SUSPENSION BAR BL -->
  <link name="bar_bl">
    <inertial>
      <mass value="1.0"/>
      <origin xyz="0 0 0"/>
      <inertia ixx="0.001" ixy="0.0" ixz="0.0" iyy="0.001" iyz="0.0" izz="0.001"/>
    </inertial>
    <visual>
      <origin rpy="0 0 0" xyz="0 0 0"/>
      <geometry>
        <mesh filename="package://meshes/hq_suspension/suspension_bar2.dae"/>
      </geometry>
    </visual>
    <collision>
      <origin rpy="0 0 0 " xyz="0 0 0"/>
      <geometry>
        <mesh filename="package://meshes/hq_suspension/suspension_bar2.dae"/>
      </geometry>
    </collision>
  </link>
  <joint name="bar_bl_joint" type="continuous">
    <axis xyz="0 0 1"/>
    <!-- origin xyz="-0.078 0.164 -0.048" rpy="0 0 0" / -->
    <!-- origin xyz="-0.078 0.164 -0.048" rpy="-1.5708 -0.174532925 0" / -->
    <origin rpy="1.5708 -0.174532925 0" xyz="-0.078 0.164 -0.048"/>
    <parent link="base_link"/>
    <child link="bar_bl"/>
    <limit effort="100.0" lower="-0.45" upper="-0.25" velocity="100.0"/>
  </joint>
  <!-- SUSPENSION BAR FL -->
  <link name="bar_fl">
    <inertial>
      <mass value="1.0"/>
      <origin xyz="0 0 0"/>
      <inertia ixx="0.001" ixy="0.0" ixz="0.0" iyy="0.001" iyz="0.0" izz="0.001"/>
    </inertial>
    <visual>
      <origin rpy="0 0 0" xyz="0 0 0"/>
      <geometry>
        <mesh filename="package://meshes/hq_suspension/suspension_bar1.dae"/>
      </geometry>
    </visual>
    <collision>
      <origin rpy="0 0 0 " xyz="0 0 0"/>
      <geometry>
        <mesh filename="package://meshes/hq_suspension/suspension_bar1.dae"/>
      </geometry>
    </collision>
  </link>
  <joint name="bar_fl_joint" type="continuous">
    <axis xyz="0 0 1"/>
    <origin rpy="1.5708 -0.174532925 3.1416" xyz="0.078 0.164 -0.048"/>
    <parent link="base_link"/>
    <child link="bar_fl"/>
    <limit effort="100.0" lower="0.25" upper="0.45" velocity="100.0"/>
  </joint>
  <!-- SUSPENSION BAR BR -->
  <link name="bar_br">
    <inertial>
      <mass value="1.0"/>
      <origin xyz="0 0 0"/>
      <inertia ixx="0.001" ixy="0.0" ixz="0.0" iyy="0.001" iyz="0.0" izz="0.001"/>
    </inertial>
    <visual>
      <origin rpy="0 0 0" xyz="0 0 0"/>
      <geometry>
        <mesh filename="package://meshes/hq_suspension/suspension_bar1.dae"/>
      </geometry>
    </visual>
    <collision>
      <origin rpy="0 0 0 " xyz="0 0 0"/>
      <geometry>
        <mesh filename="package://meshes/hq_suspension/suspension_bar1.dae"/>
      </geometry>
    </collision>
  </link>
  <joint name="bar_br_joint" type="continuous">
    <axis xyz="0 0 1"/>
    <origin rpy="1.5708 -0.174532925 0" xyz="-0.078 -0.164 -0.048"/>
    <parent link="base_link"/>
    <child link="bar_br"/>
    <limit effort="100.0" lower="-0.45" upper="-0.25" velocity="100.0"/>
  </joint>
  <!-- SUSPENSION BAR FR -->
  <link name="bar_fr">
    <inertial>
      <mass value="1.0"/>
      <origin xyz="0 0 0"/>
      <inertia ixx="0.001" ixy="0.0" ixz="0.0" iyy="0.001" iyz="0.0" izz="0.001"/>
    </inertial>
    <visual>
      <origin rpy="0 0 0" xyz="0 0 0"/>
      <geometry>
        <mesh filename="package://meshes/hq_suspension/suspension_bar2.dae"/>
      </geometry>
    </visual>
    <collision>
      <origin rpy="0 0 0 " xyz="0 0 0"/>
      <geometry>
        <mesh filename="package://meshes/hq_suspension/suspension_bar2.dae"/>
      </geometry>
    </collision>
  </link>
  <joint name="bar_fr_joint" type="continuous">
    <axis xyz="0 0 1"/>
    <!-- origin xyz="0.078 -0.164 -0.048" rpy="-1.5708 -0.174532925 3.1416" / -->
    <origin rpy="1.5708 -0.174532925 3.1416" xyz="0.078 -0.164 -0.048"/>
    <parent link="base_link"/>
    <child link="bar_fr"/>
    <limit effort="100.0" lower="0.25" upper="0.45" velocity="100.0"/>
  </joint>
  <!-- WHEEL MOTORS -->
  <!-- WHEEL MOTORS -->
  <!-- WHEEL MOTORS -->
  <!-- WHEEL MOTORS -->
  <!-- BACK LEFT WHEEL (GREY) -->
  <link name="back_left_wheel">
    <inertial>
      <mass value="1.250"/>
      <origin xyz="0 0 0"/>
      <inertia ixx="0.0109375" ixy="0.0" ixz="0.0" iyy="0.021125" iyz="0.0" izz="0.0109375"/>
    </inertial>
    <visual>
      <origin rpy="0 0 3.1416" xyz="0 0 0"/>
      <geometry>
        <mesh filename="package://meshes/hq_suspension/wheel/xl_wheel_motor.dae" scale="1.0 1.0 1.0"/>
        <!-- cylinder radius="0.125" length="0.1"/ -->
      </geometry>
      <material name="grey">
        <color rgba="0.5 0.5 0.5 1"/>
      </material>
    </visual>
    <collision>
      <origin rpy="0 0 0" xyz="0 0 0"/>
      <geometry>
        <mesh filename="package://meshes/hq_suspension/wheel/xl_wheel_motor.dae" scale="1.0 1.0 1.0"/>
        <!-- cylinder radius="0.125" length="0.1"/ -->
      </geometry>
    </collision>
  </link>
  <joint name="joint_back_left_wheel" type="continuous">
    <parent link="bar_bl"/>
    <child link="back_left_wheel"/>
    <!-- origin xyz="-${wheel_offset_x} ${wheel_offset_y} 0" rpy="1.5708 0 0" / -->
    <origin rpy="1.5708 3.1416 0" xyz="-0.165 0.0 -0.07"/>
    <axis rpy="0 0 0" xyz="0 1 0"/>
    <limit effort="100.0" velocity="100.0"/>
    <joint_properties damping="0.0" friction="{wheel_joint_friction}"/>
  </joint>
  <transmission name="joint_blw_trans">
    <type>transmission_interface/SimpleTransmission</type>
    <joint name="joint_back_left_wheel"/>
    <actuator name="joint_blw_motor">
      <hardwareInterface>EffortJointInterface</hardwareInterface>
      <!-- hardwareInterface>VelocityJointInterface</hardwareInterface -->
      <mechanicalReduction>1.0</mechanicalReduction>
      <!-- motorTorqueConstant>1</motorTorqueConstant -->
    </actuator>
  </transmission>
  <!-- BACK RIGHT WHEEL (GREY) -->
  <link name="back_right_wheel">
    <inertial>
      <mass value="1.250"/>
      <origin xyz="0 0 0"/>
      <inertia ixx="0.0109375" ixy="0.0" ixz="0.0" iyy="0.021125" iyz="0.0" izz="0.0109375"/>
    </inertial>
    <visual>
      <origin rpy="0 0 3.1416" xyz="0 0 0"/>
      <geometry>
        <mesh filename="package://meshes/hq_suspension/wheel/xl_wheel_motor.dae" scale="1.0 1.0 1.0"/>
      </geometry>
      <material name="grey">
        <color rgba="0.5 0.5 0.5 1"/>
      </material>
    </visual>
    <collision>
      <origin rpy="0 0 0" xyz="0 0 0"/>
      <geometry>
        <mesh filename="package://meshes/hq_suspension/wheel/xl_wheel_motor.dae" scale="1.0 1.0 1.0"/>
      </geometry>
    </collision>
  </link>
  <joint name="joint_back_right_wheel" type="continuous">
    <parent link="bar_br"/>
    <child link="back_right_wheel"/>
    <!-- origin xyz="-${wheel_offset_x} -${wheel_offset_y} 0" rpy="0 0 3.1416" /> 
    <axis xyz="0 1 0" rpy="0 0 3.1416" / -->
    <origin rpy="1.5708 0 1.5708" xyz="-0.165 -0.0 0.07"/>
    <axis rpy="0 0 0" xyz="0 1 0"/>
    <limit effort="100.0" velocity="100.0"/>
    <joint_properties damping="0.0" friction="{wheel_joint_friction}"/>
  </joint>
  <transmission name="joint_brw_trans">
    <type>transmission_interface/SimpleTransmission</type>
    <joint name="joint_back_right_wheel"/>
    <actuator name="joint_brw_motor">
      <hardwareInterface>EffortJointInterface</hardwareInterface>
      <mechanicalReduction>1.0</mechanicalReduction>
    </actuator>
  </transmission>
  <!-- FRONT LEFT WHEEL (GREY) -->
  <link name="front_left_wheel">
    <inertial>
      <mass value="1.250"/>
      <origin xyz="0 0 0"/>
      <inertia ixx="0.0109375" ixy="0.0" ixz="0.0" iyy="0.021125" iyz="0.0" izz="0.0109375"/>
    </inertial>
    <visual>
      <origin rpy="0 0 3.1416" xyz="0 0 0"/>
      <geometry>
        <mesh filename="package://meshes/hq_suspension/wheel/xl_wheel_motor.dae" scale="1.0 1.0 1.0"/>
      </geometry>
      <material name="grey">
        <color rgba="0.5 0.5 0.5 1"/>
      </material>
    </visual>
    <collision>
      <origin rpy="0 0 0" xyz="0 0 0"/>
      <geometry>
        <mesh filename="package://meshes/hq_suspension/wheel/xl_wheel_motor.dae" scale="1.0 1.0 1.0"/>
        <!-- cylinder radius="0.125" length="0.1"/ -->
      </geometry>
    </collision>
  </link>
  <joint name="joint_front_left_wheel" type="continuous">
    <parent link="bar_fl"/>
    <child link="front_left_wheel"/>
    <origin rpy="1.5708 0 0" xyz="-0.165 0.0 0.07"/>
    <axis rpy="0 0 0" xyz="0 1 0"/>
    <limit effort="100.0" velocity="100.0"/>
    <joint_properties damping="0.0" friction="{wheel_joint_friction}"/>
  </joint>
  <transmission name="joint_flw_trans">
    <type>transmission_interface/SimpleTransmission</type>
    <joint name="joint_front_left_wheel"/>
    <actuator name="joint_flw_motor">
      <hardwareInterface>EffortJointInterface</hardwareInterface>
      <mechanicalReduction>1.0</mechanicalReduction>
    </actuator>
  </transmission>
  <!-- FRONT RIGHT WHEEL (GREY) -->
  <link name="front_right_wheel">
    <inertial>
      <mass value="1.250"/>
      <origin xyz="0 0 0"/>
      <inertia ixx="0.0109375" ixy="0.0" ixz="0.0" iyy="0.021125" iyz="0.0" izz="0.0109375"/>
    </inertial>
    <visual>
      <origin rpy="0 0 3.1416" xyz="0 0 0"/>
      <geometry>
        <mesh filename="package://meshes/hq_suspension/wheel/xl_wheel_motor.dae" scale="1.0 1.0 1.0"/>
      </geometry>
      <material name="grey">
        <color rgba="0.5 0.5 0.5 1"/>
      </material>
    </visual>
    <collision>
      <origin rpy="0 0 0" xyz="0 0 0"/>
      <geometry>
        <mesh filename="package://meshes/hq_suspension/wheel/xl_wheel_motor.dae" scale="1.0 1.0 1.0"/>
      </geometry>
    </collision>
  </link>
  <joint name="joint_front_right_wheel" type="continuous">
    <parent link="bar_fr"/>
    <child link="front_right_wheel"/>
    <origin rpy="1.5708 3.1416 0" xyz="-0.165 -0.0 -0.07"/>
    <axis rpy="0 0 0" xyz="0 1 0"/>
    <limit effort="100.0" velocity="100.0"/>
    <joint_properties damping="0.0" friction="{wheel_joint_friction}"/>
  </joint>
  <transmission name="joint_frw_trans">
    <type>transmission_interface/SimpleTransmission</type>
    <joint name="joint_front_right_wheel"/>
    <actuator name="joint_frw_motor">
      <hardwareInterface>EffortJointInterface</hardwareInterface>
      <mechanicalReduction>1.0</mechanicalReduction>
    </actuator>
  </transmission>
  <!-- WHEEL TYRES -->
  <!-- WHEEL TYRES -->
  <!-- WHEEL TYRES -->
  <!-- WHEEL TYRES -->
  <!-- BACK LEFT TYRE (BLACK) -->
  <link name="back_left_tyre">
    <inertial>
      <mass value="1.250"/>
      <origin xyz="0 0 0"/>
      <inertia ixx="0.0109375" ixy="0.0" ixz="0.0" iyy="0.021125" iyz="0.0" izz="0.0109375"/>
    </inertial>
    <visual>
      <origin rpy="0 0 3.1416" xyz="0 0 0"/>
      <geometry>
        <mesh filename="package://meshes/hq_suspension/wheel/xl_wheel_tyre.dae" scale="1.0 1.0 1.0"/>
      </geometry>
      <material name="grey">
        <color rgba="0.5 0.5 0.5 1"/>
      </material>
    </visual>
    <collision>
      <origin rpy="0 0 0" xyz="0 0 0"/>
      <geometry>
        <mesh filename="package://meshes/hq_suspension/wheel/wheel_simple_thread_2.dae" scale="1.0 1.0 1.0"/>
        <!-- cylinder radius="0.125" length="0.1"/ -->
      </geometry>
    </collision>
  </link>
  <joint name="joint_back_left_tyre" type="fixed">
    <parent link="back_left_wheel"/>
    <child link="back_left_tyre"/>
    <origin rpy="0 0 3.1416" xyz="0 0 0"/>
  </joint>
  <!-- BACK RIGHT TYRE (BLACK) -->
  <link name="back_right_tyre">
    <inertial>
      <mass value="1.250"/>
      <origin xyz="0 0 0"/>
      <inertia ixx="0.0109375" ixy="0.0" ixz="0.0" iyy="0.021125" iyz="0.0" izz="0.0109375"/>
    </inertial>
    <visual>
      <origin rpy="0 0 3.1416" xyz="0 0 0"/>
      <geometry>
        <mesh filename="package://meshes/hq_suspension/wheel/xl_wheel_tyre.dae" scale="1.0 1.0 1.0"/>
      </geometry>
      <material name="grey">
        <color rgba="0.5 0.5 0.5 1"/>
      </material>
    </visual>
    <collision>
      <origin rpy="0 0 0" xyz="0 0 0"/>
      <geometry>
        <mesh filename="package://meshes/hq_suspension/wheel/wheel_simple_thread_2.dae" scale="1.0 1.0 1.0"/>
        <!-- cylinder radius="0.125" length="0.1"/ -->
      </geometry>
    </collision>
  </link>
  <joint name="joint_back_right_tyre" type="fixed">
    <parent link="back_right_wheel"/>
    <child link="back_right_tyre"/>
    <origin rpy="0 0 0" xyz="0 0 0"/>
  </joint>
  <!-- FRONT LEFT TYRE (BLACK) -->
  <link name="front_left_tyre">
    <inertial>
      <mass value="1.250"/>
      <origin xyz="0 0 0"/>
      <inertia ixx="0.0109375" ixy="0.0" ixz="0.0" iyy="0.021125" iyz="0.0" izz="0.0109375"/>
    </inertial>
    <visual>
      <origin rpy="0 0 3.1416" xyz="0 0 0"/>
      <geometry>
        <mesh filename="package://meshes/hq_suspension/wheel/xl_wheel_tyre.dae" scale="1.0 1.0 1.0"/>
      </geometry>
      <material name="grey">
        <color rgba="0.5 0.5 0.5 1"/>
      </material>
    </visual>
    <collision>
      <origin rpy="0 0 0" xyz="0 0 0"/>
      <geometry>
        <mesh filename="package://meshes/hq_suspension/wheel/wheel_simple_thread_2.dae" scale="1.0 1.0 1.0"/>
      </geometry>
    </collision>
  </link>
  <joint name="joint_front_left_tyre" type="fixed">
    <parent link="front_left_wheel"/>
    <child link="front_left_tyre"/>
    <origin rpy="0 0 3.1416" xyz="0 0 0"/>
  </joint>
  <!-- FRONT RIGHT TYRE (BLACK) -->
  <link name="front_right_tyre">
    <inertial>
      <mass value="1.250"/>
      <origin xyz="0 0 0"/>
      <inertia ixx="0.0109375" ixy="0.0" ixz="0.0" iyy="0.021125" iyz="0.0" izz="0.0109375"/>
    </inertial>
    <visual>
      <origin rpy="0 0 3.1416" xyz="0 0 0"/>
      <geometry>
        <mesh filename="package://meshes/hq_suspension/wheel/xl_wheel_tyre.dae" scale="1.0 1.0 1.0"/>
      </geometry>
      <material name="grey">
        <color rgba="0.5 0.5 0.5 1"/>
      </material>
    </visual>
    <collision>
      <origin rpy="0 0 0" xyz="0 0 0"/>
      <geometry>
        <mesh filename="package://meshes/hq_suspension/wheel/wheel_simple_thread_2.dae" scale="1.0 1.0 1.0"/>
      </geometry>
    </collision>
  </link>
  <joint name="joint_front_right_tyre" type="fixed">
    <parent link="front_right_wheel"/>
    <child link="front_right_tyre"/>
    <origin rpy="0 0 0" xyz="0 0 0"/>
  </joint>
  <!-- WHEEL HUBCAPS -->
  <!-- WHEEL HUBCAPS -->
  <!-- WHEEL HUBCAPS -->
  <!-- WHEEL HUBCAPS -->
  <!-- BACK LEFT HUBCUP (LIGHT GREY) -->
  <link name="back_left_hubcap">
    <inertial>
      <mass value="1.250"/>
      <origin xyz="0 0 0"/>
      <inertia ixx="0.0109375" ixy="0.0" ixz="0.0" iyy="0.021125" iyz="0.0" izz="0.0109375"/>
    </inertial>
    <visual>
      <origin rpy="0 0 3.1416" xyz="0 0 0"/>
      <geometry>
        <mesh filename="package://meshes/hq_suspension/wheel/xl_wheel_hubcap.dae" scale="1.0 1.0 1.0"/>
      </geometry>
      <material name="grey">
        <color rgba="0.5 0.5 0.5 1"/>
      </material>
    </visual>
  </link>
  <joint name="joint_back_left_hubcap" type="fixed">
    <parent link="back_left_wheel"/>
    <child link="back_left_hubcap"/>
    <origin rpy="0 0 3.1416" xyz="0 0 0"/>
  </joint>
  <!-- BACK RIGHT HUBCUP (LIGHT GREY) -->
  <link name="back_right_hubcap">
    <inertial>
      <mass value="1.250"/>
      <origin xyz="0 0 0"/>
      <inertia ixx="0.0109375" ixy="0.0" ixz="0.0" iyy="0.021125" iyz="0.0" izz="0.0109375"/>
    </inertial>
    <visual>
      <origin rpy="0 0 3.1416" xyz="0 0 0"/>
      <geometry>
        <mesh filename="package://meshes/hq_suspension/wheel/xl_wheel_hubcap.dae" scale="1.0 1.0 1.0"/>
      </geometry>
      <material name="grey">
        <color rgba="0.5 0.5 0.5 1"/>
      </material>
    </visual>
  </link>
  <joint name="joint_back_right_hubcap" type="fixed">
    <parent link="back_right_wheel"/>
    <child link="back_right_hubcap"/>
    <origin rpy="0 0 0" xyz="0 0 0"/>
  </joint>
  <!-- FRONT LEFT HUBCUP (LIGHT GREY) -->
  <link name="front_left_hubcap">
    <inertial>
      <mass value="1.250"/>
      <origin xyz="0 0 0"/>
      <inertia ixx="0.0109375" ixy="0.0" ixz="0.0" iyy="0.021125" iyz="0.0" izz="0.0109375"/>
    </inertial>
    <visual>
      <origin rpy="0 0 3.1416" xyz="0 0 0"/>
      <geometry>
        <mesh filename="package://meshes/hq_suspension/wheel/xl_wheel_hubcap.dae" scale="1.0 1.0 1.0"/>
      </geometry>
      <material name="grey">
        <color rgba="0.5 0.5 0.5 1"/>
      </material>
    </visual>
  </link>
  <joint name="joint_front_left_hubcap" type="fixed">
    <parent link="front_left_wheel"/>
    <child link="front_left_hubcap"/>
    <origin rpy="0 0 3.1416" xyz="0 0 0"/>
  </joint>
  <!-- FRONT RIGHT HUBCUP (LIGHT GREY) -->
  <link name="front_right_hubcap">
    <inertial>
      <mass value="1.250"/>
      <origin xyz="0 0 0"/>
      <inertia ixx="0.0109375" ixy="0.0" ixz="0.0" iyy="0.021125" iyz="0.0" izz="0.0109375"/>
    </inertial>
    <visual>
      <origin rpy="0 0 3.1416" xyz="0 0 0"/>
      <geometry>
        <mesh filename="package://meshes/hq_suspension/wheel/xl_wheel_hubcap.dae" scale="1.0 1.0 1.0"/>
      </geometry>
      <material name="grey">
        <color rgba="0.5 0.5 0.5 1"/>
      </material>
    </visual>
  </link>
  <joint name="joint_front_right_hubcap" type="fixed">
    <parent link="front_right_wheel"/>
    <child link="front_right_hubcap"/>
    <origin rpy="0 0 0" xyz="0 0 0"/>
  </joint>
  <!-- HOKUYO SENSOR -->
  <link name="hokuyo_laser_link">
    <collision>
      <origin rpy="0 0 0" xyz="0 0 0"/>
      <geometry>
        <box size="0.1 0.1 0.1"/>
      </geometry>
    </collision>
    <visual>
      <origin rpy="0 0 0" xyz="0 0 0"/>
      <geometry>
        <mesh filename="package://meshes/hq_suspension/hokuyo-utm30-lx-hq.dae"/>
      </geometry>
    </visual>
    <inertial>
      <mass value="1e-5"/>
      <origin rpy="0 0 0" xyz="0 0 0"/>
      <inertia ixx="1e-6" ixy="0" ixz="0" iyy="1e-6" iyz="0" izz="1e-6"/>
    </inertial>
  </link>
  <joint name="hokuyo_laser_joint" type="fixed">
    <axis xyz="0 1 0"/>
    <origin xyz="0.120 0.0 0.160"/>
    <parent link="base_link"/>
    <child link="hokuyo_laser_link"/>
  </joint>
  <link name="hokuyo_laser_cover_link">
    <collision>
      <origin rpy="0 0 0" xyz="0 0 0"/>
      <geometry>
        <box size="0.1 0.1 0.1"/>
      </geometry>
    </collision>
    <visual>
      <origin rpy="0 0 0" xyz="0 0 0"/>
      <geometry>
        <mesh filename="package://meshes/hq_suspension/hokuyo-utm30-lx-hq_cover.dae"/>
      </geometry>
    </visual>
    <inertial>
      <mass value="1e-5"/>
      <origin rpy="0 0 0" xyz="0 0 0"/>
      <inertia ixx="1e-6" ixy="0" ixz="0" iyy="1e-6" iyz="0" izz="1e-6"/>
    </inertial>
  </link>
  <joint name="hokuyo_laser_cover_joint" type="fixed">
    <axis xyz="0 1 0"/>
    <origin xyz="0.120 0.0 0.160"/>
    <parent link="base_link"/>
    <child link="hokuyo_laser_cover_link"/>
  </joint>
  <!-- AXIS CAMERA VISUAL -->
  <!-- link name="camera_link" type="camera" -->
  <link name="camera_link" type="camera">
    <inertial>
      <mass value="0.001"/>
      <origin rpy="0 0 0" xyz="0 0 0"/>
      <inertia ixx="0.0001" ixy="0" ixz="0" iyy="0.000001" iyz="0" izz="0.0001"/>
    </inertial>
    <visual>
      <origin rpy="0 0 0" xyz="0 0 0"/>
      <geometry>
        <!-- mesh filename= "package://meshes/xl_fotonic/axis_p5512.dae" scale="1.0 1.0 1.0"/ -->
        <mesh filename="package://meshes/hq_suspension/axis_p5512_base.dae" scale="1.0 1.0 1.0"/>
      </geometry>
    </visual>
    <collision>
      <origin rpy="0 0 0" xyz="0 0 0"/>
      <geometry>
        <!-- mesh filename= "package://meshes/xl_fotonic/axis_p5512.dae" scale="1.0 1.0 1.0"/ -->
        <mesh filename="package://meshes/hq_suspension/axis_p5512_base.dae" scale="1.0 1.0 1.0"/>
      </geometry>
    </collision>
  </link>
  <joint name="camera_joint" type="fixed">
    <axis xyz="0 1 0"/>
    <!-- origin xyz="0.0 0.0 -0.015"/ -->
    <origin xyz="0.0 0.0 -0.115"/>
    <parent link="base_link"/>
    <child link="camera_link"/>
  </joint>
  <!-- AXIS CAMERA VISUAL -->
  <link name="camera_link_sphere" type="camera">
    <inertial>
      <mass value="0.001"/>
      <origin rpy="0 0 0" xyz="0 0 0"/>
      <inertia ixx="0.0001" ixy="0" ixz="0" iyy="0.000001" iyz="0" izz="0.0001"/>
    </inertial>
    <visual>
      <origin rpy="0 0 0" xyz="0 0 0"/>
      <geometry>
        <!-- mesh filename= "package://meshes/xl_fotonic/axis_p5512.dae" scale="1.0 1.0 1.0"/ -->
        <mesh filename="package://meshes/hq_suspension/axis_p5512_sphere.dae" scale="1.0 1.0 1.0"/>
      </geometry>
    </visual>
    <collision>
      <origin rpy="0 0 0" xyz="0 0 0"/>
      <geometry>
        <!-- mesh filename= "package://meshes/xl_fotonic/axis_p5512.dae" scale="1.0 1.0 1.0"/ -->
        <mesh filename="package://meshes/hq_suspension/axis_p5512_sphere.dae" scale="1.0 1.0 1.0"/>
      </geometry>
    </collision>
  </link>
  <joint name="camera_joint_sphere" type="fixed">
    <axis xyz="0 1 0"/>
    <origin xyz="0.0 0.0 -0.115"/>
    <parent link="base_link"/>
    <child link="camera_link_sphere"/>
  </joint>
  <!-- FOTONIC 3D TOF LASER SENSOR -->
  <!-- IN SEVERAL PARTS TO ALLOW SHAPE COLOURS -->
  <joint name="fotonic_laser_joint" type="fixed">
    <axis xyz="0 0 1"/>
    <!-- origin xyz="0.035 0.0 -0.120"/ -->
    <origin xyz="0.0 0.0 0.0"/>
    <parent link="base_link"/>
    <child link="kinect_link"/>
  </joint>
  <link name="kinect_link">
    <inertial>
      <mass value="0.0001"/>
      <origin xyz="0 0 0"/>
      <inertia ixx="0.0001" ixy="0.0" ixz="0.0" iyy="0.0001" iyz="0.0" izz="0.0001"/>
    </inertial>
    <visual>
      <origin rpy="0 0 0" xyz="0 0 0"/>
      <geometry>
        <mesh filename="package://meshes/hq_suspension/fotonic_v1/fotonic_1.dae" scale="1.0 1.0 1.0"/>
      </geometry>
    </visual>
  </link>
  <joint name="kinect_depth_joint" type="fixed">
    <origin rpy="0 0 0" xyz="0.275 0 0.160"/>
    <parent link="kinect_link"/>
    <child link="kinect_depth_frame"/>
  </joint>
  <link name="kinect_depth_frame">
    <inertial>
      <mass value="0.0001"/>
      <origin xyz="0 0 0"/>
      <inertia ixx="0.0001" ixy="0.0" ixz="0.0" iyy="0.0001" iyz="0.0" izz="0.0001"/>
    </inertial>
  </link>
  <joint name="depth_optical_joint" type="fixed">
    <origin rpy="-1.5708 0 -1.5708" xyz="0 0 0"/>
    <parent link="kinect_depth_frame"/>
    <child link="kinect_depth_optical_frame"/>
  </joint>
  <link name="kinect_depth_optical_frame">
    <inertial>
      <mass value="0.0001"/>
      <origin xyz="0 0 0"/>
      <inertia ixx="0.0001" ixy="0.0" ixz="0.0" iyy="0.0001" iyz="0.0" izz="0.0001"/>
    </inertial>
  </link>
  <link name="fotonic_2_link">
    <inertial>
      <mass value="0.0001"/>
      <origin xyz="0 0 0"/>
      <inertia ixx="0.0001" ixy="0.0" ixz="0.0" iyy="0.0001" iyz="0.0" izz="0.0001"/>
    </inertial>
    <visual>
      <origin rpy="0 0 0" xyz="0 0 0"/>
      <geometry>
        <mesh filename="package://meshes/hq_suspension/fotonic_v1/fotonic_2.dae" scale="1.0 1.0 1.0"/>
      </geometry>
    </visual>
  </link>
  <joint name="fotonic_2_joint" type="fixed">
    <origin rpy="0 0 0" xyz="0 0 0"/>
    <parent link="kinect_link"/>
    <child link="fotonic_2_link"/>
  </joint>
  <link name="fotonic_3_link">
    <inertial>
      <mass value="0.0001"/>
      <origin xyz="0 0 0"/>
      <inertia ixx="0.0001" ixy="0.0" ixz="0.0" iyy="0.0001" iyz="0.0" izz="0.0001"/>
    </inertial>
    <visual>
      <origin rpy="0 0 0" xyz="0 0 0"/>
      <geometry>
        <mesh filename="package://meshes/hq_suspension/fotonic_v1/fotonic_3.dae" scale="1.0 1.0 1.0"/>
      </geometry>
    </visual>
  </link>
  <joint name="fotonic_3_joint" type="fixed">
    <origin rpy="0 0 0" xyz="0 0 0"/>
    <parent link="kinect_link"/>
    <child link="fotonic_3_link"/>
  </joint>
  <link name="fotonic_4_link">
    <inertial>
      <mass value="0.0001"/>
      <origin xyz="0 0 0"/>
      <inertia ixx="0.0001" ixy="0.0" ixz="0.0" iyy="0.0001" iyz="0.0" izz="0.0001"/>
    </inertial>
    <visual>
      <origin rpy="0 0 0" xyz="0 0 0"/>
      <geometry>
        <mesh filename="package://meshes/hq_suspension/fotonic_v1/fotonic_4.dae" scale="1.0 1.0 1.0"/>
      </geometry>
    </visual>
  </link>
  <joint name="fotonic_4_joint" type="fixed">
    <origin rpy="0 0 0" xyz="0 0 0"/>
    <parent link="kinect_link"/>
    <child link="fotonic_4_link"/>
  </joint>
  <link name="fotonic_5_link">
    <inertial>
      <mass value="0.0001"/>
      <origin xyz="0 0 0"/>
      <inertia ixx="0.0001" ixy="0.0" ixz="0.0" iyy="0.0001" iyz="0.0" izz="0.0001"/>
    </inertial>
    <visual>
      <origin rpy="0 0 0" xyz="0 0 0"/>
      <geometry>
        <mesh filename="package://meshes/hq_suspension/fotonic_v1/fotonic_5.dae" scale="1.0 1.0 1.0"/>
      </geometry>
    </visual>
    <collision>
      <origin rpy="0 0 0" xyz="0 0 0"/>
      <geometry>
        <mesh filename="package://meshes/hq_suspension/fotonic_v1/fotonic_5.dae" scale="1.0 1.0 1.0"/>
      </geometry>
    </collision>
  </link>
  <joint name="fotonic_5_joint" type="fixed">
    <origin rpy="0 0 0" xyz="0 0 0"/>
    <parent link="kinect_link"/>
    <child link="fotonic_5_link"/>
  </joint>
</robot>

