<?xml version="1.0" ?>
<!-- =================================================================================== -->
<!-- |    This document was autogenerated by xacro from x_wam.urdf.xacro               | -->
<!-- |    EDITING THIS FILE BY HAND IS NOT RECOMMENDED                                 | -->
<!-- =================================================================================== -->
<robot name="summit_xl" xmlns:xacro="http://www.ros.org/wiki/xacro">
  <!-- Import all Gazebo-customization elements, including Gazebo colors -->
  <gazebo>
    <plugin filename="libgazebo_ros_control.so" name="ros_control">
      <robotNamespace>/summit_xl</robotNamespace>
      <controlPeriod>0.001</controlPeriod>
      <robotSimType>gazebo_ros_control/DefaultRobotHWSim</robotSimType>
    </plugin>
  </gazebo>
  <gazebo reference="base_footprint">
    <material>Gazebo/Green</material>
  </gazebo>
  <gazebo reference="base_link">
    <material>Gazebo/Red</material>
    <gravity>true</gravity>
  </gazebo>
  <gazebo reference="front_right_steer_link">
    <material>Gazebo/Grey</material>
    <gravity>true</gravity>
  </gazebo>
  <gazebo reference="front_right_wheel">
    <mu1 value="4.0"/>
    <!-- 2.0 100.0 -->
    <mu2 value="1.0"/>
    <!-- 0.5 100.0 -->
    <fdir1 value="1 0 0"/>
    <material>Gazebo/Grey</material>
    <gravity>true</gravity>
  </gazebo>
  <gazebo reference="front_left_steer_link">
    <material>Gazebo/Grey</material>
    <gravity>true</gravity>
  </gazebo>
  <gazebo reference="front_left_wheel">
    <mu1 value="4.0"/>
    <!-- 2.0 -->
    <mu2 value="1.0"/>
    <!-- 0.5 -->
    <fdir1 value="1 0 0"/>
    <material>Gazebo/Grey</material>
    <gravity>true</gravity>
  </gazebo>
  <gazebo reference="back_left_steer_link">
    <material>Gazebo/Grey</material>
    <gravity>true</gravity>
  </gazebo>
  <gazebo reference="back_left_wheel">
    <mu1 value="4.0"/>
    <mu2 value="1.0"/>
    <fdir1 value="1 0 0"/>
    <material>Gazebo/Grey</material>
    <gravity>true</gravity>
  </gazebo>
  <gazebo reference="back_right_steer_link">
    <material>Gazebo/Grey</material>
    <gravity>true</gravity>
  </gazebo>
  <gazebo reference="back_right_wheel">
    <mu1 value="4.0"/>
    <mu2 value="1.0"/>
    <fdir1 value="1 0 0"/>
    <material>Gazebo/Grey</material>
    <gravity>true</gravity>
  </gazebo>
  <gazebo reference="hokuyo_laser_box_link">
    <material>Gazebo/Grey</material>
    <gravity>true</gravity>
  </gazebo>
  <gazebo reference="rover_link">
    <material>Gazebo/Red</material>
    <gravity>true</gravity>
  </gazebo>
  <gazebo reference="camera_link">
    <mu1>0.2</mu1>
    <mu2>0.2</mu2>
    <material>Gazebo/Red</material>
    <sensor name="camera1" type="camera">
      <update_rate>30.0</update_rate>
      <camera name="head">
        <horizontal_fov>1.3962634</horizontal_fov>
        <image>
          <width>800</width>
          <height>800</height>
          <format>R8G8B8</format>
        </image>
        <clip>
          <near>0.02</near>
          <far>300</far>
        </clip>
        <noise>
          <type>gaussian</type>
          <mean>0.0</mean>
          <stddev>0.007</stddev>
        </noise>
      </camera>
      <plugin filename="libgazebo_ros_camera.so" name="camera_controller">
        <alwaysOn>true</alwaysOn>
        <updateRate>0.0</updateRate>
        <cameraName>/summit_xl/camera1</cameraName>
        <imageTopicName>image_raw</imageTopicName>
        <cameraInfoTopicName>camera_info</cameraInfoTopicName>
        <frameName>camera_link</frameName>
        <hackBaseline>0.07</hackBaseline>
        <distortionK1>0.0</distortionK1>
        <distortionK2>0.0</distortionK2>
        <distortionK3>0.0</distortionK3>
        <distortionT1>0.0</distortionT1>
        <distortionT2>0.0</distortionT2>
      </plugin>
    </sensor>
  </gazebo>
  <gazebo reference="hokuyo_laser_link">
    <sensor name="head_hokuyo_sensor" type="ray">
      <pose>0 0 0 0 0 0</pose>
      <visualize>false</visualize>
      <update_rate>30</update_rate>
      <ray>
        <scan>
          <horizontal>
            <samples>720</samples>
            <resolution>1</resolution>
            <min_angle>-1.570796</min_angle>
            <max_angle>1.570796</max_angle>
          </horizontal>
        </scan>
        <range>
          <min>0.10</min>
          <max>30.0</max>
          <resolution>0.01</resolution>
        </range>
        <noise>
          <type>gaussian</type>
          <mean>0.0</mean>
          <stddev>0.01</stddev>
        </noise>
      </ray>
      <plugin filename="libgazebo_ros_laser.so" name="gazebo_ros_head_hokuyo_controller">
        <topicName>/scan</topicName>
        <frameName>hokuyo_laser_link</frameName>
      </plugin>
    </sensor>
  </gazebo>
  <gazebo>
    <plugin filename="libgazebo_ros_imu.so" name="ros_imu">
      <robotNamespace>/summit_xl</robotNamespace>
      <topicName>imu_data</topicName>
      <bodyName>imu_link </bodyName>
      <serviceName>/imu_service</serviceName>
      <gaussianNoise>0.001</gaussianNoise>
    </plugin>
  </gazebo>
  <gazebo reference="wam_link1">
    <material>Gazebo/White</material>
    <!-- selfCollide>true</selfCollide -->
    <gravity>true</gravity>
  </gazebo>
  <gazebo reference="wam_link2">
    <material>Gazebo/Grey</material>
    <!-- selfCollide>true</selfCollide -->
    <gravity>true</gravity>
  </gazebo>
  <gazebo reference="wam_link3">
    <material>Gazebo/Grey</material>
    <!-- selfCollide>true</selfCollide -->
    <gravity>true</gravity>
  </gazebo>
  <gazebo reference="wam_link4">
    <material>Gazebo/Grey</material>
    <!-- selfCollide>true</selfCollide -->
    <gravity>true</gravity>
  </gazebo>
  <gazebo reference="wam_link5">
    <material>Gazebo/Grey</material>
    <!-- selfCollide>true</selfCollide -->
    <gravity>true</gravity>
  </gazebo>
  <gazebo reference="wam_link6">
    <material>Gazebo/Grey</material>
    <!-- selfCollide>true</selfCollide -->
    <gravity>true</gravity>
  </gazebo>
  <gazebo reference="wam_link7">
    <material>Gazebo/Grey</material>
    <!-- selfCollide>true</selfCollide -->
    <gravity>true</gravity>
  </gazebo>
  <!-- Constants for robot dimensions -->
  <!-- xacro:property name="wheel_offset_x" value="0.261" / -->
  <!-- x,y,z in base_footprint CS -->
  <!-- x,y,z in base_footprint CS -->
  <!-- WAM Parameters -->
  <!-- Used for fixing robot to Gazebo 'base_link' -->
  <!-- link name="world"/>

  <joint name="fwf" type="planar">
    <parent link="world"/>
    <child link="base_footprint"/>
  </joint -->
  <!-- BASE FOOTPRINT -->
  <!-- base_footprint is a fictitious link(frame) that is on the ground right below base_link origin,
             navigation stack depends on this frame -->
  <link name="base_footprint">
    <!-- inertial>
          <mass value="0.0001" />
          <origin xyz="0 0 0" />
          <inertia ixx="0.0001" ixy="0.0" ixz="0.0"
                         iyy="0.0001" iyz="0.0" 
                         izz="0.0001" />
      </inertial -->
    <visual>
      <origin rpy="0 0 0" xyz="0 0 0"/>
      <geometry>
        <box size="0.001 0.001 0.001"/>
      </geometry>
    </visual>
    <collision>
      <origin rpy="0 0 0" xyz="0 0 0"/>
      <geometry>
        <box size="0.001 0.001 0.001"/>
      </geometry>
    </collision>
  </link>
  <joint name="base_footprint_joint" type="fixed">
    <!--NB: While you would think this would make it go up, it is oddly reversed.
      This moves the joint to 0,0,0 where we want it for rviz, etc. -->
    <!-- origin xyz="0 0 0.075" rpy="0 0 0" / -->
    <origin rpy="0 0 0" xyz="0 0 0.150"/>
    <parent link="base_footprint"/>
    <child link="base_link"/>
  </joint>
  <!-- BASE_LINK (RED) -->
  <link name="base_link">
    <!-- inertial>
      <mass value="20.0" />
      <origin xyz="0 0 0" />
      <inertia  ixx="0.2185" ixy="0.0"  ixz="-0.001"  iyy="0.33677"  iyz="0.0"  izz="0.20511" />
    </inertial -->
    <inertial>
      <mass value="40.0"/>
      <origin xyz="0 0 0"/>
      <inertia ixx="1.0" ixy="0.0" ixz="0.0" iyy="1.0" iyz="0.0" izz="1.0"/>
    </inertial>
    <visual>
      <origin rpy="0 0 0" xyz="0 0 0"/>
      <geometry>
        <mesh filename="package://summit_xl_description/meshes/x_wam/chassis_xwam_down.dae"/>
      </geometry>
    </visual>
    <collision>
      <origin rpy="0 0 0 " xyz="0 0 0"/>
      <geometry>
        <mesh filename="package://summit_xl_description/meshes/x_wam/chassis_xwam_down.dae"/>
      </geometry>
    </collision>
  </link>
  <!-- **************************** -->
  <!-- WHEEL 1                      -->
  <!-- FRONT RIGHT WHEEL - STEERING -->
  <!-- **************************** -->
  <link name="front_right_steer_link">
    <inertial>
      <mass value="0.1"/>
      <origin xyz="0 0 0"/>
      <inertia ixx="0.01" ixy="0.0" ixz="0.0" iyy="0.01" iyz="0.0" izz="0.01"/>
    </inertial>
    <visual>
      <!-- visual origin is defined w.r.t. link local coordinate system -->
      <origin rpy="0 0 0" xyz="0 0 0"/>
      <geometry>
        <cylinder length="0.025" radius="0.015"/>
      </geometry>
    </visual>
    <collision>
      <origin rpy="0 0 0" xyz="0 0 0"/>
      <geometry>
        <cylinder length="0.025" radius="0.015"/>
      </geometry>
    </collision>
  </link>
  <joint name="joint_front_right_steer" type="continuous">
    <!-- revolute -->
    <parent link="base_link"/>
    <child link="front_right_steer_link"/>
    <origin rpy="0 0 0" xyz="0.285 -0.285 -0.069"/>
    <axis rpy="0 0 0" xyz="0 0 1"/>
    <limit effort="5.0" velocity="5.0"/>
    <!-- lower="-1.570796327" upper="1.570796327"/ -->
    <joint_properties damping="2.0" friction="{steer_joint_friction}"/>
  </joint>
  <transmission name="joint_frw_steer_trans">
    <type>transmission_interface/SimpleTransmission</type>
    <joint name="joint_front_right_steer"/>
    <actuator name="joint_frw_steer_motor">
      <hardwareInterface>EffortJointInterface</hardwareInterface>
      <mechanicalReduction>100.0</mechanicalReduction>
      <motorTorqueConstant>1</motorTorqueConstant>
    </actuator>
  </transmission>
  <!-- **************************** -->
  <!-- WHEEL 1                      -->
  <!-- FRONT RIGHT WHEEL - TRACTION -->
  <!-- **************************** -->
  <link name="front_right_wheel">
    <inertial>
      <mass value="1.250"/>
      <origin xyz="0 0 0"/>
      <inertia ixx="0.0109375" ixy="0.0" ixz="0.0" iyy="0.021125" iyz="0.0" izz="0.0109375"/>
    </inertial>
    <visual>
      <origin rpy="0 0 0" xyz="0 0 0"/>
      <geometry>
        <!-- mesh filename="package://summit_xl_description/meshes/summit_xl_wheel.dae" scale="1.0 1.0 1.0"/ -->
        <sphere radius="0.127"/>
      </geometry>
      <material name="grey">
        <color rgba="0.5 0.5 0.5 1"/>
      </material>
    </visual>
    <collision>
      <origin rpy="0 0 0" xyz="0 0 0"/>
      <geometry>
        <!-- mesh filename="package://summit_xl_description/meshes/summit_xl_wheel.dae" scale="1.0 1.0 1.0"/ -->
        <sphere radius="0.127"/>
      </geometry>
    </collision>
  </link>
  <joint name="joint_front_right_wheel" type="continuous">
    <parent link="front_right_steer_link"/>
    <child link="front_right_wheel"/>
    <origin rpy="0 0 0" xyz="0 0 0"/>
    <axis xyz="0 -1 0"/>
    <limit effort="100.0" velocity="0.1"/>
    <joint_properties damping="1.0" friction="{wheel_joint_friction}"/>
  </joint>
  <transmission name="joint_frw_trans">
    <type>transmission_interface/SimpleTransmission</type>
    <joint name="joint_front_right_wheel"/>
    <actuator name="joint_frw_motor">
      <hardwareInterface>EffortJointInterface</hardwareInterface>
      <mechanicalReduction>15.0</mechanicalReduction>
      <motorTorqueConstant>1</motorTorqueConstant>
    </actuator>
  </transmission>
  <!-- **************************** -->
  <!-- WHEEL 2                      -->
  <!-- FRONT LEFT WHEEL  - STEERING -->
  <!-- **************************** -->
  <link name="front_left_steer_link">
    <inertial>
      <mass value="0.1"/>
      <origin xyz="0 0 0"/>
      <inertia ixx="0.01" ixy="0.0" ixz="0.0" iyy="0.01" iyz="0.0" izz="0.01"/>
    </inertial>
    <visual>
      <!-- visual origin is defined w.r.t. link local coordinate system -->
      <origin rpy="0 0 0" xyz="0 0 0"/>
      <geometry>
        <cylinder length="0.025" radius="0.015"/>
      </geometry>
    </visual>
    <collision>
      <origin rpy="0 0 0" xyz="0 0 0"/>
      <geometry>
        <cylinder length="0.025" radius="0.015"/>
      </geometry>
    </collision>
  </link>
  <joint name="joint_front_left_steer" type="continuous">
    <parent link="base_link"/>
    <child link="front_left_steer_link"/>
    <origin rpy="0 0 0" xyz="0.285 0.285 -0.069"/>
    <axis rpy="0 0 0" xyz="0 0 1"/>
    <limit effort="5.0" velocity="5.0"/>
    <!-- lower="-1.570796327" upper="1.570796327"/ -->
    <joint_properties damping="2.0" friction="{steer_joint_friction}"/>
  </joint>
  <transmission name="joint_flw_steer_trans">
    <type>transmission_interface/SimpleTransmission</type>
    <joint name="joint_front_left_steer"/>
    <actuator name="joint_flw_steer_motor">
      <hardwareInterface>EffortJointInterface</hardwareInterface>
      <mechanicalReduction>100.0</mechanicalReduction>
      <motorTorqueConstant>1</motorTorqueConstant>
    </actuator>
  </transmission>
  <!-- **************************** -->
  <!-- WHEEL 2                      -->
  <!-- FRONT LEFT WHEEL  - TRACTION -->
  <!-- **************************** -->
  <link name="front_left_wheel">
    <inertial>
      <mass value="1.250"/>
      <origin xyz="0 0 0"/>
      <inertia ixx="0.0109375" ixy="0.0" ixz="0.0" iyy="0.021125" iyz="0.0" izz="0.0109375"/>
    </inertial>
    <visual>
      <origin rpy="0 0 0" xyz="0 0 0"/>
      <geometry>
        <!-- mesh filename="package://summit_xl_description/meshes/summit_xl_wheel.dae" scale="1.0 1.0 1.0"/ -->
        <sphere radius="0.127"/>
      </geometry>
      <material name="grey">
        <color rgba="0.5 0.5 0.5 1"/>
      </material>
    </visual>
    <collision>
      <origin rpy="0 0 0" xyz="0 0 0"/>
      <geometry>
        <!-- mesh filename="package://summit_xl_description/meshes/summit_xl_wheel.dae" scale="1.0 1.0 1.0"/ -->
        <sphere radius="0.127"/>
      </geometry>
    </collision>
  </link>
  <joint name="joint_front_left_wheel" type="continuous">
    <parent link="front_left_steer_link"/>
    <child link="front_left_wheel"/>
    <origin rpy="0 0 0" xyz="0 0 0"/>
    <axis rpy="0 0 0" xyz="0 1 0"/>
    <limit effort="100.0" velocity="0.1"/>
    <joint_properties damping="1.0" friction="{wheel_joint_friction}"/>
  </joint>
  <transmission name="joint_flw_trans">
    <type>transmission_interface/SimpleTransmission</type>
    <joint name="joint_front_left_wheel"/>
    <actuator name="joint_flw_motor">
      <hardwareInterface>EffortJointInterface</hardwareInterface>
      <mechanicalReduction>15.0</mechanicalReduction>
      <motorTorqueConstant>1</motorTorqueConstant>
    </actuator>
  </transmission>
  <!-- **************************** -->
  <!-- WHEEL 3                      -->
  <!-- BACK LEFT WHEEL  - STEERING -->
  <!-- **************************** -->
  <link name="back_left_steer_link">
    <inertial>
      <mass value="0.1"/>
      <origin xyz="0 0 0"/>
      <inertia ixx="0.01" ixy="0.0" ixz="0.0" iyy="0.01" iyz="0.0" izz="0.01"/>
    </inertial>
    <visual>
      <!-- visual origin is defined w.r.t. link local coordinate system -->
      <origin rpy="0 0 0" xyz="0 0 0"/>
      <geometry>
        <cylinder length="0.025" radius="0.015"/>
      </geometry>
    </visual>
    <collision>
      <origin rpy="0 0 0" xyz="0 0 0"/>
      <geometry>
        <cylinder length="0.025" radius="0.015"/>
      </geometry>
    </collision>
  </link>
  <joint name="joint_back_left_steer" type="continuous">
    <parent link="base_link"/>
    <child link="back_left_steer_link"/>
    <origin rpy="0 0 0" xyz="-0.285 0.285 -0.069"/>
    <axis rpy="0 0 0" xyz="0 0 1"/>
    <limit effort="5.0" velocity="5.0"/>
    <!-- lower="-1.570796327" upper="1.570796327"/ -->
    <joint_properties damping="2.0" friction="{steer_joint_friction}"/>
  </joint>
  <transmission name="joint_blw_steer_trans">
    <type>transmission_interface/SimpleTransmission</type>
    <joint name="joint_back_left_steer"/>
    <actuator name="joint_blw_steer_motor">
      <hardwareInterface>EffortJointInterface</hardwareInterface>
      <mechanicalReduction>100.0</mechanicalReduction>
      <motorTorqueConstant>1</motorTorqueConstant>
    </actuator>
  </transmission>
  <!-- **************************** -->
  <!-- WHEEL 3                      -->
  <!-- BACK LEFT WHEEL  - TRACTION  -->
  <!-- **************************** -->
  <link name="back_left_wheel">
    <inertial>
      <mass value="1.250"/>
      <origin xyz="0 0 0"/>
      <inertia ixx="0.0109375" ixy="0.0" ixz="0.0" iyy="0.021125" iyz="0.0" izz="0.0109375"/>
    </inertial>
    <visual>
      <origin rpy="0 0 0" xyz="0 0 0"/>
      <geometry>
        <sphere radius="0.127"/>
        <!-- mesh filename="package://summit_xl_description/meshes/summit_xl_wheel.dae" scale="1.0 1.0 1.0"/ -->
      </geometry>
      <material name="grey">
        <color rgba="0.5 0.5 0.5 1"/>
      </material>
    </visual>
    <collision>
      <origin rpy="0 0 0" xyz="0 0 0"/>
      <geometry>
        <sphere radius="0.127"/>
        <!-- mesh filename="package://summit_xl_description/meshes/summit_xl_wheel.dae" scale="1.0 1.0 1.0"/ -->
      </geometry>
    </collision>
  </link>
  <joint name="joint_back_left_wheel" type="continuous">
    <parent link="back_left_steer_link"/>
    <child link="back_left_wheel"/>
    <origin rpy="0 0 0" xyz="0 0 0"/>
    <axis rpy="0 0 0" xyz="0 1 0"/>
    <limit effort="100.0" velocity="0.1"/>
    <joint_properties damping="1.0" friction="{wheel_joint_friction}"/>
  </joint>
  <transmission name="joint_blw_trans">
    <type>transmission_interface/SimpleTransmission</type>
    <joint name="joint_back_left_wheel"/>
    <actuator name="joint_blw_motor">
      <hardwareInterface>EffortJointInterface</hardwareInterface>
      <mechanicalReduction>15.0</mechanicalReduction>
      <motorTorqueConstant>1</motorTorqueConstant>
    </actuator>
  </transmission>
  <!-- **************************** -->
  <!-- WHEEL 4                      -->
  <!-- BACK RIGHT WHEEL  - STEERING -->
  <!-- **************************** -->
  <link name="back_right_steer_link">
    <inertial>
      <mass value="0.1"/>
      <origin xyz="0 0 0"/>
      <inertia ixx="0.01" ixy="0.0" ixz="0.0" iyy="0.01" iyz="0.0" izz="0.01"/>
    </inertial>
    <visual>
      <!-- visual origin is defined w.r.t. link local coordinate system -->
      <origin rpy="0 0 0" xyz="0 0 0"/>
      <geometry>
        <cylinder length="0.025" radius="0.015"/>
      </geometry>
    </visual>
    <collision>
      <origin rpy="0 0 0" xyz="0 0 0"/>
      <geometry>
        <cylinder length="0.025" radius="0.015"/>
      </geometry>
    </collision>
  </link>
  <joint name="joint_back_right_steer" type="continuous">
    <parent link="base_link"/>
    <child link="back_right_steer_link"/>
    <origin rpy="0 0 0" xyz="-0.285 -0.285 -0.069"/>
    <axis rpy="0 0 0" xyz="0 0 1"/>
    <limit effort="5.0" velocity="5.0"/>
    <!-- lower="-1.570796327" upper="1.570796327"/ -->
    <joint_properties damping="2.0" friction="{steer_joint_friction}"/>
  </joint>
  <transmission name="joint_brw_steer_trans">
    <type>transmission_interface/SimpleTransmission</type>
    <joint name="joint_back_right_steer"/>
    <actuator name="joint_brw_steer_motor">
      <hardwareInterface>EffortJointInterface</hardwareInterface>
      <mechanicalReduction>100.0</mechanicalReduction>
      <motorTorqueConstant>1</motorTorqueConstant>
    </actuator>
  </transmission>
  <!-- **************************** -->
  <!-- WHEEL 4                      -->
  <!-- BACK RIGHT WHEEL  - TRACTION -->
  <!-- **************************** -->
  <link name="back_right_wheel">
    <inertial>
      <mass value="1.250"/>
      <origin xyz="0 0 0"/>
      <inertia ixx="0.0109375" ixy="0.0" ixz="0.0" iyy="0.021125" iyz="0.0" izz="0.0109375"/>
    </inertial>
    <visual>
      <origin rpy="0 0 0" xyz="0 0 0"/>
      <geometry>
        <sphere radius="0.127"/>
        <!-- mesh filename="package://summit_xl_description/meshes/summit_xl_wheel.dae" scale="1.0 1.0 1.0"/ -->
      </geometry>
      <material name="grey">
        <color rgba="0.5 0.5 0.5 1"/>
      </material>
    </visual>
    <collision>
      <origin rpy="0 0 0" xyz="0 0 0"/>
      <geometry>
        <sphere radius="0.127"/>
        <!-- mesh filename="package://summit_xl_description/meshes/summit_xl_wheel.dae" scale="1.0 1.0 1.0"/ -->
      </geometry>
    </collision>
  </link>
  <joint name="joint_back_right_wheel" type="continuous">
    <parent link="back_right_steer_link"/>
    <child link="back_right_wheel"/>
    <origin rpy="0 0 0" xyz="0 0 0"/>
    <axis xyz="0 -1 0"/>
    <limit effort="100.0" velocity="0.1"/>
    <joint_properties damping="1.0" friction="{wheel_joint_friction}"/>
  </joint>
  <transmission name="joint_brw_trans">
    <type>transmission_interface/SimpleTransmission</type>
    <joint name="joint_back_right_wheel"/>
    <actuator name="joint_brw_motor">
      <hardwareInterface>EffortJointInterface</hardwareInterface>
      <mechanicalReduction>15.0</mechanicalReduction>
      <motorTorqueConstant>1</motorTorqueConstant>
    </actuator>
  </transmission>
  <!-- IMU SENSOR -->
  <joint name="imu_joint" type="fixed">
    <axis xyz="1 0 0"/>
    <!-- 0 1 0 -->
    <origin xyz="0 0 0.2825"/>
    <parent link="base_link"/>
    <child link="imu_link"/>
  </joint>
  <link name="imu_link">
    <inertial>
      <mass value="0.001"/>
      <origin rpy="0 0 0" xyz="0 0 0"/>
      <inertia ixx="0.0001" ixy="0" ixz="0" iyy="0.000001" iyz="0" izz="0.0001"/>
    </inertial>
    <visual>
      <origin rpy="0 0 0" xyz="0 0 0"/>
      <geometry>
        <box size="0.001 0.001 0.001"/>
      </geometry>
    </visual>
    <collision>
      <origin rpy="0 0 0" xyz="0 0 0"/>
      <geometry>
        <box size=".001 .001 .001"/>
      </geometry>
    </collision>
  </link>
  <!-- ***************************** -->
  <!-- SCISSOR MECHANISM PART 1      -->
  <!-- ***************************** -->
  <!-- link name="scissor_bars1_link">
    <inertial>
      <mass value="6.0" />
      <origin xyz="0 0 0" />
      <inertia  ixx="0.2185" ixy="0.0"  ixz="-0.001"  iyy="0.33677"  iyz="0.0"  izz="0.20511" />
    </inertial>
    <visual>
       <origin xyz="0 0 0" rpy="0 0 0" />
       <geometry>
	   <mesh filename="package://summit_xl_description/meshes/x_wam/scissor_bars_1.dae"/>
       </geometry>
    </visual>
    <collision>
       <origin xyz="0 0 0" rpy="0 0 0 " />
       <geometry>
       <mesh filename="package://summit_xl_description/meshes/x_wam/scissor_bars_1.dae"/>
       </geometry>
    </collision>     
  </link>

  <joint name="scissor_bars1_joint" type="continuous">
    <parent link="base_link"/>
    <child link="scissor_bars1_link"/>
    <origin xyz="0.261 0.0 -0.038" rpy="0.0 -3.1416 0.0" />
    <axis xyz="0 1 0" />
    <limit effort="300" velocity="1"/ -->
  <!-- lower="-3.1416" upper="-2.28"/ -->
  <!-- dynamics damping="1.0" friction="0.1"/>
  </joint -->
  <!-- mimic joint="scissor_prismatic_joint" multiplier="1.72" offset="-3.14" / -->
  <!-- ***************************** -->
  <!-- ROVER PART - UP SCISSOR MECH  -->
  <!-- ***************************** -->
  <link name="rover_link">
    <inertial>
      <mass value="20.0"/>
      <origin xyz="0 0 0"/>
      <inertia ixx="0.2185" ixy="0.0" ixz="-0.001" iyy="0.33677" iyz="0.0" izz="0.20511"/>
    </inertial>
    <visual>
      <origin rpy="0 0 0" xyz="0 0 0"/>
      <geometry>
        <mesh filename="package://summit_xl_description/meshes/x_wam/chassis_xwam_up.dae"/>
      </geometry>
    </visual>
    <collision>
      <origin rpy="0 0 0 " xyz="0 0 0"/>
      <geometry>
        <mesh filename="package://summit_xl_description/meshes/x_wam/chassis_xwam_up.dae"/>
      </geometry>
    </collision>
  </link>
  <joint name="scissor_prismatic_joint" type="prismatic">
    <parent link="base_link"/>
    <child link="rover_link"/>
    <limit effort="1000.0" lower="0.0" upper="0.500" velocity="0.25"/>
    <origin rpy="0 0 0" xyz="0.261 0 -0.038"/>
    <axis xyz="0 0 1"/>
  </joint>
  <transmission name="joint_scissor_trans">
    <type>transmission_interface/SimpleTransmission</type>
    <joint name="scissor_prismatic_joint"/>
    <actuator name="scissor_motor">
      <hardwareInterface>EffortJointInterface</hardwareInterface>
      <mechanicalReduction>100.0</mechanicalReduction>
    </actuator>
  </transmission>
  <!-- ******************************************** -->
  <!-- HOKUYO SENSOR - ATTACHED TO ROVER PART - UP  -->
  <!-- ******************************************** -->
  <joint name="hokuyo_laser_joint" type="fixed">
    <axis xyz="0 1 0"/>
    <origin rpy="3.1416 0.0 0.0" xyz="0.075 0 0.02"/>
    <parent link="rover_link"/>
    <child link="hokuyo_laser_link"/>
  </joint>
  <link name="hokuyo_laser_link" type="laser">
    <inertial>
      <mass value="0.001"/>
      <origin rpy="0 0 0" xyz="0 0 0"/>
      <inertia ixx="0.0001" ixy="0" ixz="0" iyy="0.000001" iyz="0" izz="0.0001"/>
    </inertial>
  </link>
  <!-- This adds a visual box to allow us to see the Hokuyo in rviz/gazebo -->
  <joint name="hokuyo_laser_box_joint" type="fixed">
    <origin rpy="0 0 0" xyz="0 0 0"/>
    <parent link="hokuyo_laser_link"/>
    <child link="hokuyo_laser_box_link"/>
  </joint>
  <link name="hokuyo_laser_box_link">
    <inertial>
      <mass value="0.01"/>
      <origin xyz="0 0 0"/>
      <inertia ixx="0.001" ixy="0.0" ixz="0.0" iyy="0.001" iyz="0.0" izz="0.001"/>
    </inertial>
    <visual>
      <origin rpy="0 0 0" xyz="0 0 0"/>
      <geometry>
        <!--box size="0.05 0.05 0.1" /-->
        <mesh filename="package://summit_xl_description/meshes/hokuyo-utm30-lx.dae" scale="1.0 1.0 1.0"/>
      </geometry>
    </visual>
    <collision>
      <origin rpy="0 0 0" xyz="0 0 0"/>
      <geometry>
        <box size="0.05 0.05 0.1"/>
      </geometry>
    </collision>
  </link>
  <!-- ***************************** -->
  <!-- SCISSOR MECHANISM PART 2      -->
  <!-- ***************************** -->
  <!-- link name="scissor_bars2_link">
    <inertial>
      <mass value="3.0" />
      <origin xyz="0 0 0" />
      <inertia  ixx="0.2185" ixy="0.0"  ixz="-0.001"  iyy="0.33677"  iyz="0.0"  izz="0.20511" />
    </inertial>
    <visual>
       <origin xyz="0 0 0" rpy="0 0 0" />
       <geometry>
	   <mesh filename="package://summit_xl_description/meshes/x_wam/scissor_bars_2.dae"/>
       </geometry>
    </visual>
    <collision>
       <origin xyz="0 0 0" rpy="0 0 0 " />
       <geometry>
       <mesh filename="package://summit_xl_description/meshes/x_wam/scissor_bars_2.dae"/>
       </geometry>
    </collision>     
  </link>
  <joint name="scissor_bars2_joint" type="continuous">
    <parent link="rover_link"/>
    <child link="scissor_bars2_link"/>
    <origin xyz="0.0 0 0" rpy="0 0 0" />
    <axis xyz="0 1 0" />
    <limit effort="300" velocity="1"/ -->
  <!-- lower="-0.86" upper="0.0" / -->
  <!-- dynamics damping="0.1" friction="0.1"/>
  </joint>
  <transmission name="scissor_bars2_trans">
	 <type>transmission_interface/SimpleTransmission</type>
     <joint name="scissor_bars2_joint" />
     <actuator name="scissor_bars2_motor">
		<hardwareInterface>EffortJointInterface</hardwareInterface>
		<mechanicalReduction>0.001</mechanicalReduction>
        <motorTorqueConstant>0.001</motorTorqueConstant>
	 </actuator>
  </transmission -->
  <!-- AXIS PTZ CAMERA -->
  <joint name="camera_joint" type="fixed">
    <axis xyz="0 1 0"/>
    <!-- FRONT MOUNT -->
    <origin xyz="0.3 0.0 0.25"/>
    <parent link="base_link"/>
    <child link="camera_link"/>
  </joint>
  <link name="camera_link">
    <inertial>
      <mass value="0.001"/>
      <origin rpy="0 0 0" xyz="0 0 0"/>
      <inertia ixx="0.0001" ixy="0" ixz="0" iyy="0.000001" iyz="0" izz="0.0001"/>
    </inertial>
  </link>
  <!-- Import Barrett WAM robot xacro file description -->
  <!-- xacro:include filename="$(find wam_description)/urdf/wam_arm.urdf.xacro" / -->
  <gazebo>
    <plugin filename="libgazebo_ros_control.so" name="ros_control">
      <robotNamespace>/wam</robotNamespace>
      <controlPeriod>0.001</controlPeriod>
      <robotSimType>gazebo_ros_control/DefaultRobotHWSim</robotSimType>
    </plugin>
  </gazebo>
  <gazebo reference="wam_link1">
    <material>Gazebo/White</material>
    <gravity>true</gravity>
  </gazebo>
  <gazebo reference="wam_link2">
    <material>Gazebo/Grey</material>
    <gravity>true</gravity>
  </gazebo>
  <gazebo reference="wam_link3">
    <material>Gazebo/Grey</material>
    <gravity>true</gravity>
  </gazebo>
  <gazebo reference="wam_link4">
    <material>Gazebo/Grey</material>
    <gravity>true</gravity>
  </gazebo>
  <gazebo reference="wam_link5">
    <material>Gazebo/Grey</material>
    <gravity>true</gravity>
  </gazebo>
  <gazebo reference="wam_link6">
    <material>Gazebo/Grey</material>
    <gravity>true</gravity>
  </gazebo>
  <gazebo reference="wam_link7">
    <material>Gazebo/Grey</material>
    <gravity>true</gravity>
  </gazebo>
  <link name="wam_base_link">
    <inertial>
      <mass value="5.0"/>
      <origin xyz="0 0 0"/>
      <inertia ixx="5.0" ixy="0.0" ixz="0.0" iyy="5.0" iyz="0.0" izz="5.0"/>
    </inertial>
    <visual>
      <origin rpy="0 0 0" xyz="0 0 0"/>
      <geometry>
        <mesh filename="package://wam_description/meshes/wambase.dae"/>
      </geometry>
    </visual>
    <collision>
      <origin rpy="0 0 0 " xyz="0 0 0"/>
      <geometry>
        <mesh filename="package://wam_description/meshes/wambase.dae"/>
      </geometry>
    </collision>
  </link>
  <link name="wam_link1">
    <inertial>
      <mass value="2.3936"/>
      <origin rpy="0 0 0" xyz="0.0 0.0 0.0"/>
      <inertia ixx="1.0" ixy="0.0" ixz="0.0" iyy="1.0" iyz="0.0" izz="1.0"/>
    </inertial>
    <visual>
      <origin rpy="0 0 0" xyz="0.0 0.0 0.0"/>
      <geometry name="wam_link1_visual">
        <mesh filename="package://wam_description/meshes/wam1.dae" scale="1.0 1.0 1.0"/>
      </geometry>
      <material name="Grey">
        <color rgba="0.75 0.75 0.75 1.0"/>
      </material>
    </visual>
    <collision>
      <origin rpy="0 0 0" xyz="0.0 0.0 0.0"/>
      <geometry name="wam_link1_collision">
        <mesh filename="package://wam_description/meshes/wam1.dae" scale="1.0 1.0 1.0"/>
      </geometry>
      <contact_coefficients kd="1.0" kp="1000.0" mu="0"/>
    </collision>
  </link>
  <joint name="j1_joint" type="revolute">
    <parent link="wam_base_link"/>
    <child link="wam_link1"/>
    <!-- origin xyz="0.125 0 0.55" rpy="0 0 0" / -->
    <origin rpy="0 0 0" xyz="0.0 0 0.0"/>
    <axis xyz="0 0 1"/>
    <limit effort="30.0" lower="-2.6" upper="2.6" velocity="2.0"/>
    <dynamics damping="100.0" friction="1.0"/>
  </joint>
  <transmission name="j1_transmission">
    <type>transmission_interface/SimpleTransmission</type>
    <joint name="j1_joint"/>
    <actuator name="j1">
      <hardwareInterface>EffortJointInterface</hardwareInterface>
      <mechanicalReduction>1</mechanicalReduction>
      <motorTorqueConstant>1</motorTorqueConstant>
    </actuator>
  </transmission>
  <link name="wam_link2">
    <inertial>
      <origin rpy="0 0 0" xyz="0 0 0"/>
      <mass value="1.8487"/>
      <inertia ixx="1.0" ixy="0.0" ixz="0.0" iyy="0.1" iyz="0.0" izz="0.1"/>
    </inertial>
    <visual>
      <origin rpy="0 0 0" xyz="0.0 0.0 0.0"/>
      <geometry name="wam_link2_visual">
        <mesh filename="package://wam_description/meshes/wam2.dae" scale="1.0 1.0 1.0"/>
      </geometry>
      <material name="Grey">
        <color rgba="0.75 0.75 0.75 1.0"/>
      </material>
    </visual>
    <collision>
      <origin rpy="0 0 0" xyz="0.0 0.0 0.0"/>
      <geometry name="wam_link2_collision">
        <mesh filename="package://wam_description/meshes/wam2.dae" scale="1.0 1.0 1.0"/>
      </geometry>
      <contact_coefficients kd="1.0" kp="1000.0" mu="0"/>
    </collision>
  </link>
  <joint name="j2_joint" type="revolute">
    <parent link="wam_link1"/>
    <child link="wam_link2"/>
    <origin rpy="0 0 0" xyz="0.0 0.0 0.0"/>
    <axis xyz="0 1 0"/>
    <limit effort="30.0" lower="-2.0" upper="2.0" velocity="2.0"/>
    <dynamics damping="100.0" friction="1.0"/>
  </joint>
  <transmission name="j2_transmission">
    <type>transmission_interface/SimpleTransmission</type>
    <joint name="j2_joint"/>
    <actuator name="j2">
      <hardwareInterface>EffortJointInterface</hardwareInterface>
      <mechanicalReduction>1</mechanicalReduction>
      <motorTorqueConstant>1</motorTorqueConstant>
    </actuator>
  </transmission>
  <link name="wam_link3">
    <inertial>
      <mass value="0.43"/>
      <origin rpy="0 0 0" xyz="0 0 0.225"/>
      <inertia ixx="1.0" ixy="0.0" ixz="0.0" iyy="0.1" iyz="0.0" izz="0.1"/>
    </inertial>
    <visual>
      <origin rpy="0 0 0" xyz="0.0 0.0 0.0"/>
      <geometry name="wam_link3_visual">
        <mesh filename="package://wam_description/meshes/wam3.dae" scale="1.0 1.0 1.0"/>
      </geometry>
      <material name="Grey">
        <color rgba="0.75 0.75 0.75 1.0"/>
      </material>
    </visual>
    <collision>
      <origin rpy="0 0 0" xyz="0.0 0.0 0.0"/>
      <geometry name="wam_link3_collision">
        <mesh filename="package://wam_description/meshes/wam3.dae" scale="1.0 1.0 1.0"/>
      </geometry>
      <contact_coefficients kd="1.0" kp="1000.0" mu="0"/>
    </collision>
  </link>
  <joint name="j3_joint" type="revolute">
    <parent link="wam_link2"/>
    <child link="wam_link3"/>
    <origin rpy="0 0 0" xyz="0.0 0.0 0.0"/>
    <axis xyz="0 0 1"/>
    <limit effort="30.0" lower="-2.8" upper="2.8" velocity="2.0"/>
    <dynamics damping="100.0" friction="1.0"/>
  </joint>
  <transmission name="j3_transmission">
    <type>transmission_interface/SimpleTransmission</type>
    <joint name="j3_joint"/>
    <actuator name="j3">
      <hardwareInterface>EffortJointInterface</hardwareInterface>
      <mechanicalReduction>1</mechanicalReduction>
      <motorTorqueConstant>1</motorTorqueConstant>
    </actuator>
  </transmission>
  <link name="wam_link4">
    <inertial>
      <mass value="0.52"/>
      <origin rpy="0 0 0" xyz="-0.045 -0.15 0"/>
      <inertia ixx="1.0" ixy="0.0" ixz="0.0" iyy="0.1" iyz="0.0" izz="0.1"/>
    </inertial>
    <visual>
      <origin rpy="0 0 0" xyz="0.0 0.0 0.0"/>
      <geometry name="wam_link4_visual">
        <mesh filename="package://wam_description/meshes/wam4.dae" scale="1.0 1.0 1.0"/>
      </geometry>
      <material name="Grey">
        <color rgba="0.75 0.75 0.75 1.0"/>
      </material>
    </visual>
    <collision>
      <origin rpy="0 0 0" xyz="0.0 0.0 0.0"/>
      <geometry name="wam_link4_collision">
        <mesh filename="package://wam_description/meshes/wam4.dae" scale="1.0 1.0 1.0"/>
      </geometry>
      <contact_coefficients kd="1.0" kp="1000.0" mu="0"/>
    </collision>
  </link>
  <joint name="j4_joint" type="revolute">
    <parent link="wam_link3"/>
    <child link="wam_link4"/>
    <origin rpy="-1.57079632679 0 0" xyz="0.045 0.0 0.55"/>
    <axis xyz="0 0 1"/>
    <limit effort="30.0" lower="-0.9" upper="2.8" velocity="2.0"/>
    <dynamics damping="100.0" friction="1.0"/>
  </joint>
  <transmission name="j4_transmission">
    <type>transmission_interface/SimpleTransmission</type>
    <joint name="j4_joint"/>
    <actuator name="j4">
      <hardwareInterface>EffortJointInterface</hardwareInterface>
      <mechanicalReduction>1</mechanicalReduction>
      <motorTorqueConstant>1</motorTorqueConstant>
    </actuator>
  </transmission>
  <link name="wam_link5">
    <inertial>
      <origin rpy="0 0 0" xyz="0 0 0"/>
      <mass value="0.076675"/>
      <inertia ixx="1.0" ixy="0.0" ixz="0.0" iyy="0.1" iyz="0.0" izz="0.1"/>
    </inertial>
    <visual>
      <origin rpy="0 0 0" xyz="0.0 0.0 0.0"/>
      <geometry name="wam_link5_visual">
        <mesh filename="package://wam_description/meshes/wam5.dae" scale="1.0 1.0 1.0"/>
      </geometry>
      <material name="Grey">
        <color rgba="0.75 0.75 0.75 1.0"/>
      </material>
    </visual>
    <collision>
      <origin rpy="0 0 0" xyz="0.0 0.0 0.0"/>
      <geometry name="wam_link5_collision">
        <mesh filename="package://wam_description/meshes/wam5.dae" scale="1.0 1.0 1.0"/>
      </geometry>
      <contact_coefficients kd="1.0" kp="1000.0" mu="0"/>
    </collision>
  </link>
  <joint name="j5_joint" type="revolute">
    <parent link="wam_link4"/>
    <child link="wam_link5"/>
    <origin rpy="1.57079632679 0 0" xyz="-0.045 -0.3 0.0"/>
    <axis xyz="0 0 1"/>
    <limit effort="30.0" lower="-4.8" upper="1.3" velocity="2.0"/>
    <dynamics damping="100.0" friction="1.0"/>
  </joint>
  <transmission name="j5_transmission">
    <type>transmission_interface/SimpleTransmission</type>
    <joint name="j5_joint"/>
    <actuator name="j5">
      <hardwareInterface>EffortJointInterface</hardwareInterface>
      <mechanicalReduction>1</mechanicalReduction>
      <motorTorqueConstant>1</motorTorqueConstant>
    </actuator>
  </transmission>
  <link name="wam_link6">
    <inertial>
      <origin rpy="0 0 0" xyz="0 0 0"/>
      <mass value="0.10695"/>
      <inertia ixx="1.0" ixy="0.0" ixz="0.0" iyy="0.1" iyz="0.0" izz="0.1"/>
    </inertial>
    <visual>
      <origin rpy="0 0 0" xyz="0.0 0.0 0.0"/>
      <geometry name="wam_link6_visual">
        <mesh filename="package://wam_description/meshes/wam6.dae" scale="1.0 1.0 1.0"/>
      </geometry>
      <material name="Grey">
        <color rgba="0.75 0.75 0.75 1.0"/>
      </material>
    </visual>
    <collision>
      <origin rpy="0 0 0" xyz="0.0 0.0 0.0"/>
      <geometry name="wam_link6_collision">
        <mesh filename="package://wam_description/meshes/wam6.dae" scale="1.0 1.0 1.0"/>
      </geometry>
      <contact_coefficients kd="1.0" kp="1000.0" mu="0"/>
    </collision>
  </link>
  <joint name="j6_joint" type="revolute">
    <parent link="wam_link5"/>
    <child link="wam_link6"/>
    <origin rpy="-1.57079632679 0 0" xyz="0.0 0.0 0.0"/>
    <axis xyz="0 0 1"/>
    <limit effort="30.0" lower="-1.6" upper="1.6" velocity="2.0"/>
    <dynamics damping="100.0" friction="1.0"/>
  </joint>
  <transmission name="j6_transmission">
    <type>transmission_interface/SimpleTransmission</type>
    <joint name="j6_joint"/>
    <actuator name="j6">
      <hardwareInterface>EffortJointInterface</hardwareInterface>
      <mechanicalReduction>1</mechanicalReduction>
      <motorTorqueConstant>1</motorTorqueConstant>
    </actuator>
  </transmission>
  <link name="wam_link7">
    <inertial>
      <origin rpy="0 0 0" xyz="0 0 0"/>
      <mass value="0.013925"/>
      <inertia ixx="1.0" ixy="0.0" ixz="0.0" iyy="0.1" iyz="0.0" izz="0.1"/>
    </inertial>
    <visual>
      <origin rpy="0 0 0" xyz="0.0 0.0 0.0"/>
      <geometry name="wam_link7_visual">
        <mesh filename="package://wam_description/meshes/wam7.dae" scale="1.0 1.0 1.0"/>
      </geometry>
      <material name="Grey">
        <color rgba="0.75 0.75 0.75 1.0"/>
      </material>
    </visual>
    <collision>
      <origin rpy="0 0 0" xyz="0.0 0.0 0.0"/>
      <geometry name="wam_link7_collision">
        <mesh filename="package://wam_description/meshes/wam7.dae" scale="1.0 1.0 1.0"/>
      </geometry>
      <contact_coefficients kd="1.0" kp="1000.0" mu="0"/>
    </collision>
  </link>
  <joint name="j7_joint" type="revolute">
    <parent link="wam_link6"/>
    <child link="wam_link7"/>
    <origin rpy="1.57079632679 0 0" xyz="0.0 0.0 0.0"/>
    <axis xyz="0 0 1"/>
    <limit effort="30.0" lower="-2.2" upper="2.2" velocity="2.0"/>
    <dynamics damping="100.0" friction="1.0"/>
  </joint>
  <transmission name="j7_transmission">
    <type>transmission_interface/SimpleTransmission</type>
    <joint name="j7_joint"/>
    <actuator name="j7">
      <hardwareInterface>EffortJointInterface</hardwareInterface>
      <mechanicalReduction>1</mechanicalReduction>
      <motorTorqueConstant>1</motorTorqueConstant>
    </actuator>
  </transmission>
  <link name="wam_tcp"/>
  <joint name="wamtcp_fix" type="fixed">
    <parent link="wam_link7"/>
    <child link="wam_tcp"/>
    <origin rpy="0 0 0" xyz="0.0 0.0 0.0"/>
  </joint>
  <gazebo>
    <plugin filename="libgazebo_ros_control.so" name="ros_control">
      <robotNamespace>/bh</robotNamespace>
      <controlPeriod>0.001</controlPeriod>
      <robotSimType>gazebo_ros_control/DefaultRobotHWSim</robotSimType>
    </plugin>
  </gazebo>
  <gazebo reference="base_link">
    <material>Gazebo/White</material>
    <gravity>true</gravity>
  </gazebo>
  <gazebo reference="bh_finger_31_link">
    <material>Gazebo/Grey</material>
    <gravity>true</gravity>
  </gazebo>
  <gazebo reference="bh_finger_32_link">
    <material>Gazebo/Grey</material>
    <gravity>true</gravity>
  </gazebo>
  <gazebo reference="bh_finger_33_link">
    <material>Gazebo/Grey</material>
    <gravity>true</gravity>
  </gazebo>
  <gazebo reference="bh_finger_11_link">
    <material>Gazebo/Grey</material>
    <gravity>true</gravity>
  </gazebo>
  <gazebo reference="bh_finger_12_link">
    <material>Gazebo/Grey</material>
    <gravity>true</gravity>
  </gazebo>
  <gazebo reference="bh_finger_13_link">
    <material>Gazebo/Grey</material>
    <gravity>true</gravity>
  </gazebo>
  <link name="bh_base_link">
    <inertial>
      <mass value="1.0"/>
      <origin xyz="0 0 0"/>
      <inertia ixx="1.0" ixy="0.0" ixz="0.0" iyy="1.0" iyz="0.0" izz="1.0"/>
    </inertial>
    <visual>
      <origin rpy="0 0 0" xyz="0 0 0"/>
      <geometry>
        <mesh filename="package://bh262_description/meshes/bhand/palm.dae"/>
      </geometry>
      <material name="Grey">
        <color rgba="0.75 0.75 0.75 1.0"/>
      </material>
    </visual>
    <collision>
      <origin rpy="0 0 0 " xyz="0 0 0"/>
      <geometry name="bh_palm_collision">
        <mesh filename="package://bh262_description/meshes/bhand/palm.dae"/>
      </geometry>
      <contact_coefficients kd="1.0" kp="1000.0" mu="0"/>
    </collision>
  </link>
  <link name="bh_grasp_link"/>
  <joint name="bh_grasp_joint" type="fixed">
    <origin rpy="0 0 0" xyz="0 0 0.15"/>
    <parent link="bh_base_link"/>
    <child link="bh_grasp_link"/>
  </joint>
  <link name="bh_finger_31_link">
    <inertial>
      <mass value="0.1"/>
      <origin rpy="0 0 0" xyz="-0.046 0 0"/>
      <inertia ixx="0.01" ixy="0" ixz="0" iyy="0.01" iyz="0" izz="0.01"/>
    </inertial>
    <visual>
      <origin rpy="0 0 0" xyz="-0.046 0 0"/>
      <geometry>
        <mesh filename="package://bh262_description/meshes/bhand/knuckle.dae"/>
      </geometry>
      <material name="Black"/>
    </visual>
    <collision>
      <origin rpy="0 0 0" xyz="-0.046 0 0"/>
      <geometry>
        <mesh filename="package://bh262_description/meshes/bhand/knuckle.dae"/>
      </geometry>
      <contact_coefficients kd="1.0" kp="1000.0" mu="0"/>
    </collision>
  </link>
  <joint name="j31_joint" type="fixed">
    <parent link="bh_base_link"/>
    <child link="bh_finger_31_link"/>
    <origin rpy="0 0 0" xyz="0 0 0.06"/>
  </joint>
  <link name="bh_finger_32_link">
    <inertial>
      <mass value="0.1"/>
      <origin rpy="0 0 0" xyz="0 0 0"/>
      <inertia ixx="0.01" ixy="0" ixz="0" iyy="0.01" iyz="0" izz="0.01"/>
    </inertial>
    <visual>
      <origin rpy="0 0 0" xyz="0 0 0"/>
      <geometry>
        <mesh filename="package://bh262_description/meshes/bhand/finger.dae"/>
      </geometry>
      <material name="Blue"/>
    </visual>
    <collision>
      <origin rpy="0 0 0" xyz="0 0 0"/>
      <geometry>
        <mesh filename="package://bh262_description/meshes/bhand/finger.dae"/>
      </geometry>
      <contact_coefficients kd="1.0" kp="1000.0" mu="0"/>
    </collision>
  </link>
  <joint name="j32_joint" type="revolute">
    <parent link="bh_finger_31_link"/>
    <child link="bh_finger_32_link"/>
    <origin rpy="0 0 0" xyz="-0.050 0 0.030"/>
    <axis xyz="0 1 0"/>
    <limit effort="30.0" lower="-1.5708" upper="0.8727" velocity="2.0"/>
    <dynamics damping="100.0" friction="1.0"/>
  </joint>
  <transmission name="j32_transmission">
    <type>transmission_interface/SimpleTransmission</type>
    <joint name="j32_joint"/>
    <actuator name="j32">
      <hardwareInterface>EffortJointInterface</hardwareInterface>
      <mechanicalReduction>1</mechanicalReduction>
      <motorTorqueConstant>1</motorTorqueConstant>
    </actuator>
  </transmission>
  <link name="bh_finger_33_link">
    <inertial>
      <mass value="0.1"/>
      <origin rpy="0 0 0" xyz="0 0 0"/>
      <inertia ixx="0.01" ixy="0" ixz="0" iyy="0.01" iyz="0" izz="0.01"/>
    </inertial>
    <visual>
      <origin rpy="0 0 0" xyz="0 0 0"/>
      <geometry>
        <mesh filename="package://bh262_description/meshes/bhand/finger_tip.dae"/>
      </geometry>
      <material name="Blue"/>
    </visual>
    <collision>
      <origin rpy="0 0 0" xyz="0 0 0"/>
      <geometry>
        <mesh filename="package://bh262_description/meshes/bhand/finger_tip.dae"/>
      </geometry>
      <contact_coefficients kd="1.0" kp="1000.0" mu="0"/>
    </collision>
  </link>
  <joint name="j33_joint" type="revolute">
    <parent link="bh_finger_32_link"/>
    <child link="bh_finger_33_link"/>
    <origin rpy="0 0 1.57079633" xyz="0 0 0.07"/>
    <axis xyz="1 0 0"/>
    <limit effort="30.0" lower="0.7330" upper="1.5708" velocity="2.0"/>
    <dynamics damping="100.0" friction="1.0"/>
  </joint>
  <transmission name="j33_transmission">
    <type>transmission_interface/SimpleTransmission</type>
    <joint name="j33_joint"/>
    <actuator name="j33">
      <hardwareInterface>EffortJointInterface</hardwareInterface>
      <mechanicalReduction>1</mechanicalReduction>
      <motorTorqueConstant>1</motorTorqueConstant>
    </actuator>
  </transmission>
  <link name="bh_finger_11_link">
    <inertial>
      <mass value="0.1"/>
      <origin rpy="0 0 0" xyz="-0.046 0 0"/>
      <inertia ixx="0.01" ixy="0" ixz="0" iyy="0.01" iyz="0" izz="0.01"/>
    </inertial>
    <visual>
      <origin rpy="0 0 0" xyz="-0.046 0 0"/>
      <geometry>
        <mesh filename="package://bh262_description/meshes/bhand/knuckle.dae"/>
      </geometry>
      <material name="Green"/>
    </visual>
    <collision>
      <origin rpy="0 0 0" xyz="-0.046 0 0"/>
      <geometry>
        <mesh filename="package://bh262_description/meshes/bhand/knuckle.dae"/>
      </geometry>
    </collision>
  </link>
  <joint name="j11_joint" type="revolute">
    <parent link="bh_base_link"/>
    <child link="bh_finger_11_link"/>
    <origin rpy="0 0 3.14" xyz="0.0 -0.025 0.06"/>
    <axis xyz="0 0 1"/>
    <limit effort="30.0" lower="-3.1416" upper="0" velocity="2.0"/>
    <dynamics damping="100.0" friction="1.0"/>
  </joint>
  <transmission name="j11_transmission">
    <type>transmission_interface/SimpleTransmission</type>
    <joint name="j11_joint"/>
    <actuator name="j11">
      <hardwareInterface>EffortJointInterface</hardwareInterface>
      <mechanicalReduction>1</mechanicalReduction>
      <motorTorqueConstant>1</motorTorqueConstant>
    </actuator>
  </transmission>
  <link name="bh_finger_12_link">
    <inertial>
      <mass value="0.1"/>
      <origin rpy="0 0 0" xyz="0 0 0"/>
      <inertia ixx="0.01" ixy="0" ixz="0" iyy="0.01" iyz="0" izz="0.01"/>
    </inertial>
    <visual>
      <origin rpy="0 0 0" xyz="0 0 0"/>
      <geometry>
        <mesh filename="package://bh262_description/meshes/bhand/finger.dae"/>
      </geometry>
      <material name="Blue"/>
    </visual>
    <collision>
      <origin rpy="0 0 0" xyz="0 0 0"/>
      <geometry>
        <mesh filename="package://bh262_description/meshes/bhand/finger.dae"/>
      </geometry>
    </collision>
  </link>
  <joint name="j12_joint" type="revolute">
    <parent link="bh_finger_11_link"/>
    <child link="bh_finger_12_link"/>
    <origin rpy="0 0 0" xyz="-0.050 0 0.025"/>
    <axis xyz="0 1 0"/>
    <limit effort="30.0" lower="-1.5708" upper="0.8727" velocity="2.0"/>
    <dynamics damping="100.0" friction="1.0"/>
  </joint>
  <transmission name="j12_transmission">
    <type>transmission_interface/SimpleTransmission</type>
    <joint name="j12_joint"/>
    <actuator name="j12">
      <hardwareInterface>EffortJointInterface</hardwareInterface>
      <mechanicalReduction>1</mechanicalReduction>
      <motorTorqueConstant>1</motorTorqueConstant>
    </actuator>
  </transmission>
  <link name="bh_finger_13_link">
    <inertial>
      <mass value="0.1"/>
      <origin rpy="0 0 0" xyz="0 0 0"/>
      <inertia ixx="0.01" ixy="0" ixz="0" iyy="0.01" iyz="0" izz="0.01"/>
    </inertial>
    <visual>
      <origin rpy="0 0 0" xyz="0 0 0"/>
      <geometry>
        <mesh filename="package://bh262_description/meshes/bhand/finger_tip.dae"/>
      </geometry>
      <material name="Yellow"/>
    </visual>
    <collision>
      <origin rpy="0 0 0" xyz="0 0 0"/>
      <geometry>
        <mesh filename="package://bh262_description/meshes/bhand/finger_tip.dae"/>
      </geometry>
    </collision>
  </link>
  <joint name="j13_joint" type="revolute">
    <parent link="bh_finger_12_link"/>
    <child link="bh_finger_13_link"/>
    <origin rpy="0 0 1.57079633" xyz="0 0 0.070"/>
    <axis xyz="1 0 0"/>
    <limit effort="30.0" lower="0.7330" upper="1.5708" velocity="2.0"/>
    <dynamics damping="100.0" friction="1.0"/>
  </joint>
  <transmission name="j13_transmission">
    <type>transmission_interface/SimpleTransmission</type>
    <joint name="j13_joint"/>
    <actuator name="j13">
      <hardwareInterface>EffortJointInterface</hardwareInterface>
      <mechanicalReduction>1</mechanicalReduction>
      <motorTorqueConstant>1</motorTorqueConstant>
    </actuator>
  </transmission>
  <link name="bh_finger_21_link">
    <inertial>
      <mass value="0.1"/>
      <origin rpy="0 0 0" xyz="-0.046 0 0"/>
      <inertia ixx="0.01" ixy="0" ixz="0" iyy="0.01" iyz="0" izz="0.01"/>
    </inertial>
    <visual>
      <origin rpy="0 0 0" xyz="-0.046 0 0"/>
      <geometry>
        <mesh filename="package://bh262_description/meshes/bhand/knuckle.dae"/>
      </geometry>
      <material name="Black"/>
    </visual>
    <collision>
      <origin rpy="0 0 0" xyz="-0.046 0 0"/>
      <geometry>
        <mesh filename="package://bh262_description/meshes/bhand/knuckle.dae"/>
      </geometry>
    </collision>
  </link>
  <joint name="j21_joint" type="revolute">
    <parent link="bh_base_link"/>
    <child link="bh_finger_21_link"/>
    <origin rpy="0 0 3.14" xyz="0.0 0.025 0.06"/>
    <axis xyz="0 0 1"/>
    <limit effort="30.0" lower="0" upper="3.1416" velocity="2.0"/>
    <dynamics damping="100.0" friction="1.0"/>
  </joint>
  <transmission name="j21_transmission">
    <type>transmission_interface/SimpleTransmission</type>
    <joint name="j21_joint"/>
    <actuator name="j21">
      <hardwareInterface>EffortJointInterface</hardwareInterface>
      <mechanicalReduction>1</mechanicalReduction>
      <motorTorqueConstant>1</motorTorqueConstant>
    </actuator>
  </transmission>
  <link name="bh_finger_22_link">
    <inertial>
      <mass value="0.1"/>
      <origin rpy="0 0 0" xyz="0 0 0"/>
      <inertia ixx="0.01" ixy="0" ixz="0" iyy="0.01" iyz="0" izz="0.01"/>
    </inertial>
    <visual>
      <origin rpy="0 0 0" xyz="0 0 0"/>
      <geometry>
        <mesh filename="package://bh262_description/meshes/bhand/finger.dae"/>
      </geometry>
      <material name="Blue"/>
    </visual>
    <collision>
      <origin rpy="0 0 0" xyz="0 0 0"/>
      <geometry>
        <mesh filename="package://bh262_description/meshes/bhand/finger.dae"/>
      </geometry>
    </collision>
  </link>
  <joint name="j22_joint" type="revolute">
    <parent link="bh_finger_21_link"/>
    <child link="bh_finger_22_link"/>
    <origin rpy="0 0 0" xyz="-0.050 0 0.025"/>
    <axis xyz="0 1 0"/>
    <limit effort="30.0" lower="-1.5708" upper="0.8727" velocity="2.0"/>
    <dynamics damping="100.0" friction="1.0"/>
  </joint>
  <transmission name="j22_transmission">
    <type>transmission_interface/SimpleTransmission</type>
    <joint name="j22_joint"/>
    <actuator name="j22">
      <hardwareInterface>EffortJointInterface</hardwareInterface>
      <mechanicalReduction>1</mechanicalReduction>
      <motorTorqueConstant>1</motorTorqueConstant>
    </actuator>
  </transmission>
  <link name="bh_finger_23_link">
    <inertial>
      <origin rpy="0 0 0" xyz="0 0 0"/>
      <mass value="0.1"/>
      <inertia ixx="0.01" ixy="0" ixz="0" iyy="0.01" iyz="0" izz="0.01"/>
    </inertial>
    <visual>
      <origin rpy="0 0 0" xyz="0 0 0"/>
      <geometry>
        <mesh filename="package://bh262_description/meshes/bhand/finger_tip.dae"/>
      </geometry>
      <material name="Yellow"/>
    </visual>
    <collision>
      <origin rpy="0 0 0" xyz="0 0 0"/>
      <geometry>
        <mesh filename="package://bh262_description/meshes/bhand/finger_tip.dae"/>
      </geometry>
    </collision>
  </link>
  <joint name="j23_joint" type="revolute">
    <parent link="bh_finger_22_link"/>
    <child link="bh_finger_23_link"/>
    <origin rpy="0 0 1.57079633" xyz="0 0 0.070"/>
    <axis xyz="1 0 0"/>
    <limit effort="30.0" lower="0.7330" upper="1.5708" velocity="2.0"/>
    <dynamics damping="100.0" friction="1.0"/>
  </joint>
  <transmission name="j23_transmission">
    <type>transmission_interface/SimpleTransmission</type>
    <joint name="j23_joint"/>
    <actuator name="j23">
      <hardwareInterface>EffortJointInterface</hardwareInterface>
      <mechanicalReduction>1</mechanicalReduction>
      <motorTorqueConstant>1</motorTorqueConstant>
    </actuator>
  </transmission>
  <joint name="base_footprint_bh_joint" type="fixed">
    <origin rpy="0 0 0" xyz="0.0 0.0 0.0"/>
    <parent link="wam_tcp"/>
    <child link="bh_base_link"/>
  </joint>
  <joint name="base_footprint_wam_joint" type="fixed">
    <origin rpy="0 0 0" xyz="-0.220 0 0.410"/>
    <parent link="rover_link"/>
    <child link="wam_base_link"/>
    <!-- axis xyz="0 0 0" / -->
  </joint>
</robot>

