<?xml version="1.0"?>
<robot name="wheel" xmlns:xacro="http://wiki.ros.org/xacro">

  <xacro:property name="M_PI" value="3.1415926535897931" />

  <material name="dark-gray">
    <color rgba="0.8 0.8 0.8 1"/>
  </material>

  <xacro:macro name="cylinder_inertia" params="m r h">
    <inertia  ixx="${m*(3*r*r+h*h)/12}" ixy = "0" ixz = "0"
              iyy="${m*r*r/2}" iyz = "0"
              izz="${m*(3*r*r+h*h)/12}" />
  </xacro:macro>

  <xacro:macro name="basic_wheel" params="prefix parent *origin radius height mass">

  <!--WHEEL TIRE -->
    <joint name="${prefix}_wheel_joint" type="continuous">
      <parent link="${parent}"/>
      <child link="${prefix}_wheel"/>
      <xacro:insert_block name="origin" />
      <axis xyz="0 1 0" rpy="0 0 0" />
      <limit effort="100" velocity="100"/>
      <joint_properties damping="0.0" friction="0.0"/>
    </joint>

    <link name="${prefix}_wheel">
      <visual>
        <origin xyz="0 0 0" rpy="${M_PI/2} 0 0" />
        <geometry>
          <cylinder length="${height}" radius="${radius}" />
        </geometry>
        <material name="dark-gray"/>
      </visual>

      <collision>
				<origin xyz="0 0 0" rpy="${M_PI/2} 0 0" />
        <geometry>
          <cylinder length="${height}" radius="${radius}" />
        </geometry>
      </collision>

      <inertial>
        <mass value="${mass}" />
        <origin xyz="0 0 0" />
        <xacro:cylinder_inertia  m="${mass}" r="${radius}" h="${height}" />
      </inertial>
    </link>


    <!-- Transmission is important to link the joints and the controller (see summit_xl_control/config/summit_xl_control.yaml)-->
    <transmission name="${prefix}_wheel_joint_trans">
      <type>transmission_interface/SimpleTransmission</type>
      <joint name="${prefix}_wheel_joint">
        <hardwareInterface>hardware_interface/VelocityJointInterface</hardwareInterface>
      </joint>
      <actuator name="${prefix}_wheel_joint_motor">
        <mechanicalReduction>1</mechanicalReduction>
        <motorTorqueConstant>20</motorTorqueConstant>
      </actuator>
     </transmission>

    <gazebo reference="${prefix}_wheel">
			<mu1 value="1.0"/>
			<mu2 value="1.0"/>
			<kp value="10000000.0" />
			<kd value="1.0" />
			<fdir1 value="1 0 0"/>
      <turnGravityOff>false</turnGravityOff>
    </gazebo>


  </xacro:macro>

</robot>
