<?xml version="1.0" ?>
<!-- =================================================================================== -->
<!-- |    This document was autogenerated by xacro from summit_xl_170420A.urdf.xacro   | -->
<!-- |    EDITING THIS FILE BY HAND IS NOT RECOMMENDED                                 | -->
<!-- =================================================================================== -->
<robot name="summit_xl" xmlns:xacro="http://www.ros.org/wiki/xacro">
  <!-- ***************** -->
  <!-- Imported elements -->
  <!-- ***************** -->
  <!-- First we import all posible elements defined in the urdf.xacro files. All these elements are defined as macro:xacros -->
  <gazebo reference="base_footprint">
    <material>Gazebo/Green</material>
  </gazebo>
  <!-- in kg-->
  <!-- This file unifies all sensors that can be used on simulation, defined as xacro:macros -->
  <!-- ***************** -->
  <!-- Global parameters -->
  <!-- ***************** -->
  <!-- *************** -->
  <!-- Robots Elements -->
  <!-- *************** -->
  <!-- Here we create the robot elements using the xacro:macros imported at the beggining of this file -->
  <link name="summit_xl_base_footprint">
    <visual>
      <origin rpy="0 0 0" xyz="0 0 0"/>
      <geometry>
        <box size="0.001 0.001 0.001"/>
      </geometry>
    </visual>
  </link>
  <joint name="summit_xl_base_footprint_joint" type="fixed">
    <origin rpy="0 0 0" xyz="0 0 0.125"/>
    <!-- ${wheel_radius} property must be defined inside wheel description -->
    <parent link="summit_xl_base_footprint"/>
    <child link="summit_xl_base_link"/>
  </joint>
  <!-- BASE_LINK -->
  <link name="summit_xl_base_link">
    <inertial>
      <mass value="25.0"/>
      <origin xyz="0 0 0"/>
      <inertia ixx="1.391" ixy="0.004" ixz="0.0" iyy="6.853" iyz="0.0" izz="6.125"/>
    </inertial>
    <visual>
      <origin rpy="0 0 0" xyz="0 0 0"/>
      <geometry>
        <mesh filename="package://summit_xl_description/meshes/bases/summit_xl_hl_chassis.dae"/>
      </geometry>
      <material name="darkgrey">
        <color rgba="0.1 0.1 0.1 1"/>
      </material>
    </visual>
    <collision>
      <origin rpy="0 0 0 " xyz="0 0 0"/>
      <geometry>
        <mesh filename="package://summit_xl_description/meshes/bases/summit_xl_hl_chassis.dae"/>
      </geometry>
    </collision>
  </link>
  <gazebo>
    <plugin filename="libgazebo_ros_control.so" name="ros_control">
      <!--<robotNamespace>/summit_xl</robotNamespace>-->
      <robotParam>robot_description</robotParam>
      <controlPeriod>0.001</controlPeriod>
      <robotSimType>gazebo_ros_control/DefaultRobotHWSim</robotSimType>
    </plugin>
  </gazebo>
  <!-- Gazebo skid steering pluggins -->
  <!-- Simulation now uses a set of ros_control controllers and a node called summit_xl_robot_control -->
  <!--xacro:ros_force_based_move broadcastOdomTF="0"/-->
  <!--xacro:skid_steering broadcastOdomTF="0"/>-->
  <!-- Gazebo omni steering plugin -->
  <!--xacro:omni_steering/-->
  <!-- WHEELS -->
  <!--WHEEL TIRE -->
  <joint name="summit_xl_front_right_wheel_joint" type="continuous">
    <parent link="summit_xl_base_link"/>
    <child link="summit_xl_front_right_wheel"/>
    <origin rpy="0 0 0" xyz="0.229 -0.234 0.0"/>
    <axis rpy="0 0 0" xyz="0 1 0"/>
    <limit effort="100" velocity="100"/>
    <joint_properties damping="0.0" friction="0.0"/>
  </joint>
  <link name="summit_xl_front_right_wheel">
    <visual>
      <origin rpy="0 0 0" xyz="0 0 0"/>
      <geometry>
        <mesh filename="package://summit_xl_description/meshes/wheels/rubber_wheel_right.dae"/>
      </geometry>
    </visual>
    <collision>
      <origin rpy="1.57079632679 0 0" xyz="0 0 0"/>
      <geometry>
        <cylinder length="0.14" radius="0.125"/>
      </geometry>
    </collision>
    <inertial>
      <mass value="6.5"/>
      <origin xyz="0 0 0"/>
      <inertia ixx="0.0360072916667" ixy="0" ixz="0" iyy="0.05078125" iyz="0" izz="0.0360072916667"/>
    </inertial>
  </link>
  <!-- Transmission is important to link the joints and the controller (see summit_xl_control/config/summit_xl_control.yaml)-->
  <transmission name="summit_xl_front_right_wheel_joint_trans">
    <type>transmission_interface/SimpleTransmission</type>
    <joint name="summit_xl_front_right_wheel_joint">
      <hardwareInterface>hardware_interface/VelocityJointInterface</hardwareInterface>
    </joint>
    <actuator name="summit_xl_front_right_wheel_joint_motor">
      <mechanicalReduction>1</mechanicalReduction>
      <motorTorqueConstant>20</motorTorqueConstant>
    </actuator>
  </transmission>
  <gazebo reference="summit_xl_front_right_wheel">
    <mu1 value="1.0"/>
    <mu2 value="1.0"/>
    <kp value="10000000.0"/>
    <kd value="1.0"/>
    <fdir1 value="1 0 0"/>
    <turnGravityOff>false</turnGravityOff>
  </gazebo>
  <!--WHEEL TIRE -->
  <joint name="summit_xl_front_left_wheel_joint" type="continuous">
    <parent link="summit_xl_base_link"/>
    <child link="summit_xl_front_left_wheel"/>
    <origin rpy="0 0 0" xyz="0.229 0.234 0.0"/>
    <axis rpy="0 0 0" xyz="0 1 0"/>
    <limit effort="100" velocity="100"/>
    <joint_properties damping="0.0" friction="0.0"/>
  </joint>
  <link name="summit_xl_front_left_wheel">
    <visual>
      <origin rpy="0 0 0" xyz="0 0 0"/>
      <geometry>
        <mesh filename="package://summit_xl_description/meshes/wheels/rubber_wheel_left.dae"/>
      </geometry>
    </visual>
    <collision>
      <origin rpy="1.57079632679 0 0" xyz="0 0 0"/>
      <geometry>
        <cylinder length="0.14" radius="0.125"/>
      </geometry>
    </collision>
    <inertial>
      <mass value="6.5"/>
      <origin xyz="0 0 0"/>
      <inertia ixx="0.0360072916667" ixy="0" ixz="0" iyy="0.05078125" iyz="0" izz="0.0360072916667"/>
    </inertial>
  </link>
  <!-- Transmission is important to link the joints and the controller (see summit_xl_control/config/summit_xl_control.yaml)-->
  <transmission name="summit_xl_front_left_wheel_joint_trans">
    <type>transmission_interface/SimpleTransmission</type>
    <joint name="summit_xl_front_left_wheel_joint">
      <hardwareInterface>hardware_interface/VelocityJointInterface</hardwareInterface>
    </joint>
    <actuator name="summit_xl_front_left_wheel_joint_motor">
      <mechanicalReduction>1</mechanicalReduction>
      <motorTorqueConstant>20</motorTorqueConstant>
    </actuator>
  </transmission>
  <gazebo reference="summit_xl_front_left_wheel">
    <mu1 value="1.0"/>
    <mu2 value="1.0"/>
    <kp value="10000000.0"/>
    <kd value="1.0"/>
    <fdir1 value="1 0 0"/>
    <turnGravityOff>false</turnGravityOff>
  </gazebo>
  <!--WHEEL TIRE -->
  <joint name="summit_xl_back_left_wheel_joint" type="continuous">
    <parent link="summit_xl_base_link"/>
    <child link="summit_xl_back_left_wheel"/>
    <origin rpy="0 0 0" xyz="-0.229 0.234 0.0"/>
    <axis rpy="0 0 0" xyz="0 1 0"/>
    <limit effort="100" velocity="100"/>
    <joint_properties damping="0.0" friction="0.0"/>
  </joint>
  <link name="summit_xl_back_left_wheel">
    <visual>
      <origin rpy="0 0 0" xyz="0 0 0"/>
      <geometry>
        <mesh filename="package://summit_xl_description/meshes/wheels/rubber_wheel_left.dae"/>
      </geometry>
    </visual>
    <collision>
      <origin rpy="1.57079632679 0 0" xyz="0 0 0"/>
      <geometry>
        <cylinder length="0.14" radius="0.125"/>
      </geometry>
    </collision>
    <inertial>
      <mass value="6.5"/>
      <origin xyz="0 0 0"/>
      <inertia ixx="0.0360072916667" ixy="0" ixz="0" iyy="0.05078125" iyz="0" izz="0.0360072916667"/>
    </inertial>
  </link>
  <!-- Transmission is important to link the joints and the controller (see summit_xl_control/config/summit_xl_control.yaml)-->
  <transmission name="summit_xl_back_left_wheel_joint_trans">
    <type>transmission_interface/SimpleTransmission</type>
    <joint name="summit_xl_back_left_wheel_joint">
      <hardwareInterface>hardware_interface/VelocityJointInterface</hardwareInterface>
    </joint>
    <actuator name="summit_xl_back_left_wheel_joint_motor">
      <mechanicalReduction>1</mechanicalReduction>
      <motorTorqueConstant>20</motorTorqueConstant>
    </actuator>
  </transmission>
  <gazebo reference="summit_xl_back_left_wheel">
    <mu1 value="1.0"/>
    <mu2 value="1.0"/>
    <kp value="10000000.0"/>
    <kd value="1.0"/>
    <fdir1 value="1 0 0"/>
    <turnGravityOff>false</turnGravityOff>
  </gazebo>
  <!--WHEEL TIRE -->
  <joint name="summit_xl_back_right_wheel_joint" type="continuous">
    <parent link="summit_xl_base_link"/>
    <child link="summit_xl_back_right_wheel"/>
    <origin rpy="0 0 0" xyz="-0.229 -0.234 0.0"/>
    <axis rpy="0 0 0" xyz="0 1 0"/>
    <limit effort="100" velocity="100"/>
    <joint_properties damping="0.0" friction="0.0"/>
  </joint>
  <link name="summit_xl_back_right_wheel">
    <visual>
      <origin rpy="0 0 0" xyz="0 0 0"/>
      <geometry>
        <mesh filename="package://summit_xl_description/meshes/wheels/rubber_wheel_right.dae"/>
      </geometry>
    </visual>
    <collision>
      <origin rpy="1.57079632679 0 0" xyz="0 0 0"/>
      <geometry>
        <cylinder length="0.14" radius="0.125"/>
      </geometry>
    </collision>
    <inertial>
      <mass value="6.5"/>
      <origin xyz="0 0 0"/>
      <inertia ixx="0.0360072916667" ixy="0" ixz="0" iyy="0.05078125" iyz="0" izz="0.0360072916667"/>
    </inertial>
  </link>
  <!-- Transmission is important to link the joints and the controller (see summit_xl_control/config/summit_xl_control.yaml)-->
  <transmission name="summit_xl_back_right_wheel_joint_trans">
    <type>transmission_interface/SimpleTransmission</type>
    <joint name="summit_xl_back_right_wheel_joint">
      <hardwareInterface>hardware_interface/VelocityJointInterface</hardwareInterface>
    </joint>
    <actuator name="summit_xl_back_right_wheel_joint_motor">
      <mechanicalReduction>1</mechanicalReduction>
      <motorTorqueConstant>20</motorTorqueConstant>
    </actuator>
  </transmission>
  <gazebo reference="summit_xl_back_right_wheel">
    <mu1 value="1.0"/>
    <mu2 value="1.0"/>
    <kp value="10000000.0"/>
    <kd value="1.0"/>
    <fdir1 value="1 0 0"/>
    <turnGravityOff>false</turnGravityOff>
  </gazebo>
  <!-- SENSORS -->
  <!-- Hokuyo laser sensors can be parametized with min_angle and max_angle e.g: -->
  <!--xacro:sensor_hokuyo_utm30lx prefix="$(arg prefix)hokuyo_base" parent="$(arg prefix)base_link" min_angle="2.35" max_angle="-2.35"-->
  <!--xacro:sensor_hokuyo_utm30lx prefix="$(arg prefix)hokuyo_base" parent="$(arg prefix)base_link">
		<origin xyz="0.0 0.0 0.33" rpy="0 0 0"/>
	</xacro:sensor_hokuyo_utm30lx-->
  <joint name="summit_xl_laser_base_joint" type="fixed">
    <!-- FRONT MOUNT  -->
    <!--origin xyz="0.29 0 0.1" -->
    <!-- TOP MOUNT -->
    <!-- origin xyz="0.0 0.0 0.325"-->
    <origin rpy="0 0 0" xyz="0.24854 0 0.29190"/>
    <parent link="summit_xl_base_link"/>
    <child link="summit_xl_laser_base_link"/>
  </joint>
  <link name="summit_xl_laser_base_link">
    <visual>
      <origin rpy="0 0 0" xyz="0 0 -0.05"/>
      <geometry>
        <mesh filename="package://robotnik_sensors/meshes/hokuyo_urg_04lx.dae"/>
      </geometry>
    </visual>
    <inertial>
      <mass value="1e-5"/>
      <origin rpy="0 0 0" xyz="0 0 0"/>
      <inertia ixx="1e-6" ixy="0" ixz="0" iyy="1e-6" iyz="0" izz="1e-6"/>
    </inertial>
  </link>
  <link name="summit_xl_laser_link">
	</link>
  <joint name="summit_xl_laser_joint" type="fixed">
    <parent link="summit_xl_laser_base_link"/>
    <child link="summit_xl_laser_link"/>
    <origin rpy="0 0 0" xyz="0.00 0 0.05"/>
  </joint>
  <gazebo reference="summit_xl_laser_link">
    <sensor name="summit_xl_laser_sensor" type="ray">
      <pose>0 0 0 0 0 0</pose>
      <visualize>false</visualize>
      <update_rate>10</update_rate>
      <ray>
        <scan>
          <horizontal>
            <samples>640</samples>
            <resolution>1</resolution>
            <min_angle>-2.0943</min_angle>
            <max_angle>2.0943</max_angle>
          </horizontal>
        </scan>
        <range>
          <min>0.02</min>
          <max>4.0</max>
          <resolution>0.00628318531</resolution>
        </range>
        <noise>
          <type>gaussian</type>
          <mean>0.0</mean>
          <stddev>0.01</stddev>
        </noise>
      </ray>
      <plugin filename="libgazebo_ros_laser.so" name="summit_xl_laser_controller">
        <topicName>scan</topicName>
        <frameName>summit_xl_laser_link</frameName>
        <ignoreTfPrefix>1</ignoreTfPrefix>
      </plugin>
    </sensor>
  </gazebo>
  <joint name="summit_xl_structure_chasis_our_joint" type="fixed">
    <axis xyz="0 1 0"/>
    <origin rpy="0 0 0" xyz="0.0 0.0 0.0"/>
    <parent link="summit_xl_base_link"/>
    <child link="summit_xl_structure_chasis_our_link"/>
  </joint>
  <link name="summit_xl_structure_chasis_our_link">
    <inertial>
      <mass value="0.001"/>
      <origin rpy="0 0 0" xyz="0 0 0"/>
      <inertia ixx="0.0001" ixy="0" ixz="0" iyy="0.000001" iyz="0" izz="0.0001"/>
    </inertial>
    <visual>
      <origin rpy="0 0 0" xyz="0 0 0"/>
      <material name="alu_color">
        <color rgba="0.5 0.5 0.5 1"/>
      </material>
      <geometry>
        <mesh filename="package://summit_xl_description/meshes/structures/chasis_sup_our.stl"/>
      </geometry>
    </visual>
    <collision>
      <origin rpy="0 0 0" xyz="0 0 0"/>
      <geometry>
        <mesh filename="package://summit_xl_description/meshes/structures/chasis_sup_our.stl"/>
      </geometry>
    </collision>
  </link>
  <gazebo reference="summit_xl_structure_chasis_our_link">
    <material>Gazebo/White</material>
    <gravity>true</gravity>
  </gazebo>
  <!--
  <xacro:sensor_hokuyo_ust10lx prefix="$(arg prefix)hokuyo_base" parent="$(arg prefix)base_link">
		<origin xyz="0.0 0.0 0.33" rpy="0 0 0"/>
	</xacro:sensor_hokuyo_ust10lx>
-->
  <!--
	<xacro:sensor_axis prefix="$(arg prefix)camera" parent="$(arg prefix)base_link">
		<origin xyz="0.19 0 0.17" rpy="0 ${-75*PI/180} 0"/>
	</xacro:sensor_axis>
-->
  <joint name="summit_xl_imu_joint" type="fixed">
    <axis xyz="1 0 0"/>
    <!--origin xyz="0 0 0.2825"/-->
    <origin rpy="0 0 0" xyz="-0.18 0.0 0.170"/>
    <parent link="summit_xl_base_link"/>
    <child link="summit_xl_imu_link"/>
  </joint>
  <link name="summit_xl_imu_link">
    <inertial>
      <mass value="0.001"/>
      <origin rpy="0 0 0" xyz="0 0 0"/>
      <inertia ixx="0.0001" ixy="0" ixz="0" iyy="0.000001" iyz="0" izz="0.0001"/>
    </inertial>
    <visual>
      <origin rpy="0 0 0" xyz="0 0 0"/>
      <geometry>
        <box size="0.001 0.001 0.001"/>
      </geometry>
    </visual>
    <collision>
      <origin rpy="0 0 0" xyz="0 0 0"/>
      <geometry>
        <box size=".001 .001 .001"/>
      </geometry>
    </collision>
  </link>
  <gazebo>
    <plugin filename="libhector_gazebo_ros_imu.so" name="summit_xl_imu_controller">
      <alwaysOn>true</alwaysOn>
      <topicName>imu/data</topicName>
      <serviceName>summit_xl_imuimu/service</serviceName>
      <bodyName>summit_xl_imu_link</bodyName>
      <updateRate>50.0</updateRate>
      <gaussianNoise>0.005</gaussianNoise>
      <!-- orientation parameters -->
      <yawOffset>0.0</yawOffset>
      <!--<yawOffset>0.0</yawOffset>-->
      <yawDrift>0.02</yawDrift>
      <!--<yawDrift>0.0</yawDrift>-->
      <yawGaussianNoise>0.01</yawGaussianNoise>
      <!--<yawGaussianNoise>0.0004</yawGaussianNoise>-->
      <!-- angular velocities parameters -->
      <rateOffset>0.0 0.0 0.0</rateOffset>
      <rateDrift>0.002 0.002 0.002</rateDrift>
      <!--<rateDrift>0.0 0.0 0.0</rateDrift>-->
      <rateGaussianNoise>0.001 0.001 0.001</rateGaussianNoise>
      <!--<rateGaussianNoise>0.004 0.004 0.004</rateGaussianNoise>-->
      <!-- linear accelerations parameters -->
      <accelOffset>0.0 0.0 0.0</accelOffset>
      <accelDrift>0.005 0.005 0.005</accelDrift>
      <!--<accelDrift>0.0 0.0 0.0</accelDrift>-->
      <accelGaussianNoise>0.005 0.005 0.005</accelGaussianNoise>
      <!--<accelGaussianNoise>0.004 0.004 0.004</accelGaussianNoise>-->
      <ignoreTfPrefix>1</ignoreTfPrefix>
    </plugin>
  </gazebo>
  <!-- ANTENNA GPS -->
  <joint name="summit_xl_gps_joint" type="fixed">
    <axis xyz="0 1 0"/>
    <origin rpy="0 0 0" xyz="-0.22271 -0.14219 0.38959"/>
    <parent link="summit_xl_base_link"/>
    <child link="summit_xl_gps_base_link"/>
  </joint>
  <link name="summit_xl_gps_base_link">
    <inertial>
      <mass value="0.001"/>
      <origin rpy="0 0 0" xyz="0 0 0"/>
      <inertia ixx="0.0001" ixy="0" ixz="0" iyy="0.000001" iyz="0" izz="0.0001"/>
    </inertial>
    <visual>
      <origin rpy="0 0 0" xyz="0 0 0"/>
      <material name="gps_color">
        <color rgba="1 1 1 1"/>
      </material>
      <geometry>
        <mesh filename="package://robotnik_sensors/meshes/antenna_3GO16.stl" scale="1.0 1.0 1.0"/>
      </geometry>
    </visual>
    <collision>
      <origin rpy="0 0 0" xyz="0 0 0"/>
      <geometry>
        <mesh filename="package://robotnik_sensors/meshes/antenna_3GO16.stl" scale="1.0 1.0 1.0"/>
      </geometry>
    </collision>
  </link>
  <gazebo reference="summit_xl_gps_base_link">
    <material>Gazebo/White</material>
    <gravity>true</gravity>
  </gazebo>
  <gazebo>
    <plugin filename="libhector_gazebo_ros_gps.so" name="summit_xl_gps_controller">
      <alwaysOn>1</alwaysOn>
      <updateRate>5</updateRate>
      <bodyName>summit_xl_gps_base_link</bodyName>
      <!-- must be the link of the gps device, not the base_link or base_footprint -->
      <frameId>summit_xl_gps_base_link</frameId>
      <topicName>fix</topicName>
      <!-- Robotnik position at Fuente del Jarro -->
      <referenceLatitude>39.5080331</referenceLatitude>
      <referenceLongitude>-0.4619816</referenceLongitude>
      <!-- To set heading in ENU orientation (degrees) -->
      <referenceHeading>90</referenceHeading>
      <velocityTopicName>fix_velocity</velocityTopicName>
      <drift>0.0 0.0 0.0</drift>
      <!--<drift>0.0001 0.0001 0.0001</drift>-->
      <!--<drift>0.3 0.3 0.3</drift>-->
      <gaussianNoise>0.1 0.1 0.1</gaussianNoise>
      <!--<gaussianNoise>0.00001 0.00001 0.00001</gaussianNoise>-->
      <velocityDrift>0.00001 0.00001 0.00001</velocityDrift>
      <!--<velocityGaussianNoise>0.1 0.1 0.1</velocityGaussianNoise>-->
      <velocityGaussianNoise>0.00001 0.00001 0.00001</velocityGaussianNoise>
      <ignoreTfPrefix>1</ignoreTfPrefix>
    </plugin>
  </gazebo>
  <!--
	<xacro:sensor_asus_xtion_pro prefix="$(arg prefix)xtion" parent="$(arg prefix)base_link">
		<origin xyz="0.32992 0.02 0.17172" rpy="0 0 0"/>
	</xacro:sensor_asus_xtion_pro>
	
	<xacro:sensor_sick_tim571 prefix="$(arg prefix)sick_tim561" parent="$(arg prefix)base_link">
		<origin xyz="0.286 0 0.23082" rpy="0 0 0"/>
	</xacro:sensor_sick_tim571>
	
	<BB2-08S2C-38 frame="bumblebee2" name="bumblebee2" />


  <joint name="world_camera_joint" type="fixed">
    <origin xyz="0.38030 0 0.21982" rpy="0 0 0" />
    <parent link="base_link" />
    <child link="bumblebee2" />
  </joint>

-->
  <!--
	<xacro:sensor_kinect prefix="$(arg prefix)kinect" parent="$(arg prefix)base_link">
		<origin xyz="0.325 0.0 0.16" rpy="0 0 0"/> 
	</xacro:sensor_kinect>  
  
-->
  <!--
	<xacro:sensor_fotonic prefix="$(arg prefix)fotonic" parent="$(arg prefix)base_link">
		<origin xyz="0.3 0.0 0.24" rpy="0 0 0"/> 
	</xacro:sensor_fotonic>  
-->
</robot>

