<?xml version="1.0" ?>
<!-- =================================================================================== -->
<!-- |    This document was autogenerated by xacro from summit_xl_hls_omni.urdf.xacro  | -->
<!-- |    EDITING THIS FILE BY HAND IS NOT RECOMMENDED                                 | -->
<!-- =================================================================================== -->
<robot name="summit_xl" xmlns:xacro="http://ros.org/wiki/xacro">
  <!-- ***************** -->
  <!-- Imported elements -->
  <!-- ***************** -->
  <!-- First we import all posible elements defined in the urdf.xacro files. All these elements are defined as macro:xacros -->
  <!-- Import summit XL base elements -->
  <!-- ros control plugin -->
  <!-- skid steering plugin -->
  <gazebo reference="base_footprint">
    <material>Gazebo/Green</material>
  </gazebo>
  <!-- Import summit XL wheels -->
  <!-- Wheels -->
  <!-- in kg-->
  <!-- Import strucutres, holders -->
  <!-- Import pan-tilt unit -->
  <!-- xacro:property name="j2_lower_limit" value="-1.5708"/> 
  <xacro:property name="j2_upper_limit" value="1.5708"/-->
  <!-- Import all available sensors -->
  <!-- This file unifies all sensors that can be used on simulation, defined as xacro:macros -->
  <!-- Axis p5512 -->
  <!-- Axis m5013 -->
  <!-- Fotonic -->
  <!-- GPS -->
  <!-- Hokuyo urg04lx -->
  <!-- Hokuyo utm30lx -->
  <!-- Hokuyo ust10lx -->
  <!-- Imu -->
  <!-- Kinect -->
  <!-- Asus Xtion PRO -->
  <!-- Xacro properties -->
  <!-- Hokuyo 3d -->
  <!-- Sick s3000 -->
  <!-- KinectV2 -->
  <!-- ***************** -->
  <!-- Global parameters -->
  <!-- ***************** -->
  <!-- Wheel parameters -->
  <!-- x,y,z in translation from base_link to the center of the wheel -->
  <!-- Flag to select the high or low quality model -->
  <!-- *************** -->
  <!-- Robots Elements -->
  <!-- *************** -->
  <!-- Here we create the robot elements using the xacro:macros imported at the beggining of this file -->
  <!-- Summit XL base -->
  <!-- Robot mechanical and motor parameters -->
  <xacro:property name="PI" value="3.1415926535897931"/>
  <!-- xacro:property name="wheel_width" value="0.175" / -->
  <!-- BASE FOOTPRINT -->
  <link name="base_footprint">
    <visual>
      <origin rpy="0 0 0" xyz="0 0 0"/>
      <geometry>
        <box size="0.001 0.001 0.001"/>
      </geometry>
    </visual>
  </link>
  <joint name="base_footprint_joint" type="fixed">
    <origin rpy="0 0 0" xyz="0 0 0.127"/>
    <!-- ${wheel_radius} property must be defined inside wheel description -->
    <parent link="base_footprint"/>
    <child link="base_link"/>
  </joint>
  <!-- BASE_LINK -->
  <link name="base_link">
    <inertial>
      <mass value="25.0"/>
      <origin xyz="0 0 0"/>
      <inertia ixx="1.391" ixy="0.004" ixz="0.0" iyy="6.853" iyz="0.0" izz="6.125"/>
    </inertial>
    <visual>
      <origin rpy="0 0 0" xyz="0 0 0"/>
      <geometry>
        <mesh filename="package://summit_xl_description/meshes/bases/hls/summit_xl_hls.stl"/>
      </geometry>
      <material name="darkgrey">
        <color rgba="0.1 0.1 0.1 1"/>
      </material>
    </visual>
    <collision>
      <origin rpy="0 0 0 " xyz="0 0 0"/>
      <geometry>
        <mesh filename="package://summit_xl_description/meshes/bases/hls/summit_xl_hls.dae"/>
      </geometry>
    </collision>
  </link>
  <!-- Gazebo ros control pluggins -->
  <gazebo>
    <plugin filename="libgazebo_ros_control.so" name="ros_control">
      <robotNamespace>/summit_xl</robotNamespace>
      <robotParam>robot_description</robotParam>
      <controlPeriod>0.001</controlPeriod>
      <robotSimType>gazebo_ros_control/DefaultRobotHWSim</robotSimType>
    </plugin>
  </gazebo>
  <!-- Gazebo omni steering plugin -->
  <gazebo>
    <plugin filename="libgazebo_ros_planar_move.so" name="omni_steering">
      <commandTopic>/summit_xl_control/cmd_vel</commandTopic>
      <odometryTopic>/summit_xl/odom</odometryTopic>
      <odometryFrame>odom</odometryFrame>
      <odometryRate>20.0</odometryRate>
      <robotBaseFrame>base_footprint</robotBaseFrame>
    </plugin>
  </gazebo>
  <!-- HOLDERS, STRUCTURES -->
  <joint name="structure_hokuyo_front_joint" type="fixed">
    <axis xyz="0 1 0"/>
    <origin rpy="0 0 0" xyz="0.2225 -0.105 0.001"/>
    <parent link="base_link"/>
    <child link="structure_hokuyo_front_link"/>
  </joint>
  <link name="structure_hokuyo_front_link">
    <inertial>
      <mass value="0.001"/>
      <origin rpy="0 0 0" xyz="0 0 0"/>
      <inertia ixx="0.0001" ixy="0" ixz="0" iyy="0.000001" iyz="0" izz="0.0001"/>
    </inertial>
    <visual>
      <origin rpy="0 0 0" xyz="0 0 0"/>
      <material name="alu_color">
        <color rgba="0.5 0.5 0.5 1"/>
      </material>
      <geometry>
        <mesh filename="package://summit_xl_description/meshes/structures/structure_hokuyo.stl"/>
      </geometry>
    </visual>
    <collision>
      <origin rpy="0 0 0" xyz="0 0 0"/>
      <geometry>
        <mesh filename="package://summit_xl_description/meshes/structures/structure_hokuyo.dae"/>
      </geometry>
    </collision>
  </link>
  <gazebo reference="structure_hokuyo_front_link">
    <material>Gazebo/White</material>
    <gravity>true</gravity>
  </gazebo>
  <joint name="structure_hokuyo_rear_joint" type="fixed">
    <axis xyz="0 1 0"/>
    <origin rpy="0 0 3.1416" xyz="-0.2225 0.105 0.001"/>
    <parent link="base_link"/>
    <child link="structure_hokuyo_rear_link"/>
  </joint>
  <link name="structure_hokuyo_rear_link">
    <inertial>
      <mass value="0.001"/>
      <origin rpy="0 0 0" xyz="0 0 0"/>
      <inertia ixx="0.0001" ixy="0" ixz="0" iyy="0.000001" iyz="0" izz="0.0001"/>
    </inertial>
    <visual>
      <origin rpy="0 0 0" xyz="0 0 0"/>
      <material name="alu_color">
        <color rgba="0.5 0.5 0.5 1"/>
      </material>
      <geometry>
        <mesh filename="package://summit_xl_description/meshes/structures/structure_hokuyo.stl"/>
      </geometry>
    </visual>
    <collision>
      <origin rpy="0 0 0" xyz="0 0 0"/>
      <geometry>
        <mesh filename="package://summit_xl_description/meshes/structures/structure_hokuyo.dae"/>
      </geometry>
    </collision>
  </link>
  <gazebo reference="structure_hokuyo_rear_link">
    <material>Gazebo/White</material>
    <gravity>true</gravity>
  </gazebo>
  <joint name="structure_masts_joint" type="fixed">
    <axis xyz="0 1 0"/>
    <origin rpy="0 0 0" xyz="0.0 0.0 0.0"/>
    <parent link="base_link"/>
    <child link="structure_masts_link"/>
  </joint>
  <link name="structure_masts_link">
    <inertial>
      <mass value="0.001"/>
      <origin rpy="0 0 0" xyz="0 0 0"/>
      <inertia ixx="0.0001" ixy="0" ixz="0" iyy="0.000001" iyz="0" izz="0.0001"/>
    </inertial>
    <visual>
      <origin rpy="0 0 0" xyz="0 0 0"/>
      <material name="alu_color">
        <color rgba="0.5 0.5 0.5 1"/>
      </material>
      <geometry>
        <mesh filename="package://summit_xl_description/meshes/structures/masts_lh.dae"/>
      </geometry>
    </visual>
    <collision>
      <origin rpy="0 0 0" xyz="0 0 0"/>
      <geometry>
        <mesh filename="package://summit_xl_description/meshes/structures/masts_lh.dae"/>
      </geometry>
    </collision>
  </link>
  <gazebo reference="structure_masts_link">
    <material>Gazebo/White</material>
    <gravity>true</gravity>
  </gazebo>
  <!-- WHEELS -->
  <joint name="joint_front_right_wheel" type="continuous">
    <parent link="base_link"/>
    <child link="front_right_wheel"/>
    <origin rpy="0 0 0" xyz="0.2225 -0.2045 0.0"/>
    <axis rpy="0 0 0" xyz="0 1 0"/>
    <limit effort="100" velocity="100"/>
    <joint_properties damping="0.0" friction="0.0"/>
  </joint>
  <link name="front_right_wheel">
    <visual>
      <origin rpy="0 0 0" xyz="0 0 0"/>
      <geometry>
        <mesh filename="package://summit_xl_description/meshes/wheels/omni_wheel_2.dae"/>
      </geometry>
      			  
		  s
      <material name="darkgrey">
        <color rgba="0.2 0.2 0.2 1"/>
      </material>
    </visual>
    <collision>
      <origin rpy="1.57079632679 0 0" xyz="0 0 0"/>
      <geometry>
        <!--
          <sphere radius="${wheel_radius}" />
-->
        <!--
          <xacro:if value="${reflect}">
              <mesh filename="package://summit_xl_description/meshes/wheels/omni_wheel_1.dae" />
          </xacro:if>
          <xacro:unless value="${reflect}">
              <mesh filename="package://summit_xl_description/meshes/wheels/omni_wheel_2.dae" />
					</xacro:unless>
-->
        <cylinder length="0.087" radius="0.127"/>
      </geometry>
    </collision>
    <inertial>
      <mass value="6.5"/>
      <origin xyz="0 0 0"/>
      <inertia ixx="0.0303095" ixy="0" ixz="0" iyy="0.0303095" iyz="0" izz="0.05241925"/>
    </inertial>
  </link>
  <!-- Transmission is important to link the joints and the controller (see summit_xl_control/config/summit_xl_control.yaml)-->
  <transmission name="front_right_wheel_joint_trans">
    <type>transmission_interface/SimpleTransmission</type>
    <joint name="joint_front_right_wheel">
      <hardwareInterface>EffortJointInterface</hardwareInterface>
    </joint>
    <actuator name="front_right_wheel_joint_motor">
      <mechanicalReduction>1</mechanicalReduction>
    </actuator>
  </transmission>
  <gazebo reference="front_right_wheel">
    <mu1 value="1.0"/>
    <mu2 value="1.0"/>
    <kp value="10000000.0"/>
    <kd value="1.0"/>
    <fdir1 value="1 0 0"/>
    <turnGravityOff>false</turnGravityOff>
  </gazebo>
  <joint name="joint_front_left_wheel" type="continuous">
    <parent link="base_link"/>
    <child link="front_left_wheel"/>
    <origin rpy="0 0 0" xyz="0.2225 0.2045 0.0"/>
    <axis rpy="0 0 0" xyz="0 1 0"/>
    <limit effort="100" velocity="100"/>
    <joint_properties damping="0.0" friction="0.0"/>
  </joint>
  <link name="front_left_wheel">
    <visual>
      <origin rpy="0 0 0" xyz="0 0 0"/>
      <geometry>
        <mesh filename="package://summit_xl_description/meshes/wheels/omni_wheel_1.dae"/>
      </geometry>
      <material name="darkgrey">
        <color rgba="0.2 0.2 0.2 1"/>
      </material>
    </visual>
    <collision>
      <origin rpy="1.57079632679 0 0" xyz="0 0 0"/>
      <geometry>
        <!--
          <sphere radius="${wheel_radius}" />
-->
        <!--
          <xacro:if value="${reflect}">
              <mesh filename="package://summit_xl_description/meshes/wheels/omni_wheel_1.dae" />
          </xacro:if>
          <xacro:unless value="${reflect}">
              <mesh filename="package://summit_xl_description/meshes/wheels/omni_wheel_2.dae" />
					</xacro:unless>
-->
        <cylinder length="0.087" radius="0.127"/>
      </geometry>
    </collision>
    <inertial>
      <mass value="6.5"/>
      <origin xyz="0 0 0"/>
      <inertia ixx="0.0303095" ixy="0" ixz="0" iyy="0.0303095" iyz="0" izz="0.05241925"/>
    </inertial>
  </link>
  <!-- Transmission is important to link the joints and the controller (see summit_xl_control/config/summit_xl_control.yaml)-->
  <transmission name="front_left_wheel_joint_trans">
    <type>transmission_interface/SimpleTransmission</type>
    <joint name="joint_front_left_wheel">
      <hardwareInterface>EffortJointInterface</hardwareInterface>
    </joint>
    <actuator name="front_left_wheel_joint_motor">
      <mechanicalReduction>1</mechanicalReduction>
    </actuator>
  </transmission>
  <gazebo reference="front_left_wheel">
    <mu1 value="1.0"/>
    <mu2 value="1.0"/>
    <kp value="10000000.0"/>
    <kd value="1.0"/>
    <fdir1 value="1 0 0"/>
    <turnGravityOff>false</turnGravityOff>
  </gazebo>
  <joint name="joint_back_left_wheel" type="continuous">
    <parent link="base_link"/>
    <child link="back_left_wheel"/>
    <origin rpy="0 0 0" xyz="-0.2225 0.2045 0.0"/>
    <axis rpy="0 0 0" xyz="0 1 0"/>
    <limit effort="100" velocity="100"/>
    <joint_properties damping="0.0" friction="0.0"/>
  </joint>
  <link name="back_left_wheel">
    <visual>
      <origin rpy="0 0 0" xyz="0 0 0"/>
      <geometry>
        <mesh filename="package://summit_xl_description/meshes/wheels/omni_wheel_2.dae"/>
      </geometry>
      			  
		  s
      <material name="darkgrey">
        <color rgba="0.2 0.2 0.2 1"/>
      </material>
    </visual>
    <collision>
      <origin rpy="1.57079632679 0 0" xyz="0 0 0"/>
      <geometry>
        <!--
          <sphere radius="${wheel_radius}" />
-->
        <!--
          <xacro:if value="${reflect}">
              <mesh filename="package://summit_xl_description/meshes/wheels/omni_wheel_1.dae" />
          </xacro:if>
          <xacro:unless value="${reflect}">
              <mesh filename="package://summit_xl_description/meshes/wheels/omni_wheel_2.dae" />
					</xacro:unless>
-->
        <cylinder length="0.087" radius="0.127"/>
      </geometry>
    </collision>
    <inertial>
      <mass value="6.5"/>
      <origin xyz="0 0 0"/>
      <inertia ixx="0.0303095" ixy="0" ixz="0" iyy="0.0303095" iyz="0" izz="0.05241925"/>
    </inertial>
  </link>
  <!-- Transmission is important to link the joints and the controller (see summit_xl_control/config/summit_xl_control.yaml)-->
  <transmission name="back_left_wheel_joint_trans">
    <type>transmission_interface/SimpleTransmission</type>
    <joint name="joint_back_left_wheel">
      <hardwareInterface>EffortJointInterface</hardwareInterface>
    </joint>
    <actuator name="back_left_wheel_joint_motor">
      <mechanicalReduction>1</mechanicalReduction>
    </actuator>
  </transmission>
  <gazebo reference="back_left_wheel">
    <mu1 value="1.0"/>
    <mu2 value="1.0"/>
    <kp value="10000000.0"/>
    <kd value="1.0"/>
    <fdir1 value="1 0 0"/>
    <turnGravityOff>false</turnGravityOff>
  </gazebo>
  <joint name="joint_back_right_wheel" type="continuous">
    <parent link="base_link"/>
    <child link="back_right_wheel"/>
    <origin rpy="0 0 0" xyz="-0.2225 -0.2045 0.0"/>
    <axis rpy="0 0 0" xyz="0 1 0"/>
    <limit effort="100" velocity="100"/>
    <joint_properties damping="0.0" friction="0.0"/>
  </joint>
  <link name="back_right_wheel">
    <visual>
      <origin rpy="0 0 0" xyz="0 0 0"/>
      <geometry>
        <mesh filename="package://summit_xl_description/meshes/wheels/omni_wheel_1.dae"/>
      </geometry>
      <material name="darkgrey">
        <color rgba="0.2 0.2 0.2 1"/>
      </material>
    </visual>
    <collision>
      <origin rpy="1.57079632679 0 0" xyz="0 0 0"/>
      <geometry>
        <!--
          <sphere radius="${wheel_radius}" />
-->
        <!--
          <xacro:if value="${reflect}">
              <mesh filename="package://summit_xl_description/meshes/wheels/omni_wheel_1.dae" />
          </xacro:if>
          <xacro:unless value="${reflect}">
              <mesh filename="package://summit_xl_description/meshes/wheels/omni_wheel_2.dae" />
					</xacro:unless>
-->
        <cylinder length="0.087" radius="0.127"/>
      </geometry>
    </collision>
    <inertial>
      <mass value="6.5"/>
      <origin xyz="0 0 0"/>
      <inertia ixx="0.0303095" ixy="0" ixz="0" iyy="0.0303095" iyz="0" izz="0.05241925"/>
    </inertial>
  </link>
  <!-- Transmission is important to link the joints and the controller (see summit_xl_control/config/summit_xl_control.yaml)-->
  <transmission name="back_right_wheel_joint_trans">
    <type>transmission_interface/SimpleTransmission</type>
    <joint name="joint_back_right_wheel">
      <hardwareInterface>EffortJointInterface</hardwareInterface>
    </joint>
    <actuator name="back_right_wheel_joint_motor">
      <mechanicalReduction>1</mechanicalReduction>
    </actuator>
  </transmission>
  <gazebo reference="back_right_wheel">
    <mu1 value="1.0"/>
    <mu2 value="1.0"/>
    <kp value="10000000.0"/>
    <kd value="1.0"/>
    <fdir1 value="1 0 0"/>
    <turnGravityOff>false</turnGravityOff>
  </gazebo>
  <!-- SENSORS -->
  <!-- xacro:sensor_hokuyo_ust10lx name="hokuyo_front" parent="base_link">
		<origin xyz="0.403 -0.256 0.045" rpy="3.1416 0 -0.7854"/>
	</xacro:sensor_hokuyo_ust10lx -->
  <joint name="hokuyo_rear_laser_joint" type="fixed">
    <origin rpy="3.1416 0 2.3562" xyz="-0.403 0.256 -0.045"/>
    <parent link="base_link"/>
    <child link="hokuyo_rear_laser_link"/>
  </joint>
  <link name="hokuyo_rear_laser_link">
    <collision>
      <origin rpy="0 0 0" xyz="0 0 -0.05"/>
      <geometry>
        <box size="0.010 0.010 0.010"/>
      </geometry>
    </collision>
    <visual>
      <origin rpy="0 0 0" xyz="0 0 -0.05"/>
      <geometry>
        <mesh filename="package://robotnik_sensors/meshes/hokuyo_ust_10lx.dae"/>
      </geometry>
    </visual>
    <inertial>
      <mass value="1e-5"/>
      <origin rpy="0 0 0" xyz="0 0 0"/>
      <inertia ixx="1e-6" ixy="0" ixz="0" iyy="1e-6" iyz="0" izz="1e-6"/>
    </inertial>
  </link>
  <!-- Hokuyo sensor for simulation -->
  <gazebo reference="hokuyo_rear_laser_link">
    <sensor name="hokuyo_rear_sensor" type="ray">
      <pose>0 0 0 0 0 0</pose>
      <visualize>false</visualize>
      <update_rate>40</update_rate>
      <ray>
        <scan>
          <horizontal>
            <samples>1081</samples>
            <resolution>1</resolution>
            <min_angle>2.3562</min_angle>
            <max_angle>-2.3562</max_angle>
          </horizontal>
        </scan>
        <range>
          <min>0.06</min>
          <max>20.0</max>
          <!-- resolution>0.004363323</resolution -->
          <resolution>0.004359297</resolution>
          <!-- resolution>0.001</resolution -->
        </range>
        <noise>
          <type>gaussian</type>
          <mean>0.0</mean>
          <stddev>0.01</stddev>
        </noise>
      </ray>
      <plugin filename="libgazebo_ros_laser.so" name="gazebo_ros_head_hokuyo_controller">
        <topicName>hokuyo_rear/scan</topicName>
        <frameName>hokuyo_rear_laser_link</frameName>
      </plugin>
    </sensor>
  </gazebo>
  <joint name="hokuyo_front_laser_joint" type="fixed">
    <origin rpy="3.1416 0 -0.7854" xyz="0.403 -0.256 -0.045"/>
    <parent link="base_link"/>
    <child link="hokuyo_front_laser_link"/>
  </joint>
  <link name="hokuyo_front_laser_link">
    <collision>
      <origin rpy="0 0 0" xyz="0 0 -0.05"/>
      <geometry>
        <box size="0.010 0.010 0.010"/>
      </geometry>
    </collision>
    <visual>
      <origin rpy="0 0 0" xyz="0 0 -0.05"/>
      <geometry>
        <mesh filename="package://robotnik_sensors/meshes/hokuyo_ust_10lx.dae"/>
      </geometry>
    </visual>
    <inertial>
      <mass value="1e-5"/>
      <origin rpy="0 0 0" xyz="0 0 0"/>
      <inertia ixx="1e-6" ixy="0" ixz="0" iyy="1e-6" iyz="0" izz="1e-6"/>
    </inertial>
  </link>
  <!-- Hokuyo sensor for simulation -->
  <gazebo reference="hokuyo_front_laser_link">
    <sensor name="hokuyo_front_sensor" type="ray">
      <pose>0 0 0 0 0 0</pose>
      <visualize>false</visualize>
      <update_rate>40</update_rate>
      <ray>
        <scan>
          <horizontal>
            <samples>1081</samples>
            <resolution>1</resolution>
            <min_angle>2.3562</min_angle>
            <max_angle>-2.3562</max_angle>
          </horizontal>
        </scan>
        <range>
          <min>0.06</min>
          <max>20.0</max>
          <!-- resolution>0.004363323</resolution -->
          <resolution>0.004359297</resolution>
          <!-- resolution>0.001</resolution -->
        </range>
        <noise>
          <type>gaussian</type>
          <mean>0.0</mean>
          <stddev>0.01</stddev>
        </noise>
      </ray>
      <plugin filename="libgazebo_ros_laser.so" name="gazebo_ros_head_hokuyo_controller">
        <topicName>hokuyo_front/scan</topicName>
        <frameName>hokuyo_front_laser_link</frameName>
      </plugin>
    </sensor>
  </gazebo>
  <joint name="camera_front_joint" type="fixed">
    <axis xyz="0 1 0"/>
    <!--
	      <origin xyz="0.180 0.0 0.270"/>
-->
    <origin rpy="0 0 0" xyz="0.370 -0.234 0.148"/>
    <parent link="base_link"/>
    <child link="camera_front_link"/>
  </joint>
  <link name="camera_front_link">
    <inertial>
      <origin rpy="0 0 0" xyz="0 0 0"/>
      <mass value="0.1"/>
      <origin rpy="0 0 0" xyz="0 0 0"/>
      <inertia ixx="0.1" ixy="0" ixz="0" iyy="0.1" iyz="0" izz="0.1"/>
    </inertial>
    <visual>
      <origin rpy="0 0 0" xyz="0 0 0"/>
      <!-- to center the axis model -->
      <material name="axis_color">
        <color rgba="0.1 0.1 0.1 1"/>
      </material>
      <geometry>
        <mesh filename="package://robotnik_sensors/meshes/axis_m5013.dae" scale="1.0 1.0 1.0"/>
      </geometry>
    </visual>
    <collision>
      <origin rpy="0 0 0" xyz="0.0 0.0 0"/>
      <geometry>
        <mesh filename="package://robotnik_sensors/meshes/axis_m5013.stl" scale="1.0 1.0 1.0"/>
      </geometry>
    </collision>
  </link>
  <joint name="joint_camera_front_pan" type="continuous">
    <axis xyz="0 0 1"/>
    <origin xyz="0.0 0.0 0.1"/>
    <parent link="camera_front_link"/>
    <child link="camera_front_pan_link"/>
    <limit effort="100.0" lower="-3.1416" upper="3.1416" velocity="100.0"/>
    <joint_properties damping="0.1" friction="{ptz_joint_friction}"/>
  </joint>
  <link name="camera_front_pan_link">
    <inertial>
      <mass value="0.1"/>
      <origin rpy="0 0 0" xyz="0 0 0"/>
      <inertia ixx="0.1" ixy="0" ixz="0" iyy="0.1" iyz="0" izz="0.1"/>
    </inertial>
  </link>
  <transmission name="camera_front_pan_trans">
    <type>transmission_interface/SimpleTransmission</type>
    <joint name="joint_camera_front_pan">
      <hardwareInterface>EffortJointInterface</hardwareInterface>
    </joint>
    <actuator name="pan_motor">
      <hardwareInterface>EffortJointInterface</hardwareInterface>
      <mechanicalReduction>1.0</mechanicalReduction>
    </actuator>
  </transmission>
  <joint name="joint_camera_front_tilt" type="continuous">
    <axis xyz="0 1 0"/>
    <origin xyz="0.0 0.0 0.0"/>
    <parent link="camera_front_pan_link"/>
    <child link="camera_front_tilt_link"/>
    <limit effort="100.0" lower="-1.5708" upper="1.5708" velocity="100.0"/>
    <joint_properties damping="0.1" friction="{ptz_joint_friction}"/>
  </joint>
  <link name="camera_front_tilt_link">
    <inertial>
      <mass value="0.1"/>
      <origin rpy="0 0 0" xyz="0 0 0"/>
      <inertia ixx="0.1" ixy="0" ixz="0" iyy="0.1" iyz="0" izz="0.1"/>
    </inertial>
  </link>
  <transmission name="camera_front_tilt_trans">
    <type>transmission_interface/SimpleTransmission</type>
    <joint name="joint_camera_front_tilt">
      <hardwareInterface>EffortJointInterface</hardwareInterface>
    </joint>
    <actuator name="tilt_motor">
      <hardwareInterface>EffortJointInterface</hardwareInterface>
      <mechanicalReduction>1.0</mechanicalReduction>
    </actuator>
  </transmission>
  <!-- Optical frame -->
  <joint name="camera_front_depth_optical_joint" type="fixed">
    <origin rpy="-1.57079632679 0 -1.57079632679" xyz="0 0 0"/>
    <parent link="camera_front_link"/>
    <child link="camera_front_depth_optical_frame"/>
  </joint>
  <link name="camera_front_depth_optical_frame">
    <inertial>
      <mass value="0.001"/>
      <origin xyz="0 0 0"/>
      <inertia ixx="0.0001" ixy="0.0" ixz="0.0" iyy="0.0001" iyz="0.0" izz="0.0001"/>
    </inertial>
  </link>
  <gazebo reference="camera_front_link">
    <material>Gazebo/FlatBlack</material>
  </gazebo>
  <!-- Axis sensor for simulation -->
  <gazebo reference="camera_front_tilt_link">
    <sensor name="camera1" type="camera">
      <update_rate>30.0</update_rate>
      <camera name="head">
        <horizontal_fov>1.0471975512</horizontal_fov>
        <image>
          <format>R8G8B8</format>
          <width>640</width>
          <height>480</height>
        </image>
        <clip>
          <near>0.05</near>
          <far>8.0</far>
        </clip>
      </camera>
      <plugin filename="libgazebo_ros_camera.so" name="camera_controller">
        <alwaysOn>true</alwaysOn>
        <updateRate>0.0</updateRate>
        <cameraName>camera_front</cameraName>
        <imageTopicName>image_raw</imageTopicName>
        <cameraInfoTopicName>camera_info</cameraInfoTopicName>
        <frameName>camera_front_depth_optical_frame</frameName>
        <hackBaseline>0.07</hackBaseline>
        <distortionK1>0.0</distortionK1>
        <distortionK2>0.0</distortionK2>
        <distortionK3>0.0</distortionK3>
        <distortionT1>0.0</distortionT1>
        <distortionT2>0.0</distortionT2>
      </plugin>
    </sensor>
  </gazebo>
  <joint name="camera_rear_joint" type="fixed">
    <axis xyz="0 1 0"/>
    <!--
	      <origin xyz="0.180 0.0 0.270"/>
-->
    <origin rpy="0 0 3.1416" xyz="-0.370 0.234 0.148"/>
    <parent link="base_link"/>
    <child link="camera_rear_link"/>
  </joint>
  <link name="camera_rear_link">
    <inertial>
      <origin rpy="0 0 0" xyz="0 0 0"/>
      <mass value="0.1"/>
      <origin rpy="0 0 0" xyz="0 0 0"/>
      <inertia ixx="0.1" ixy="0" ixz="0" iyy="0.1" iyz="0" izz="0.1"/>
    </inertial>
    <visual>
      <origin rpy="0 0 0" xyz="0 0 0"/>
      <!-- to center the axis model -->
      <material name="axis_color">
        <color rgba="0.1 0.1 0.1 1"/>
      </material>
      <geometry>
        <mesh filename="package://robotnik_sensors/meshes/axis_m5013.dae" scale="1.0 1.0 1.0"/>
      </geometry>
    </visual>
    <collision>
      <origin rpy="0 0 0" xyz="0.0 0.0 0"/>
      <geometry>
        <mesh filename="package://robotnik_sensors/meshes/axis_m5013.stl" scale="1.0 1.0 1.0"/>
      </geometry>
    </collision>
  </link>
  <joint name="joint_camera_rear_pan" type="continuous">
    <axis xyz="0 0 1"/>
    <origin xyz="0.0 0.0 0.1"/>
    <parent link="camera_rear_link"/>
    <child link="camera_rear_pan_link"/>
    <limit effort="100.0" lower="-3.1416" upper="3.1416" velocity="100.0"/>
    <joint_properties damping="0.1" friction="{ptz_joint_friction}"/>
  </joint>
  <link name="camera_rear_pan_link">
    <inertial>
      <mass value="0.1"/>
      <origin rpy="0 0 0" xyz="0 0 0"/>
      <inertia ixx="0.1" ixy="0" ixz="0" iyy="0.1" iyz="0" izz="0.1"/>
    </inertial>
  </link>
  <transmission name="camera_rear_pan_trans">
    <type>transmission_interface/SimpleTransmission</type>
    <joint name="joint_camera_rear_pan">
      <hardwareInterface>EffortJointInterface</hardwareInterface>
    </joint>
    <actuator name="pan_motor">
      <hardwareInterface>EffortJointInterface</hardwareInterface>
      <mechanicalReduction>1.0</mechanicalReduction>
    </actuator>
  </transmission>
  <joint name="joint_camera_rear_tilt" type="continuous">
    <axis xyz="0 1 0"/>
    <origin xyz="0.0 0.0 0.0"/>
    <parent link="camera_rear_pan_link"/>
    <child link="camera_rear_tilt_link"/>
    <limit effort="100.0" lower="-1.5708" upper="1.5708" velocity="100.0"/>
    <joint_properties damping="0.1" friction="{ptz_joint_friction}"/>
  </joint>
  <link name="camera_rear_tilt_link">
    <inertial>
      <mass value="0.1"/>
      <origin rpy="0 0 0" xyz="0 0 0"/>
      <inertia ixx="0.1" ixy="0" ixz="0" iyy="0.1" iyz="0" izz="0.1"/>
    </inertial>
  </link>
  <transmission name="camera_rear_tilt_trans">
    <type>transmission_interface/SimpleTransmission</type>
    <joint name="joint_camera_rear_tilt">
      <hardwareInterface>EffortJointInterface</hardwareInterface>
    </joint>
    <actuator name="tilt_motor">
      <hardwareInterface>EffortJointInterface</hardwareInterface>
      <mechanicalReduction>1.0</mechanicalReduction>
    </actuator>
  </transmission>
  <!-- Optical frame -->
  <joint name="camera_rear_depth_optical_joint" type="fixed">
    <origin rpy="-1.57079632679 0 -1.57079632679" xyz="0 0 0"/>
    <parent link="camera_rear_link"/>
    <child link="camera_rear_depth_optical_frame"/>
  </joint>
  <link name="camera_rear_depth_optical_frame">
    <inertial>
      <mass value="0.001"/>
      <origin xyz="0 0 0"/>
      <inertia ixx="0.0001" ixy="0.0" ixz="0.0" iyy="0.0001" iyz="0.0" izz="0.0001"/>
    </inertial>
  </link>
  <gazebo reference="camera_rear_link">
    <material>Gazebo/FlatBlack</material>
  </gazebo>
  <!-- Axis sensor for simulation -->
  <gazebo reference="camera_rear_tilt_link">
    <sensor name="camera1" type="camera">
      <update_rate>30.0</update_rate>
      <camera name="head">
        <horizontal_fov>1.0471975512</horizontal_fov>
        <image>
          <format>R8G8B8</format>
          <width>640</width>
          <height>480</height>
        </image>
        <clip>
          <near>0.05</near>
          <far>8.0</far>
        </clip>
      </camera>
      <plugin filename="libgazebo_ros_camera.so" name="camera_controller">
        <alwaysOn>true</alwaysOn>
        <updateRate>0.0</updateRate>
        <cameraName>camera_rear</cameraName>
        <imageTopicName>image_raw</imageTopicName>
        <cameraInfoTopicName>camera_info</cameraInfoTopicName>
        <frameName>camera_rear_depth_optical_frame</frameName>
        <hackBaseline>0.07</hackBaseline>
        <distortionK1>0.0</distortionK1>
        <distortionK2>0.0</distortionK2>
        <distortionK3>0.0</distortionK3>
        <distortionT1>0.0</distortionT1>
        <distortionT2>0.0</distortionT2>
      </plugin>
    </sensor>
  </gazebo>
  <joint name="imu_joint" type="fixed">
    <axis xyz="1 0 0"/>
    <!--origin xyz="0 0 0.2825"/-->
    <origin rpy="0 0 0" xyz="-0.18 0.0 0.170"/>
    <parent link="base_link"/>
    <child link="imu_link"/>
  </joint>
  <link name="imu_link">
    <inertial>
      <mass value="0.001"/>
      <origin rpy="0 0 0" xyz="0 0 0"/>
      <inertia ixx="0.0001" ixy="0" ixz="0" iyy="0.000001" iyz="0" izz="0.0001"/>
    </inertial>
    <visual>
      <origin rpy="0 0 0" xyz="0 0 0"/>
      <geometry>
        <box size="0.001 0.001 0.001"/>
      </geometry>
    </visual>
    <collision>
      <origin rpy="0 0 0" xyz="0 0 0"/>
      <geometry>
        <box size=".001 .001 .001"/>
      </geometry>
    </collision>
  </link>
  <gazebo>
    <plugin filename="libgazebo_ros_imu.so" name="ros_imu">
      <topicName>imu_data</topicName>
      <bodyName>imu_link</bodyName>
      <serviceName>imu_service</serviceName>
      <gaussianNoise>0.005</gaussianNoise>
    </plugin>
  </gazebo>
  <!-- PAN TILT UNITS -->
  <!-- BASE LINK -->
  <!-- base_link -->
  <link name="ptu1_link_base">
    <inertial>
      <mass value="0.050"/>
      <origin xyz="0 0 0"/>
      <inertia ixx="0.0001" ixy="0.0" ixz="0.0" iyx="0.0" iyy="0.0001" iyz="0.0" izz="0.0001"/>
    </inertial>
    <visual>
      <origin rpy="0 0 0" xyz="0 0 0"/>
      <geometry>
        <mesh filename="package://summit_xl_description/meshes/pan_tilt/base_pan_tilt.dae"/>
      </geometry>
      <material name="carbon_fiber">
        <color rgba="0.792156862745098 0.819607843137255 0.933333333333333 1"/>
      </material>
    </visual>
    <collision>
      <origin rpy="0 0 0 " xyz="0 0 0"/>
      <geometry>
        <mesh filename="package://summit_xl_description/meshes/pan_tilt/base_pan_tilt.dae"/>
      </geometry>
    </collision>
  </link>
  <joint name="joint_ptu1_base" type="fixed">
    <origin rpy="0 0 0" xyz="0.438 0.113 0.675"/>
    <parent link="base_link"/>
    <child link="ptu1_link_base"/>
    <origin rpy="0 0 0" xyz="0.0 0 0.0"/>
  </joint>
  <!-- LINK S1 Fixed -->
  <link name="ptu1_link_s1">
    <inertial>
      <mass value="0.050"/>
      <origin xyz="0 0 0"/>
      <inertia ixx="0.0001" ixy="0.0" ixz="0.0" iyx="0.0" iyy="0.0001" iyz="0.0" izz="0.0001"/>
    </inertial>
    <visual>
      <origin rpy="0 0 0" xyz="0 0 0"/>
      <geometry>
        <mesh filename="package://summit_xl_description/meshes/pan_tilt/rx-28.dae"/>
      </geometry>
      <material name="carbon_fiber">
        <color rgba="0.792156862745098 0.819607843137255 0.933333333333333 1"/>
      </material>
    </visual>
    <collision>
      <origin rpy="0 0 0 " xyz="0 0 0"/>
      <geometry>
        <mesh filename="package://summit_xl_description/meshes/pan_tilt/rx-28.dae"/>
      </geometry>
    </collision>
  </link>
  <joint name="joint_ptu1_s1" type="fixed">
    <parent link="ptu1_link_base"/>
    <child link="ptu1_link_s1"/>
    <origin rpy="0 0 0" xyz="0.013 0 0.027"/>
  </joint>
  <link name="ptu1_link_1">
    <inertial>
      <mass value="0.050"/>
      <origin xyz="0 0 0"/>
      <inertia ixx="0.0001" ixy="0.0" ixz="0.0" iyx="0.0" iyy="0.0001" iyz="0.0" izz="0.0001"/>
    </inertial>
    <visual>
      <origin rpy="0 0 0" xyz="0 0 0"/>
      <geometry>
        <mesh filename="package://summit_xl_description/meshes/pan_tilt/fr07-s101.dae"/>
      </geometry>
      <material name="aluminium">
        <color rgba="0.678431373 0.698039216 0.741176471 1"/>
      </material>
    </visual>
    <collision>
      <origin rpy="0 0 0 " xyz="0 0 0"/>
      <geometry>
        <mesh filename="package://summit_xl_description/meshes/pan_tilt/fr07-s101.dae"/>
      </geometry>
    </collision>
  </link>
  <joint name="ptu1_joint_1" type="revolute">
    <origin rpy="0.0 0.0 0.0" xyz="0.013 0 0.048"/>
    <parent link="ptu1_link_base"/>
    <child link="ptu1_link_1"/>
    <axis xyz="0 0 1"/>
    <limit effort="2.0" lower="-3.13" upper="3.13" velocity="2.9217"/>
    <dynamics damping="0.7" friction="0.5"/>
  </joint>
  <transmission name="j1_trans">
    <type>transmission_interface/SimpleTransmission</type>
    <joint name="ptu1_joint_1">
      <!-- hardwareInterface>EffortJointInterface</hardwareInterface -->
      <hardwareInterface>PositionJointInterface</hardwareInterface>
    </joint>
    <actuator name="j1_motor">
      <hardwareInterface>EffortJointInterface</hardwareInterface>
      <mechanicalReduction>1.0</mechanicalReduction>
      <motorTorqueConstant>50.0</motorTorqueConstant>
    </actuator>
  </transmission>
  <!-- LINK S2 Fixed -->
  <link name="ptu1_link_s2">
    <inertial>
      <mass value="0.050"/>
      <origin xyz="0 0 0"/>
      <inertia ixx="0.0001" ixy="0.0" ixz="0.0" iyx="0.0" iyy="0.0001" iyz="0.0" izz="0.0001"/>
    </inertial>
    <visual>
      <origin rpy="0 0 0" xyz="0 0 0"/>
      <geometry>
        <mesh filename="package://summit_xl_description/meshes/pan_tilt/rx-28.dae"/>
      </geometry>
      <material name="carbon_fiber">
        <color rgba="0.792156862745098 0.819607843137255 0.933333333333333 1"/>
      </material>
    </visual>
    <collision>
      <origin rpy="0 0 0 " xyz="0 0 0"/>
      <geometry>
        <mesh filename="package://summit_xl_description/meshes/pan_tilt/rx-28.dae"/>
      </geometry>
    </collision>
  </link>
  <joint name="joint_ptu1_s2" type="fixed">
    <parent link="ptu1_link_1"/>
    <child link="ptu1_link_s2"/>
    <origin rpy="0 -1.5708 1.5708" xyz="0 0 0.042"/>
  </joint>
  <link name="ptu1_link_2">
    <inertial>
      <mass value="0.050"/>
      <origin xyz="0 0 0"/>
      <inertia ixx="0.0001" ixy="0.0" ixz="0.0" iyx="0.0" iyy="0.0001" iyz="0.0" izz="0.0001"/>
    </inertial>
    <visual>
      <origin rpy="0 0 0" xyz="0 0 0"/>
      <geometry>
        <mesh filename="package://summit_xl_description/meshes/pan_tilt/fr07-h101.dae"/>
      </geometry>
      <material name="aluminium">
        <color rgba="0.678431373 0.698039216 0.741176471 1"/>
      </material>
    </visual>
    <collision>
      <origin rpy="0 0 0 " xyz="0 0 0"/>
      <geometry>
        <mesh filename="package://summit_xl_description/meshes/pan_tilt/fr07-h101.dae"/>
      </geometry>
    </collision>
  </link>
  <joint name="ptu1_joint_2" type="revolute">
    <origin rpy="0.0 0.0 0.0" xyz="0.0 0 0.042"/>
    <parent link="ptu1_link_1"/>
    <child link="ptu1_link_2"/>
    <axis xyz="0 -1 0"/>
    <limit effort="2.0" lower="-1.6" upper="1.6" velocity="2.9217"/>
    <dynamics damping="0.7" friction="0.5"/>
  </joint>
  <transmission name="j2_trans">
    <type>transmission_interface/SimpleTransmission</type>
    <joint name="ptu1_joint_2">
      <!-- hardwareInterface>EffortJointInterface</hardwareInterface -->
      <hardwareInterface>PositionJointInterface</hardwareInterface>
    </joint>
    <actuator name="j2_motor">
      <hardwareInterface>EffortJointInterface</hardwareInterface>
      <mechanicalReduction>1.0</mechanicalReduction>
      <motorTorqueConstant>50.0</motorTorqueConstant>
    </actuator>
  </transmission>
  <!-- BASE LINK -->
  <!-- base_link -->
  <link name="ptu2_link_base">
    <inertial>
      <mass value="0.050"/>
      <origin xyz="0 0 0"/>
      <inertia ixx="0.0001" ixy="0.0" ixz="0.0" iyx="0.0" iyy="0.0001" iyz="0.0" izz="0.0001"/>
    </inertial>
    <visual>
      <origin rpy="0 0 0" xyz="0 0 0"/>
      <geometry>
        <mesh filename="package://summit_xl_description/meshes/pan_tilt/base_pan_tilt.dae"/>
      </geometry>
      <material name="carbon_fiber">
        <color rgba="0.792156862745098 0.819607843137255 0.933333333333333 1"/>
      </material>
    </visual>
    <collision>
      <origin rpy="0 0 0 " xyz="0 0 0"/>
      <geometry>
        <mesh filename="package://summit_xl_description/meshes/pan_tilt/base_pan_tilt.dae"/>
      </geometry>
    </collision>
  </link>
  <joint name="joint_ptu2_base" type="fixed">
    <origin rpy="0 0 0" xyz="0.438 -0.117 1.375"/>
    <parent link="base_link"/>
    <child link="ptu2_link_base"/>
    <origin rpy="0 0 0" xyz="0.0 0 0.0"/>
  </joint>
  <!-- LINK S1 Fixed -->
  <link name="ptu2_link_s1">
    <inertial>
      <mass value="0.050"/>
      <origin xyz="0 0 0"/>
      <inertia ixx="0.0001" ixy="0.0" ixz="0.0" iyx="0.0" iyy="0.0001" iyz="0.0" izz="0.0001"/>
    </inertial>
    <visual>
      <origin rpy="0 0 0" xyz="0 0 0"/>
      <geometry>
        <mesh filename="package://summit_xl_description/meshes/pan_tilt/rx-28.dae"/>
      </geometry>
      <material name="carbon_fiber">
        <color rgba="0.792156862745098 0.819607843137255 0.933333333333333 1"/>
      </material>
    </visual>
    <collision>
      <origin rpy="0 0 0 " xyz="0 0 0"/>
      <geometry>
        <mesh filename="package://summit_xl_description/meshes/pan_tilt/rx-28.dae"/>
      </geometry>
    </collision>
  </link>
  <joint name="joint_ptu2_s1" type="fixed">
    <parent link="ptu2_link_base"/>
    <child link="ptu2_link_s1"/>
    <origin rpy="0 0 0" xyz="0.013 0 0.027"/>
  </joint>
  <link name="ptu2_link_1">
    <inertial>
      <mass value="0.050"/>
      <origin xyz="0 0 0"/>
      <inertia ixx="0.0001" ixy="0.0" ixz="0.0" iyx="0.0" iyy="0.0001" iyz="0.0" izz="0.0001"/>
    </inertial>
    <visual>
      <origin rpy="0 0 0" xyz="0 0 0"/>
      <geometry>
        <mesh filename="package://summit_xl_description/meshes/pan_tilt/fr07-s101.dae"/>
      </geometry>
      <material name="aluminium">
        <color rgba="0.678431373 0.698039216 0.741176471 1"/>
      </material>
    </visual>
    <collision>
      <origin rpy="0 0 0 " xyz="0 0 0"/>
      <geometry>
        <mesh filename="package://summit_xl_description/meshes/pan_tilt/fr07-s101.dae"/>
      </geometry>
    </collision>
  </link>
  <joint name="ptu2_joint_1" type="revolute">
    <origin rpy="0.0 0.0 0.0" xyz="0.013 0 0.048"/>
    <parent link="ptu2_link_base"/>
    <child link="ptu2_link_1"/>
    <axis xyz="0 0 1"/>
    <limit effort="2.0" lower="-3.13" upper="3.13" velocity="2.9217"/>
    <dynamics damping="0.7" friction="0.5"/>
  </joint>
  <transmission name="j1_trans">
    <type>transmission_interface/SimpleTransmission</type>
    <joint name="ptu2_joint_1">
      <!-- hardwareInterface>EffortJointInterface</hardwareInterface -->
      <hardwareInterface>PositionJointInterface</hardwareInterface>
    </joint>
    <actuator name="j1_motor">
      <hardwareInterface>EffortJointInterface</hardwareInterface>
      <mechanicalReduction>1.0</mechanicalReduction>
      <motorTorqueConstant>50.0</motorTorqueConstant>
    </actuator>
  </transmission>
  <!-- LINK S2 Fixed -->
  <link name="ptu2_link_s2">
    <inertial>
      <mass value="0.050"/>
      <origin xyz="0 0 0"/>
      <inertia ixx="0.0001" ixy="0.0" ixz="0.0" iyx="0.0" iyy="0.0001" iyz="0.0" izz="0.0001"/>
    </inertial>
    <visual>
      <origin rpy="0 0 0" xyz="0 0 0"/>
      <geometry>
        <mesh filename="package://summit_xl_description/meshes/pan_tilt/rx-28.dae"/>
      </geometry>
      <material name="carbon_fiber">
        <color rgba="0.792156862745098 0.819607843137255 0.933333333333333 1"/>
      </material>
    </visual>
    <collision>
      <origin rpy="0 0 0 " xyz="0 0 0"/>
      <geometry>
        <mesh filename="package://summit_xl_description/meshes/pan_tilt/rx-28.dae"/>
      </geometry>
    </collision>
  </link>
  <joint name="joint_ptu2_s2" type="fixed">
    <parent link="ptu2_link_1"/>
    <child link="ptu2_link_s2"/>
    <origin rpy="0 -1.5708 1.5708" xyz="0 0 0.042"/>
  </joint>
  <link name="ptu2_link_2">
    <inertial>
      <mass value="0.050"/>
      <origin xyz="0 0 0"/>
      <inertia ixx="0.0001" ixy="0.0" ixz="0.0" iyx="0.0" iyy="0.0001" iyz="0.0" izz="0.0001"/>
    </inertial>
    <visual>
      <origin rpy="0 0 0" xyz="0 0 0"/>
      <geometry>
        <mesh filename="package://summit_xl_description/meshes/pan_tilt/fr07-h101.dae"/>
      </geometry>
      <material name="aluminium">
        <color rgba="0.678431373 0.698039216 0.741176471 1"/>
      </material>
    </visual>
    <collision>
      <origin rpy="0 0 0 " xyz="0 0 0"/>
      <geometry>
        <mesh filename="package://summit_xl_description/meshes/pan_tilt/fr07-h101.dae"/>
      </geometry>
    </collision>
  </link>
  <joint name="ptu2_joint_2" type="revolute">
    <origin rpy="0.0 0.0 0.0" xyz="0.0 0 0.042"/>
    <parent link="ptu2_link_1"/>
    <child link="ptu2_link_2"/>
    <axis xyz="0 -1 0"/>
    <limit effort="2.0" lower="-1.6" upper="1.6" velocity="2.9217"/>
    <dynamics damping="0.7" friction="0.5"/>
  </joint>
  <transmission name="j2_trans">
    <type>transmission_interface/SimpleTransmission</type>
    <joint name="ptu2_joint_2">
      <!-- hardwareInterface>EffortJointInterface</hardwareInterface -->
      <hardwareInterface>PositionJointInterface</hardwareInterface>
    </joint>
    <actuator name="j2_motor">
      <hardwareInterface>EffortJointInterface</hardwareInterface>
      <mechanicalReduction>1.0</mechanicalReduction>
      <motorTorqueConstant>50.0</motorTorqueConstant>
    </actuator>
  </transmission>
  <joint name="ptu1_cam_rgb_joint" type="fixed">
    <origin rpy="0 0 0" xyz="0.015 0.020 0.045"/>
    <parent link="ptu1_link_2"/>
    <child link="ptu1_cam_rgb_frame"/>
  </joint>
  <link name="ptu1_cam_rgb_frame">
    <inertial>
      <mass value="0.001"/>
      <origin xyz="0 0 0"/>
      <inertia ixx="0.0001" ixy="0.0" ixz="0.0" iyy="0.0001" iyz="0.0" izz="0.0001"/>
    </inertial>
  </link>
  <joint name="ptu1_cam_rgb_optical_joint" type="fixed">
    <origin rpy="-1.57079632679 0 -1.57079632679" xyz="0 0 0"/>
    <parent link="ptu1_cam_rgb_frame"/>
    <child link="ptu1_cam_rgb_optical_frame"/>
  </joint>
  <link name="ptu1_cam_rgb_optical_frame">
    <inertial>
      <mass value="0.001"/>
      <origin xyz="0 0 0"/>
      <inertia ixx="0.0001" ixy="0.0" ixz="0.0" iyy="0.0001" iyz="0.0" izz="0.0001"/>
    </inertial>
  </link>
  <joint name="ptu1_cam_joint" type="fixed">
    <origin rpy="0 0 0" xyz="0 -0.022 0"/>
    <parent link="ptu1_cam_rgb_frame"/>
    <child link="ptu1_cam_link"/>
  </joint>
  <link name="ptu1_cam_link">
    <visual>
      <origin rpy="-1.57079632679 -3.14159265359 -1.57079632679" xyz="-0.01 0 0"/>
      <geometry>
        <mesh filename="package://robotnik_sensors/meshes/asus_xtion_pro_live.dae" scale="0.001 0.001 0.001"/>
      </geometry>
    </visual>
    <collision>
      <origin rpy="0 0 0" xyz="0.0 0.0 0.0"/>
      <geometry>
        <box size="0.0730 .2760 0.0720"/>
      </geometry>
    </collision>
    <inertial>
      <mass value="0.01"/>
      <origin xyz="0 0 0"/>
      <inertia ixx="0.001" ixy="0.0" ixz="0.0" iyy="0.001" iyz="0.0" izz="0.001"/>
    </inertial>
  </link>
  <joint name="ptu1_cam_depth_joint" type="fixed">
    <origin rpy="0 0 0" xyz="0 0.027 0"/>
    <parent link="ptu1_cam_rgb_frame"/>
    <child link="ptu1_cam_depth_frame"/>
  </joint>
  <link name="ptu1_cam_depth_frame">
    <inertial>
      <mass value="0.01"/>
      <origin xyz="0 0 0"/>
      <inertia ixx="0.001" ixy="0.0" ixz="0.0" iyy="0.001" iyz="0.0" izz="0.001"/>
    </inertial>
  </link>
  <joint name="ptu1_cam_depth_optical_joint" type="fixed">
    <origin rpy="-1.57079632679 0 -1.57079632679" xyz="0 0 0"/>
    <parent link="ptu1_cam_depth_frame"/>
    <child link="ptu1_cam_depth_optical_frame"/>
  </joint>
  <link name="ptu1_cam_depth_optical_frame">
    <inertial>
      <mass value="0.001"/>
      <origin xyz="0 0 0"/>
      <inertia ixx="0.0001" ixy="0.0" ixz="0.0" iyy="0.0001" iyz="0.0" izz="0.0001"/>
    </inertial>
  </link>
  <!-- RGBD sensor for simulation, same as Kinect -->
  <gazebo reference="ptu1_cam_depth_frame">
    <sensor name="cam" type="depth">
      <always_on>true</always_on>
      <update_rate>20.0</update_rate>
      <camera>
        <horizontal_fov>1.0471975512</horizontal_fov>
        <image>
          <format>R8G8B8</format>
          <width>640</width>
          <height>480</height>
        </image>
        <clip>
          <near>0.05</near>
          <far>3.5</far>
        </clip>
      </camera>
      <plugin filename="libgazebo_ros_openni_kinect.so" name="xtion_pro_cam_controller">
        <cameraName>ptu1</cameraName>
        <alwaysOn>true</alwaysOn>
        <updateRate>15</updateRate>
        <imageTopicName>rgb/image_raw</imageTopicName>
        <depthImageTopicName>depth/image_raw</depthImageTopicName>
        <pointCloudTopicName>depth/points</pointCloudTopicName>
        <cameraInfoTopicName>rgb/camera_info</cameraInfoTopicName>
        <depthImageCameraInfoTopicName>depth/camera_info</depthImageCameraInfoTopicName>
        <frameName>ptu1_cam_depth_optical_frame</frameName>
        <baseline>0.1</baseline>
        <distortion_k1>0.0</distortion_k1>
        <distortion_k2>0.0</distortion_k2>
        <distortion_k3>0.0</distortion_k3>
        <distortion_t1>0.0</distortion_t1>
        <distortion_t2>0.0</distortion_t2>
        <pointCloudCutoff>0.4</pointCloudCutoff>
      </plugin>
    </sensor>
  </gazebo>
  <joint name="ptu2_cam_rgb_joint" type="fixed">
    <origin rpy="0 0 0" xyz="0.015 0.020 0.045"/>
    <parent link="ptu2_link_2"/>
    <child link="ptu2_cam_rgb_frame"/>
  </joint>
  <link name="ptu2_cam_rgb_frame">
    <inertial>
      <mass value="0.001"/>
      <origin xyz="0 0 0"/>
      <inertia ixx="0.0001" ixy="0.0" ixz="0.0" iyy="0.0001" iyz="0.0" izz="0.0001"/>
    </inertial>
  </link>
  <joint name="ptu2_cam_rgb_optical_joint" type="fixed">
    <origin rpy="-1.57079632679 0 -1.57079632679" xyz="0 0 0"/>
    <parent link="ptu2_cam_rgb_frame"/>
    <child link="ptu2_cam_rgb_optical_frame"/>
  </joint>
  <link name="ptu2_cam_rgb_optical_frame">
    <inertial>
      <mass value="0.001"/>
      <origin xyz="0 0 0"/>
      <inertia ixx="0.0001" ixy="0.0" ixz="0.0" iyy="0.0001" iyz="0.0" izz="0.0001"/>
    </inertial>
  </link>
  <joint name="ptu2_cam_joint" type="fixed">
    <origin rpy="0 0 0" xyz="0 -0.022 0"/>
    <parent link="ptu2_cam_rgb_frame"/>
    <child link="ptu2_cam_link"/>
  </joint>
  <link name="ptu2_cam_link">
    <visual>
      <origin rpy="-1.57079632679 -3.14159265359 -1.57079632679" xyz="-0.01 0 0"/>
      <geometry>
        <mesh filename="package://robotnik_sensors/meshes/asus_xtion_pro_live.dae" scale="0.001 0.001 0.001"/>
      </geometry>
    </visual>
    <collision>
      <origin rpy="0 0 0" xyz="0.0 0.0 0.0"/>
      <geometry>
        <box size="0.0730 .2760 0.0720"/>
      </geometry>
    </collision>
    <inertial>
      <mass value="0.01"/>
      <origin xyz="0 0 0"/>
      <inertia ixx="0.001" ixy="0.0" ixz="0.0" iyy="0.001" iyz="0.0" izz="0.001"/>
    </inertial>
  </link>
  <joint name="ptu2_cam_depth_joint" type="fixed">
    <origin rpy="0 0 0" xyz="0 0.027 0"/>
    <parent link="ptu2_cam_rgb_frame"/>
    <child link="ptu2_cam_depth_frame"/>
  </joint>
  <link name="ptu2_cam_depth_frame">
    <inertial>
      <mass value="0.01"/>
      <origin xyz="0 0 0"/>
      <inertia ixx="0.001" ixy="0.0" ixz="0.0" iyy="0.001" iyz="0.0" izz="0.001"/>
    </inertial>
  </link>
  <joint name="ptu2_cam_depth_optical_joint" type="fixed">
    <origin rpy="-1.57079632679 0 -1.57079632679" xyz="0 0 0"/>
    <parent link="ptu2_cam_depth_frame"/>
    <child link="ptu2_cam_depth_optical_frame"/>
  </joint>
  <link name="ptu2_cam_depth_optical_frame">
    <inertial>
      <mass value="0.001"/>
      <origin xyz="0 0 0"/>
      <inertia ixx="0.0001" ixy="0.0" ixz="0.0" iyy="0.0001" iyz="0.0" izz="0.0001"/>
    </inertial>
  </link>
  <!-- RGBD sensor for simulation, same as Kinect -->
  <gazebo reference="ptu2_cam_depth_frame">
    <sensor name="cam" type="depth">
      <always_on>true</always_on>
      <update_rate>20.0</update_rate>
      <camera>
        <horizontal_fov>1.0471975512</horizontal_fov>
        <image>
          <format>R8G8B8</format>
          <width>640</width>
          <height>480</height>
        </image>
        <clip>
          <near>0.05</near>
          <far>3.5</far>
        </clip>
      </camera>
      <plugin filename="libgazebo_ros_openni_kinect.so" name="xtion_pro_cam_controller">
        <cameraName>ptu2</cameraName>
        <alwaysOn>true</alwaysOn>
        <updateRate>15</updateRate>
        <imageTopicName>rgb/image_raw</imageTopicName>
        <depthImageTopicName>depth/image_raw</depthImageTopicName>
        <pointCloudTopicName>depth/points</pointCloudTopicName>
        <cameraInfoTopicName>rgb/camera_info</cameraInfoTopicName>
        <depthImageCameraInfoTopicName>depth/camera_info</depthImageCameraInfoTopicName>
        <frameName>ptu2_cam_depth_optical_frame</frameName>
        <baseline>0.1</baseline>
        <distortion_k1>0.0</distortion_k1>
        <distortion_k2>0.0</distortion_k2>
        <distortion_k3>0.0</distortion_k3>
        <distortion_t1>0.0</distortion_t1>
        <distortion_t2>0.0</distortion_t2>
        <pointCloudCutoff>0.4</pointCloudCutoff>
      </plugin>
    </sensor>
  </gazebo>
  <!-- xacro:sensor_gps name="gps" parent="base_link">
		<origin xyz="-0.22 0 0.275" rpy="0 0 0"/>
	</xacro:sensor_gps -->
  <!--
	<xacro:sensor_kinect name="kinect" parent="base_link">
		<origin xyz="0.325 0.0 0.16" rpy="0 0 0"/> 
	</xacro:sensor_kinect>  
-->
  <!--
	<xacro:sensor_fotonic name="fotonic" parent="base_link">
		<origin xyz="0.3 0.0 0.24" rpy="0 0 0"/> 
	</xacro:sensor_fotonic>  
-->
</robot>

